Workbook

Sheet Central Dashboard
A1: FY25-26 | B1: B2C Revenue Tracker
A2: FY26-27
A3: Sno. | B3: Venues | C3: April | D3: May | E3: June | F3: July | G3: August | H3: Sept | I3: Oct | J3: Nov | K3: Dec
A4: 1 | B4: RallyGully I Tirang Sports Arena | Dwarka | C4: ='RallyGully I Sector 10 Dwarka'!B26 -> 256879 | D4: ='RallyGully I Sector 10 Dwarka'!C26 -> 428482 | E4: ='RallyGully I Sector 10 Dwarka'!D26 -> 245541 | F4: ='RallyGully I Sector 10 Dwarka'!E26 -> 260770 | G4: ='RallyGully I Sector 10 Dwarka'!F26 -> 264373 | H4: ='RallyGully I Sector 10 Dwarka'!G26 -> 321329
A5: 2 | B5: RallyGully I The Blue Court | Sec 83 | C5: ='RallyGully | KLJ 83'!B26 -> 183913 | D5: ='RallyGully | KLJ 83'!E26 -> 247268 | E5: ='RallyGully | KLJ 83'!H26 -> 199285 | F5: ='RallyGully | KLJ 83'!K26 -> 245199 | G5: ='RallyGully | KLJ 83'!N26 -> 209847 | H5: ='RallyGully | KLJ 83'!Q26 -> 187469
B6: Pickleball | C6: ='RallyGully | KLJ 83'!C26 -> 97738 | D6: ='RallyGully | KLJ 83'!F26 -> 137540 | E6: ='RallyGully | KLJ 83'!I26 -> 107239 | F6: ='RallyGully | KLJ 83'!L26 -> 133437 | G6: ='RallyGully | KLJ 83'!O26 -> 106073 | H6: ='RallyGully | KLJ 83'!R26 -> 102755
B7: Turf | C7: ='RallyGully | KLJ 83'!D26 -> 85218 | D7: ='RallyGully | KLJ 83'!G26 -> 109728 | E7: ='RallyGully | KLJ 83'!J26 -> 68046 | F7: ='RallyGully | KLJ 83'!M26 -> 67309 | G7: ='RallyGully | KLJ 83'!P26 -> 94374 | H7: ='RallyGully | KLJ 83'!S26 -> 84714
A8: 3 | B8: RallyGully I East of Kailash | C8: ='RallyGully | EOK'!B26 -> 301420 | D8: ='RallyGully | EOK'!C26 -> 350844 | E8: ='RallyGully | EOK'!D26 -> 389200 | F8: ='RallyGully | EOK'!E26 -> 193062 | G8: ='RallyGully | EOK'!F26 -> 208166 | H8: ='RallyGully | EOK'!G26 -> 217526
A9: 4 | B9: RallyGully I Drive or Kick | Dwarka | C9: ='RallyGully | DOK Dwarka'!B26 -> 85355 | D9: ='RallyGully | DOK Dwarka'!C26 -> 132322 | E9: ='RallyGully | DOK Dwarka'!D26 -> 110817 | F9: ='RallyGully | DOK Dwarka'!E26 -> 67760 | G9: ='RallyGully | DOK Dwarka'!F26 -> 64231 | H9: ='RallyGully | DOK Dwarka'!G26 -> 52735
A10: 5 | B10: RallyGully | 1011 | DPSG Palam Vihar | C10: ='RallyGully | DPSG'!B26 -> 95190 | D10: ='RallyGully | DPSG'!C26 -> 157033 | E10: ='RallyGully | DPSG'!D26 -> 117732 | F10: ='RallyGully | DPSG'!E26 -> 68206 | G10: ='RallyGully | DPSG'!F26 -> 62615 | H10: ='RallyGully | DPSG'!G26 -> 49069
A11: 6 | B11: RallyGully I Panchsheel Enclave | C11: ='RallyGully | Panchsheel'!B26 -> 126187 | D11: ='RallyGully | Panchsheel'!C26 -> 119195 | E11: ='RallyGully | Panchsheel'!D26 -> 77734 | F11: ='RallyGully | Panchsheel'!E26 -> 65801 | G11: ='RallyGully | Panchsheel'!F26 -> 38408 | H11: ='RallyGully | Panchsheel'!G26 -> 56821
A12: 7 | B12: RallyGully | Law College Road | C12: ='RallyGully | LCR'!B26 -> 342681 | D12: ='RallyGully | LCR'!C26 -> 423322 | E12: ='RallyGully | LCR'!D26 -> 303555 | F12: ='RallyGully | LCR'!E26 -> 204478 | G12: ='RallyGully | LCR'!F26 -> 215489 | H12: ='RallyGully | LCR'!G26 -> 243227
A13: 8 | B13: RallyGully | Powerplay Park | C13: ='RallyGully | Powerplay'!B26 -> 226511 | D13: ='RallyGully | Powerplay'!F26 -> 252927 | E13: ='RallyGully | Powerplay'!J26 -> 217661 | F13: ='RallyGully | Powerplay'!N26 -> 161820 | G13: ='RallyGully | Powerplay'!R26 -> 141427 | H13: ='RallyGully | Powerplay'!V26 -> 160569
B14: Pickleball | C14: ='RallyGully | Powerplay'!C26 -> 53909 | D14: ='RallyGully | Powerplay'!G26 -> 87588 | E14: ='RallyGully | Powerplay'!K26 -> 45308 | F14: ='RallyGully | Powerplay'!O26 -> 15815 | G14: ='RallyGully | Powerplay'!S26 -> 7477 | H14: ='RallyGully | Powerplay'!W26 -> 12270
B15: Padel | C15: ='RallyGully | Powerplay'!E26 -> 118000 | D15: ='RallyGully | Powerplay'!I26 | E15: ='RallyGully | Powerplay'!M26 -> 118000 | F15: ='RallyGully | Powerplay'!Q26 -> 118000 | G15: ='RallyGully | Powerplay'!U26 -> 118000 | H15: ='RallyGully | Powerplay'!Y26 -> 118000
B16: Turf | C16: ='RallyGully | Powerplay'!D26 -> 51089 | D16: ='RallyGully | Powerplay'!H26 | E16: ='RallyGully | Powerplay'!L26 -> 56803 | F16: ='RallyGully | Powerplay'!P26 -> 28005 | G16: ='RallyGully | Powerplay'!T26 -> 15850 | H16: ='RallyGully | Powerplay'!X26 -> 30299
A17: 9 | B17: Commons | RallyGully x Delhi Padel Collective | C17: ='RallyGully | Commons'!B26 -> 335848 | D17: ='RallyGully | Commons'!F26 -> 563241 | E17: ='RallyGully | Commons'!J26 -> 710647 | F17: ='RallyGully | Commons'!N26 -> 614603 | G17: ='RallyGully | Commons'!R26 -> 619059 | H17: ='RallyGully | Commons'!V26 -> 635389
B18: Pickleball | C18: ='RallyGully | Commons'!C26 -> 35407 | D18: ='RallyGully | Commons'!G26 -> 145200 | E18: ='RallyGully | Commons'!K26 -> 168475 | F18: ='RallyGully | Commons'!O26 -> 75602 | G18: ='RallyGully | Commons'!S26 -> 84704 | H18: ='RallyGully | Commons'!W26 -> 93919
B19: Padel | C19: ='RallyGully | Commons'!E26 -> 88513 | D19: ='RallyGully | Commons'!I26 -> 71832 | E19: ='RallyGully | Commons'!M26 -> 63501 | F19: ='RallyGully | Commons'!Q26 -> 81339 | G19: ='RallyGully | Commons'!U26 -> 87157 | H19: ='RallyGully | Commons'!Y26 -> 99482
B20: Turf | C20: ='RallyGully | Commons'!D26 -> 178734 | D20: ='RallyGully | Commons'!H26 -> 346211 | E20: ='RallyGully | Commons'!L26 -> 474406 | F20: ='RallyGully | Commons'!P26 -> 431310 | G20: ='RallyGully | Commons'!T26 -> 363688 | H20: ='RallyGully | Commons'!X26 -> 426515
A21: 10 | B21: RallyGully I Drive or Kick | Sec 83 | C21: 0 | D21: 0 | E21: ='DOK | 83'!D26 -> 49974 | F21: ='DOK | 83'!E26 -> 91850 | G21: ='DOK | 83'!H26 -> 114611 | H21: ='DOK | 83'!I26 -> 47651
B22: Padel | C22: 0 | D22: 0 | E22: 0 | F22: 0 | G22: 0 | H22: 0
B23: Turf | C23: 0 | D23: 0 | E23: ='DOK | 83'!F21 -> 0 | F23: =F21 -> 91850 | G23: =G21 -> 114611 | H23: =H21 -> 47651
A24: 11 | B24: RallyGully I Chandigarh Sec 37 | C24: 0 | D24: 0 | E24: 0 | F24: 0 | G24: 0 | H24: ='RallyGully | Chd'!B26 -> 20398
A25: 12 | B25: RallyGully I Golf Course EXT. | C25: 0 | D25: 0 | E25: 0 | F25: 0 | G25: 0 | H25: 0
B26: RallyGully I Gandhipath | C26: ='RallyGully | Gandipath Jaipur'!B26 -> 46515 | D26: ='RallyGully | Gandipath Jaipur'!C26 -> 31460 | E26: ='RallyGully | Gandipath Jaipur'!D26 -> 36755 | F26: ='RallyGully | Gandipath Jaipur'!E26 -> 49021 | G26: ='RallyGully | Gandipath Jaipur'!F26 -> 40697
B27: RallyGully I Ambala | C27: 0 | D27: 0 | E27: =Ambala!B26 -> 36986 | F27: =Ambala!C26 -> 73258 | G27: =Ambala!D26 -> 23536
B28: RallyGully I Zirakpur | C28: 0 | D28: 0 | E28: =Zirakpur!B26 -> 5734 | F28: =Zirakpur!C26 -> 5142 | G28: =Zirakpur!D26 -> 2242
B29: Total Gross Revenue | C29: =sum(C4,C5,C8,C9,C10,C11,C12,C26,C13,C17) -> 2000499 | D29: =sum(D4,D5,D8,D9,D10,D11,D12,D26,D13,D17) -> 2706094 | E29: =sum(E4,E5,E8,E9,E10,E11,E12,E26,E13,E17,E21,E27,E28) -> 2501621 | F29: =sum(F4,F5,F8,F9,F10,F11,F12,F26,F13,F17,F21,F27,F28) -> 2100970 | G29: =sum(G4,G5,G8,G9,G10,G11,G12,G26,G13,G17,G21,G27,G28) -> 2004701 | H29: =H4+H5+H8+H9+H10+H11+H12+H13+H17+H21+H24 -> 1992183 | I29: =SUM(I4:I17) -> 0 | J29: =SUM(J4:J17) -> 0 | K29: =SUM(K4:K17) -> 0
B30: Net Revenue Post GST | C30: ='RallyGully I Sector 10 Dwarka'!B28+'RallyGully | KLJ 83'!B28+'RallyGully | EOK'!B28+'RallyGully | DOK Dwarka'!B28+'RallyGully | DPSG'!B28+'RallyGully | Panchsheel'!B28+'RallyGully | LCR'!B28+'RallyGully | Gandipath Jaipur'!B28+'RallyGully | Powerplay'!B28+'RallyGully | Commons'!B28 -> 1695338.1 | D30: ='RallyGully I Sector 10 Dwarka'!C28+'RallyGully | KLJ 83'!E28+'RallyGully | EOK'!C28+'RallyGully | DOK Dwarka'!C28+'RallyGully | DPSG'!C28+'RallyGully | Panchsheel'!C28+'RallyGully | LCR'!C28+'RallyGully | Gandipath Jaipur'!C28+'RallyGully | Powerplay'!F28+'RallyGully | Commons'!F28 -> 2293300 | E30: ='RallyGully I Sector 10 Dwarka'!D28+'RallyGully | KLJ 83'!H28+'RallyGully | EOK'!D28+'RallyGully | DOK Dwarka'!D28+'RallyGully | DPSG'!D28+'RallyGully | Panchsheel'!D28+'RallyGully | LCR'!D28+'RallyGully | Gandipath Jaipur'!D28+'RallyGully | Powerplay'!J28+'RallyGully | Commons'!J28+'DOK | 83'!F28+Ambala!B28+Zirakpur!B28 -> 2120170.3 | F30: ='RallyGully I Sector 10 Dwarka'!E28+'RallyGully | KLJ 83'!K28+'RallyGully | EOK'!E28+'RallyGully | DOK Dwarka'!E28+'RallyGully | DPSG'!E28+'RallyGully | Panchsheel'!E28+'RallyGully | LCR'!E28+'RallyGully | Gandipath Jaipur'!E28+'RallyGully | Powerplay'!N28+'RallyGully | Commons'!N28+'DOK | 83'!G28+Ambala!C28+Zirakpur!C28 -> 1780483.1 | G30: ='RallyGully I Sector 10 Dwarka'!F28+'RallyGully | KLJ 83'!N28+'RallyGully | EOK'!F28+'RallyGully | DOK Dwarka'!F28+'RallyGully | DPSG'!F28+'RallyGully | Panchsheel'!F28+'RallyGully | LCR'!F28+'RallyGully | Gandipath Jaipur'!F28+'RallyGully | Powerplay'!R28+'RallyGully | Commons'!R28+'DOK | 83'!H28+Ambala!D28+Zirakpur!D28 -> 1698899.2 | H30: ='RallyGully I Sector 10 Dwarka'!G28+'RallyGully | KLJ 83'!Q28+'RallyGully | EOK'!G28+'RallyGully | DOK Dwarka'!G28+'RallyGully | DPSG'!G28+'RallyGully | Panchsheel'!G28+'RallyGully | LCR'!G28+'RallyGully | Powerplay'!V28+'RallyGully | Commons'!V28+'DOK | 83'!I28+'RallyGully | Chd'!B28 -> 1688290.7
B33: Verticle Vise | C33: April | D33: May | E33: June | F33: July | G33: August | H33: Sept | I33: Oct | J33: Nov | K33: Dec
B34: Pay & Play | C34: =C35+C41 -> 1404213 | D34: =D35+D41 -> 1954301 | E34: =E35+E41 -> 1646292 | F34: =F35+F41 -> 1445541 | G34: =G35+G41 -> 1064083 | H34: =H35+H41 -> 1160572
B35: Online | C35: =sum(C36:C40) -> 801801 | D35: =sum(D36:D40) -> 1321278 | E35: =sum(E36:E40) -> 961428 | F35: =sum(F36:F40) -> 777870 | G35: =sum(G36:G40) -> 675155 | H35: =sum(H36:H40) -> 756313
B36: District | C36: =sum('RallyGully I Sector 10 Dwarka'!B5,'RallyGully | KLJ 83'!B5,'RallyGully | EOK'!B5,'RallyGully | DOK Dwarka'!B5,'RallyGully | DPSG'!B5,'RallyGully | LCR'!B5,'RallyGully | Gandipath Jaipur'!B5,'RallyGully | Panchsheel'!B5,'RallyGully | Powerplay'!B5,'RallyGully | Commons'!B5) -> 258239 | D36: =sum('RallyGully I Sector 10 Dwarka'!C5,'RallyGully | KLJ 83'!E5,'RallyGully | EOK'!C5,'RallyGully | DOK Dwarka'!C5,'RallyGully | DPSG'!C5,'RallyGully | LCR'!C5,'RallyGully | Gandipath Jaipur'!C5,'RallyGully | Panchsheel'!C5,'RallyGully | Powerplay'!F5,'RallyGully | Commons'!F5) -> 996125 | E36: =sum('RallyGully I Sector 10 Dwarka'!D5,'RallyGully | KLJ 83'!H5,'RallyGully | EOK'!D5,'RallyGully | DOK Dwarka'!D5,'RallyGully | DPSG'!D5,'RallyGully | LCR'!D5,'RallyGully | Gandipath Jaipur'!D5,'RallyGully | Panchsheel'!D5,'RallyGully | Powerplay'!J5,'RallyGully | Commons'!J5+'DOK | 83'!D5+Ambala!B5+Zirakpur!B5) -> 814906 | F36: =sum('RallyGully I Sector 10 Dwarka'!E5,'RallyGully | KLJ 83'!K5,'RallyGully | EOK'!E5,'RallyGully | DOK Dwarka'!E5,'RallyGully | DPSG'!E5,'RallyGully | LCR'!E5,'RallyGully | Gandipath Jaipur'!E5,'RallyGully | Panchsheel'!E5,'RallyGully | Powerplay'!N5,'RallyGully | Commons'!N5+'DOK | 83'!E5+Ambala!C5+Zirakpur!C5) -> 708643 | G36: ='RallyGully I Sector 10 Dwarka'!F5+'RallyGully | KLJ 83'!N5+'RallyGully | EOK'!F5+'RallyGully | DOK Dwarka'!F5+'RallyGully | DPSG'!F5+'RallyGully | Panchsheel'!F5+'RallyGully | LCR'!F5+'RallyGully | Gandipath Jaipur'!F5+'RallyGully | Powerplay'!R5+'RallyGully | Commons'!R5+'DOK | 83'!H5+Ambala!D5+Zirakpur!D5 -> 620378 | H36: ='RallyGully I Sector 10 Dwarka'!G5+'RallyGully | KLJ 83'!Q5+'RallyGully | EOK'!G5+'RallyGully | DOK Dwarka'!G5+'RallyGully | DPSG'!G5+'RallyGully | Panchsheel'!G5+'RallyGully | LCR'!G5+'RallyGully | Powerplay'!V5+'RallyGully | Commons'!V5+'DOK | 83'!I5+'RallyGully | Chd'!B5 -> 688435
B37: Hudle | C37: =sum('RallyGully I Sector 10 Dwarka'!B6,'RallyGully | KLJ 83'!B6,'RallyGully | EOK'!B6,'RallyGully | DOK Dwarka'!B6,'RallyGully | DPSG'!B6,'RallyGully | LCR'!B6,'RallyGully | Gandipath Jaipur'!B6,'RallyGully | Panchsheel'!B6,'RallyGully | Powerplay'!B6,'RallyGully | Commons'!B6) -> 351892 | D37: =sum('RallyGully I Sector 10 Dwarka'!C6,'RallyGully | KLJ 83'!E6,'RallyGully | EOK'!C6,'RallyGully | DOK Dwarka'!C6,'RallyGully | DPSG'!C6,'RallyGully | LCR'!C6,'RallyGully | Gandipath Jaipur'!C6,'RallyGully | Panchsheel'!C6,'RallyGully | Powerplay'!F6,'RallyGully | Commons'!F6) -> 166290 | E37: =sum('RallyGully I Sector 10 Dwarka'!D6,'RallyGully | KLJ 83'!H6,'RallyGully | EOK'!D6,'RallyGully | DOK Dwarka'!D6,'RallyGully | DPSG'!D6,'RallyGully | LCR'!D6,'RallyGully | Gandipath Jaipur'!D6,'RallyGully | Panchsheel'!D6,'RallyGully | Powerplay'!J6,'RallyGully | Commons'!J6+'DOK | 83'!D6+Ambala!B6+Zirakpur!B6) -> 19272 | F37: =sum('RallyGully I Sector 10 Dwarka'!E6,'RallyGully | KLJ 83'!K6,'RallyGully | EOK'!E6,'RallyGully | DOK Dwarka'!E6,'RallyGully | DPSG'!E6,'RallyGully | LCR'!E6,'RallyGully | Gandipath Jaipur'!E6,'RallyGully | Panchsheel'!E6,'RallyGully | Powerplay'!N6,'RallyGully | Commons'!N6+'DOK | 83'!E6+Ambala!C6+Zirakpur!C6) -> 26736 | G37: ='RallyGully I Sector 10 Dwarka'!F6+'RallyGully | KLJ 83'!N6+'RallyGully | EOK'!F6+'RallyGully | DOK Dwarka'!F6+'RallyGully | DPSG'!F6+'RallyGully | Panchsheel'!F6+'RallyGully | LCR'!F6+'RallyGully | Gandipath Jaipur'!F6+'RallyGully | Powerplay'!R6+'RallyGully | Commons'!R6+'DOK | 83'!H6+Ambala!D6+Zirakpur!D6 -> 15641 | H37: ='RallyGully I Sector 10 Dwarka'!G6+'RallyGully | KLJ 83'!Q6+'RallyGully | EOK'!G6+'RallyGully | DOK Dwarka'!G6+'RallyGully | DPSG'!G6+'RallyGully | Panchsheel'!G6+'RallyGully | LCR'!G6+'RallyGully | Powerplay'!V6+'RallyGully | Commons'!V6+'DOK | 83'!I6+'RallyGully | Chd'!B6 -> 10070
B38: Playo | C38: =sum('RallyGully I Sector 10 Dwarka'!B7,'RallyGully | KLJ 83'!B7,'RallyGully | EOK'!B7,'RallyGully | DOK Dwarka'!B7,'RallyGully | DPSG'!B7,'RallyGully | LCR'!B7,'RallyGully | Gandipath Jaipur'!B7,'RallyGully | Panchsheel'!B7,'RallyGully | Powerplay'!B7,'RallyGully | Commons'!B7) -> 107876 | D38: =sum('RallyGully I Sector 10 Dwarka'!C7,'RallyGully | KLJ 83'!E7,'RallyGully | EOK'!C7,'RallyGully | DOK Dwarka'!C7,'RallyGully | DPSG'!C7,'RallyGully | LCR'!C7,'RallyGully | Gandipath Jaipur'!C7,'RallyGully | Panchsheel'!C7,'RallyGully | Powerplay'!F7,'RallyGully | Commons'!F7) -> 103594 | E38: =sum('RallyGully I Sector 10 Dwarka'!D7,'RallyGully | KLJ 83'!H7,'RallyGully | EOK'!D7,'RallyGully | DOK Dwarka'!D7,'RallyGully | DPSG'!D7,'RallyGully | LCR'!D7,'RallyGully | Gandipath Jaipur'!D7,'RallyGully | Panchsheel'!D7,'RallyGully | Powerplay'!J7,'RallyGully | Commons'!J7+'DOK | 83'!D7+Ambala!B7+Zirakpur!B7) -> 84875 | F38: =sum('RallyGully I Sector 10 Dwarka'!E7,'RallyGully | KLJ 83'!K7,'RallyGully | EOK'!E7,'RallyGully | DOK Dwarka'!E7,'RallyGully | DPSG'!E7,'RallyGully | LCR'!E7,'RallyGully | Gandipath Jaipur'!E7,'RallyGully | Panchsheel'!E7,'RallyGully | Powerplay'!N7,'RallyGully | Commons'!N7+'DOK | 83'!E7+Ambala!C7+Zirakpur!C7) -> 27753 | G38: ='RallyGully I Sector 10 Dwarka'!F7+'RallyGully | KLJ 83'!N7+'RallyGully | EOK'!F7+'RallyGully | DOK Dwarka'!F7+'RallyGully | DPSG'!F7+'RallyGully | Panchsheel'!F7+'RallyGully | LCR'!F7+'RallyGully | Gandipath Jaipur'!F7+'RallyGully | Powerplay'!R7+'RallyGully | Commons'!R7+'DOK | 83'!H7+Ambala!D7+Zirakpur!D7 -> 26005 | H38: ='RallyGully I Sector 10 Dwarka'!G7+'RallyGully | KLJ 83'!Q7+'RallyGully | EOK'!G7+'RallyGully | DOK Dwarka'!G7+'RallyGully | DPSG'!G7+'RallyGully | Panchsheel'!G7+'RallyGully | LCR'!G7+'RallyGully | Powerplay'!V7+'RallyGully | Commons'!V7+'DOK | 83'!I7+'RallyGully | Chd'!B7 -> 44730
B39: Khelomore | C39: =SUM('RallyGully I Sector 10 Dwarka'!B8,'RallyGully | KLJ 83'!B8,'RallyGully | EOK'!B8,'RallyGully | DOK Dwarka'!B8,'RallyGully | DPSG'!B8,'RallyGully | LCR'!B8,'RallyGully | Gandipath Jaipur'!B8,'RallyGully | Panchsheel'!B8,'RallyGully | Powerplay'!B8,'RallyGully | Commons'!B8) -> 46888 | D39: =SUM('RallyGully I Sector 10 Dwarka'!C8,'RallyGully | KLJ 83'!E8,'RallyGully | EOK'!C8,'RallyGully | DOK Dwarka'!C8,'RallyGully | DPSG'!C8,'RallyGully | LCR'!C8,'RallyGully | Gandipath Jaipur'!C8,'RallyGully | Panchsheel'!C8,'RallyGully | Powerplay'!F8,'RallyGully | Commons'!F8) -> 41275 | E39: =sum('RallyGully I Sector 10 Dwarka'!D8,'RallyGully | KLJ 83'!H8,'RallyGully | EOK'!D8,'RallyGully | DOK Dwarka'!D8,'RallyGully | DPSG'!D8,'RallyGully | LCR'!D8,'RallyGully | Gandipath Jaipur'!D8,'RallyGully | Panchsheel'!D8,'RallyGully | Powerplay'!J8,'RallyGully | Commons'!J8+'DOK | 83'!D8+Ambala!B8+Zirakpur!B8) -> 35177 | F39: =sum('RallyGully I Sector 10 Dwarka'!E8,'RallyGully | KLJ 83'!K8,'RallyGully | EOK'!E8,'RallyGully | DOK Dwarka'!E8,'RallyGully | DPSG'!E8,'RallyGully | LCR'!E8,'RallyGully | Gandipath Jaipur'!E8,'RallyGully | Panchsheel'!E8,'RallyGully | Powerplay'!N8,'RallyGully | Commons'!N8+'DOK | 83'!E8+Ambala!C8+Zirakpur!C8) -> 14154 | G39: ='RallyGully I Sector 10 Dwarka'!F8+'RallyGully | KLJ 83'!N8+'RallyGully | EOK'!F8+'RallyGully | DOK Dwarka'!F8+'RallyGully | DPSG'!F8+'RallyGully | Panchsheel'!F8+'RallyGully | LCR'!F8+'RallyGully | Gandipath Jaipur'!F8+'RallyGully | Powerplay'!R8+'RallyGully | Commons'!R8+'DOK | 83'!H8+Ambala!D8+Zirakpur!D8 -> 11979 | H39: ='RallyGully I Sector 10 Dwarka'!G8+'RallyGully | KLJ 83'!Q8+'RallyGully | EOK'!G8+'RallyGully | DOK Dwarka'!G8+'RallyGully | DPSG'!G8+'RallyGully | Panchsheel'!G8+'RallyGully | LCR'!G8+'RallyGully | Powerplay'!V8+'RallyGully | Commons'!V8+'DOK | 83'!I8+'RallyGully | Chd'!B8 -> 13078
B40: Zplys | C40: ='RallyGully | Gandipath Jaipur'!B9 -> 36906 | D40: ='RallyGully | Gandipath Jaipur'!C9 -> 13994 | E40: =sum('RallyGully I Sector 10 Dwarka'!D9,'RallyGully | KLJ 83'!H9,'RallyGully | EOK'!D9,'RallyGully | DOK Dwarka'!D9,'RallyGully | DPSG'!D9,'RallyGully | LCR'!D9,'RallyGully | Gandipath Jaipur'!D9,'RallyGully | Panchsheel'!D9,'RallyGully | Powerplay'!J9,'RallyGully | Commons'!J9+'DOK | 83'!D9+Ambala!B9+Zirakpur!B9) -> 7198 | F40: =sum('RallyGully I Sector 10 Dwarka'!E9,'RallyGully | KLJ 83'!K9,'RallyGully | EOK'!E9,'RallyGully | DOK Dwarka'!E9,'RallyGully | DPSG'!E9,'RallyGully | LCR'!E9,'RallyGully | Gandipath Jaipur'!E9,'RallyGully | Panchsheel'!E9,'RallyGully | Powerplay'!N9,'RallyGully | Commons'!N9+'DOK | 83'!E9+Ambala!C9+Zirakpur!C9) -> 584 | G40: ='RallyGully I Sector 10 Dwarka'!F9+'RallyGully | KLJ 83'!N9+'RallyGully | EOK'!F9+'RallyGully | DOK Dwarka'!F9+'RallyGully | DPSG'!F9+'RallyGully | Panchsheel'!F9+'RallyGully | LCR'!F9+'RallyGully | Gandipath Jaipur'!F9+'RallyGully | Powerplay'!R9+'RallyGully | Commons'!R9+'DOK | 83'!H9+Ambala!D9+Zirakpur!D9 -> 1152 | H40: ='RallyGully I Sector 10 Dwarka'!G9+'RallyGully | KLJ 83'!O9+'RallyGully | EOK'!G9+'RallyGully | DOK Dwarka'!G9+'RallyGully | DPSG'!G9+'RallyGully | Panchsheel'!G9+'RallyGully | LCR'!G9+'RallyGully | Gandipath Jaipur'!G9+'RallyGully | Powerplay'!S9+'RallyGully | Commons'!V9+'DOK | 83'!I9+'RallyGully | Chd'!C9 -> 0 | Y40: =sum('RallyGully I Sector 10 Dwarka'!X9,'RallyGully | KLJ 83'!AF9,'RallyGully | EOK'!X9,'RallyGully | DOK Dwarka'!X9,'RallyGully | DPSG'!X9,'RallyGully | LCR'!X9,'RallyGully | Gandipath Jaipur'!T9,'RallyGully | Panchsheel'!X9,'RallyGully | Powerplay'!AG9,'RallyGully | Commons'!AH9+'DOK | 83'!AB9+Ambala!L9+Zirakpur!R9) -> 0
B41: Offline | C41: =sum(C42:C43) -> 602412 | D41: =sum(D42:D43) -> 633023 | E41: =sum(E42:E43) -> 684864 | F41: =sum(F42:F43) -> 667671 | G41: =sum(G42:G43) -> 388928 | H41: =sum(H42:H43) -> 404259
B42: Bookings | C42: =sum('RallyGully I Sector 10 Dwarka'!B11,'RallyGully | KLJ 83'!B11,'RallyGully | EOK'!B11,'RallyGully | DOK Dwarka'!B11,'RallyGully | DPSG'!B11,'RallyGully | LCR'!B11,'RallyGully | Gandipath Jaipur'!B11,'RallyGully | Panchsheel'!B11,'RallyGully | Powerplay'!B11,'RallyGully | Commons'!B11) -> 537112 | D42: =sum('RallyGully I Sector 10 Dwarka'!C11,'RallyGully | KLJ 83'!E11,'RallyGully | EOK'!C11,'RallyGully | DOK Dwarka'!C11,'RallyGully | DPSG'!C11,'RallyGully | LCR'!C11,'RallyGully | Gandipath Jaipur'!C11,'RallyGully | Panchsheel'!C11,'RallyGully | Powerplay'!F11,'RallyGully | Commons'!F11) -> 485023 | E42: =sum('RallyGully I Sector 10 Dwarka'!D11,'RallyGully | KLJ 83'!H11,'RallyGully | EOK'!D11,'RallyGully | DOK Dwarka'!D11,'RallyGully | DPSG'!D11,'RallyGully | LCR'!D11,'RallyGully | Gandipath Jaipur'!D11,'RallyGully | Panchsheel'!D11,'RallyGully | Powerplay'!J11,'RallyGully | Commons'!J11+'DOK | 83'!D11+Ambala!B11+Zirakpur!B11) -> 612084 | F42: =sum('RallyGully I Sector 10 Dwarka'!E11,'RallyGully | KLJ 83'!K11,'RallyGully | EOK'!E11,'RallyGully | DOK Dwarka'!E11,'RallyGully | DPSG'!E11,'RallyGully | LCR'!E11,'RallyGully | Gandipath Jaipur'!E11,'RallyGully | Panchsheel'!E11,'RallyGully | Powerplay'!N11,'RallyGully | Commons'!N11+'DOK | 83'!E11+Ambala!C11+Zirakpur!C11) -> 538071 | G42: ='RallyGully I Sector 10 Dwarka'!F11+'RallyGully | KLJ 83'!N11+'RallyGully | EOK'!F11+'RallyGully | DOK Dwarka'!F11+'RallyGully | DPSG'!F11+'RallyGully | Panchsheel'!F11+'RallyGully | LCR'!F11+'RallyGully | Gandipath Jaipur'!F11+'RallyGully | Powerplay'!R11+'RallyGully | Commons'!R11+'DOK | 83'!H11+Ambala!D11+Zirakpur!D11 -> 321328 | H42: ='RallyGully I Sector 10 Dwarka'!G11+'RallyGully | KLJ 83'!Q11+'RallyGully | EOK'!G11+'RallyGully | DOK Dwarka'!G11+'RallyGully | DPSG'!G11+'RallyGully | Panchsheel'!G11+'RallyGully | LCR'!G11+'RallyGully | Powerplay'!V11+'RallyGully | Commons'!V11+'DOK | 83'!I11+'RallyGully | Chd'!B11 -> 275359
...

Sheet RallyGully I Sector 10 Dwarka
B1: Link | C1: Link | D1: Link | E1: Link | F1: Link | G1: Link
A2: Venues | B2: April | C2: May | D2: June | E2: July | F2: August | G2: Sept | H2: Oct | I2: Nov | J2: Dec
A3: Pay & Play | B3: =sum(B4,B10) -> 120359 | C3: =sum(C4,C10) -> 339577 | D3: =sum(D4,D10) -> 186067 | E3: =sum(E4,E10) -> 174333 | F3: =sum(F4,F10) -> 130433 | G3: =sum(G4,G10) -> 180690
A4: Online | B4: =sum(B5:B9) -> 98039 | C4: =sum(C5:C9) -> 267597 | D4: =sum(D5:D9) -> 122537 | E4: =sum(E5:E9) -> 116989 | F4: =sum(F5:F9) -> 100710 | G4: =sum(G5:G9) -> 149821
A5: District | B5: 50900 | C5: 225063 | D5: 122537 | E5: 116989 | F5: 100710 | G5: 149821
A6: Hudle | B6: 39539 | C6: 42134 | D6: 0 | E6: 0 | F6: 0 | G6: 0
A7: Playo | B7: 4400 | C7: 400 | D7: 0 | E7: 0 | F7: 0 | G7: 0
A8: Khelomore | B8: 3200 | C8: 0 | D8: 0 | E8: 0 | F8: 0 | G8: 0
A9: Zplys | B9: 0 | C9: 0 | D9: 0 | E9: 0 | F9: 0 | G9: 0
A10: Offline | B10: =sum(B11:B12) -> 22320 | C10: =sum(C11:C12) -> 71980 | D10: =sum(D11:D12) -> 63530 | E10: =sum(E11:E12) -> 57344 | F10: =sum(F11:F12) -> 29723 | G10: =sum(G11:G12) -> 30869
A11: Bookings | B11: 22320 | C11: 20780 | D11: 63530 | E11: 57344 | F11: 29723 | G11: 30869
A12: Memberships | B12: 0 | C12: 51200 | D12: 0 | E12: 0 | F12: 0 | G12: 0
A13: Community | B13: =sum(B14:B16) -> 95160 | C13: =sum(C14:C16) -> 64700 | D13: =sum(D14:D16) -> 44484 | E13: =sum(E14:E16) -> 69742 | F13: =sum(F14:F16) -> 111860 | G13: =sum(G14:G16) -> 123004
A14: Pickup games | B14: 26200 | C14: 42200 | D14: 38100 | E14: 45000 | F14: 58050 | G14: 61300
A15: Social Events/Tournaments | B15: 68960 | C15: 22500 | D15: 6384 | E15: 24742 | F15: 8500 | G15: 7984
A16: Community Partnerships | B16: 0 | C16: 0 | D16: 0 | E16: 0 | F16: 45310 | G16: 53720
A17: Academy | B17: 0 | C17: 13000 | D17: 6500 | E17: 6500 | F17: 6500 | G17: 6500
A18: B2B | B18: =sum(B19,B20) -> 30000 | C18: =sum(C19,C20) -> 0 | D18: =sum(D19,D20) -> 0 | E18: =sum(E19,E20) -> 0 | F18: =sum(F19,F20) -> 5950 | G18: =sum(G19,G20) -> 0
A19: Corporate events | B19: 0 | C19: 0 | D19: 0 | E19: 0 | F19: 5950 | G19: 0
A20: All B2B partnerships | B20: 30000 | C20: 0 | D20: 0 | E20: 0 | F20: 0 | G20: 0
A21: Commerce | B21: =sum(B22:B24) -> 11360 | C21: =sum(C22:C24) -> 11205 | D21: =sum(D22:D24) -> 8490 | E21: =sum(E22,E24) -> 10195 | F21: =sum(F22,F24) -> 9630 | G21: =sum(G22:G24) -> 11135
A22: Product rental | B22: 9200 | C22: 9000 | D22: 8250 | E22: 9775 | F22: 7175 | G22: 6850
A23: Product sales | B23: 0 | C23: 0 | D23: 0 | E23: 0 | F23: 0 | G23: 0
A24: F&B | B24: 2160 | C24: 2205 | D24: 240 | E24: 420 | F24: 2455 | G24: 4285
A25: Other Income | B25: 0 | C25: 0 | D25: 0 | E25: 0 | F25: 0 | G25: 0
A26: Total Gross Revenue | B26: =B3+B13+B17+B18+B21+B25 -> 256879 | C26: =C3+C13+C17+C18+C21+C25 -> 428482 | D26: =D3+D13+D17+D18+D21+D25 -> 245541 | E26: =E3+E13+E17+E18+E21+E25 -> 260770 | F26: =F3+F13+F17+F18+F21+F25 -> 264373 | G26: =G3+G13+G17+G18+G21+G25 -> 321329
A27: GST | B27: =B26-(B26/1.18) -> 39184.932 | C27: =C26-(C26/1.18) -> 65361.661 | D27: =D26-(D26/1.18) -> 37455.407 | E27: =E26-(E26/1.18) -> 39778.475 | F27: =F26-(F26/1.18) -> 40328.085 | G27: =G26-(G26/1.18) -> 49016.288
A28: Net Revenue Post GST | B28: =B26-B27 -> 217694.07 | C28: =C26-C27 -> 363120.34 | D28: =D26-D27 -> 208085.59 | E28: =E26-E27 -> 220991.53 | F28: =F26-F27 -> 224044.92 | G28: =G26-G27 -> 272312.71
G29: =G26/1.18 -> 272312.71

Sheet RallyGully | KLJ 83
B1: Link | E1: Link | H1: Link | K1: Link | N1: Link | Q1: Link
A2: Venues | B2: April | C2: Pickleball | D2: Turf | E2: May | F2: Pickleball | G2: Turf | H2: June | I2: Pickleball | J2: Turf | K2: July | L2: Pickleball | M2: Turf | N2: August | O2: Pickleball | P2: Turf | Q2: Sept | R2: Pickleball | S2: Turf | T2: Oct | U2: Nov | V2: Dec
A3: Pay & Play | B3: =sum(B4,B10) -> 173128 | C3: =sum(C4,C10) -> 89513 | D3: =sum(D4,D10) -> 82658 | E3: =sum(E4,E10) -> 240943 | F3: =sum(F4,F10) -> 131215 | G3: =sum(G4,G10) -> 109728 | H3: =sum(H4,H10) -> 195280 | I3: =sum(I4,I10) -> 103234 | ... S3: =sum(S4,S10) -> 82794
A4: Online | B4: =sum(B5:B9) -> 48628 | C4: =sum(C5:C9) -> 29193 | D4: =sum(D5:D9) -> 18478 | E4: =sum(E5:E9) -> 133403 | F4: =sum(F5:F9) -> 70875 | G4: =sum(G5:G9) -> 62528 | H4: =sum(H5:H9) -> 74190 | I4: =sum(I5:I9) -> 47504 | ... S4: =sum(S5:S9) -> 34894
A5: District | B5: 19000 | C5: 13700 | D5: 5300 | E5: 131267 | F5: 70237 | G5: 61030 | H5: 74190 | I5: 47504 | J5: 2686 | K5: 78884 | L5: 25642 | M5: 8789 | N5: 61103 | O5: 38123 | P5: 22980 | Q5: 85044 | R5: 50150 | S5: 34894
A6: Hudle | B6: 25628 | C6: 13893 | D6: 10778 | E6: 2136 | F6: 638 | G6: 1498 | H6: 0 | I6: 0 | J6: 0 | K6: 0 | L6: 0 | M6: 0 | N6: 0 | O6: 0 | P6: 0 | Q6: 0 | R6: 0 | S6: 0
A7: Playo | B7: 3200 | C7: 800 | D7: 2400 | E7: 0 | F7: 0 | G7: 0 | H7: 0 | I7: 0 | J7: 0 | K7: 0 | L7: 0 | M7: 0 | N7: 0 | O7: 0 | P7: 0 | Q7: 0 | R7: 0 | S7: 0
A8: Khelomore | B8: 800 | C8: 800 | D8: 0 | E8: 0 | F8: 0 | G8: 0 | H8: 0 | I8: 0 | J8: 0 | K8: 0 | L8: 0 | M8: 0 | N8: 0 | O8: 0 | P8: 0 | Q8: 0 | R8: 0 | S8: 0
A9: Zplys | B9: 0 | C9: 0 | D9: 0 | E9: 0 | F9: 0 | G9: 0 | H9: 0 | I9: 0 | J9: 0 | K9: 0 | L9: 0 | M9: 0 | N9: 0 | O9: 0 | P9: 0 | Q9: 0 | R9: 0 | S9: 0
A10: Offline | B10: =sum(B11:B12) -> 124500 | C10: =sum(C11:C12) -> 60320 | D10: =sum(D11:D12) -> 64180 | E10: =sum(E11:E12) -> 107540 | F10: =sum(F11:F12) -> 60340 | G10: =sum(G11:G12) -> 47200 | H10: =sum(H11:H12) -> 121090 | I10: =sum(I11:I12) -> 55730 | ... S10: =sum(S11:S12) -> 47900
A11: Bookings | B11: 105700 | C11: 50920 | D11: 54780 | E11: 60740 | F11: 22940 | G11: 37800 | H11: 92290 | I11: 46330 | J11: 45960 | K11: 106685 | L11: 60125 | M11: 46560 | N11: 102734 | O11: 55300 | P11: 47434 | Q11: 63020 | R11: 41320 | S11: 21700
A12: Memberships | B12: 18800 | C12: 9400 | D12: 9400 | E12: 46800 | F12: 37400 | G12: 9400 | H12: 28800 | I12: 9400 | J12: 19400 | K12: 54800 | L12: 45400 | M12: 9400 | N12: 42800 | O12: 12000 | P12: 21400 | Q12: 35600 | R12: 9400 | S12: 26200
A13: Community | B13: =sum(B14:B16) -> 0 | C13: =sum(C14:C15) -> 0 | D13: =sum(D14:D15) -> 0 | E13: =sum(E14:E16) -> 2400 | F13: =sum(F14:F15) -> 2400 | G13: =sum(G14:G15) -> 0 | H13: =sum(H14:H16) -> 480 | I13: =sum(I14:I15) -> 480 | J13: =sum(J14:J15) -> 0 | K13: =sum(K14:K16) -> 1270 | L13: =sum(L14:L16) -> 1270 | M13: =sum(M14:M16) -> 0 | N13: =sum(N14:N16) -> 450 | O13: =sum(O14:O16) -> 450 | P13: =sum(P14:P16) -> 0 | Q13: =sum(Q14:Q16) -> 1710 | R13: =sum(R14:R16) -> 1710 | S13: =sum(S14:S16) -> 0
A14: Pickup games | B14: 0 | C14: 0 | D14: 0 | E14: 2400 | F14: 2400 | G14: 0 | H14: 480 | I14: 480 | J14: 0 | K14: 1270 | L14: 1270 | M14: 0 | N14: 450 | O14: 450 | P14: 0 | Q14: 1710 | R14: 1710 | S14: 0
A15: Social Events/Tournaments | B15: 0 | C15: 0 | D15: 0 | E15: 0 | F15: 0 | G15: 0 | H15: 0 | I15: 0 | J15: 0 | K15: 0 | L15: 0 | M15: 0 | N15: 0 | O15: 0 | P15: 0 | Q15: 0 | R15: 0
A16: Community Partnerships | B16: 0 | E16: 0 | H16: 0 | K16: 0 | L16: 0 | M16: 0 | N16: 0 | O16: 0 | P16: 0 | Q16: 0 | R16: 0 | S16: 0
A17: Academy | B17: 0 | C17: 0 | D17: 0 | E17: 0 | F17: 0 | G17: 0 | H17: 0 | I17: 0 | J17: 0 | K17: 0 | L17: 0 | M17: 0 | N17: 0 | O17: 0 | P17: 0 | Q17: 0 | R17: 0 | S17: 0
A18: B2B | B18: =sum(B19,B20) -> 2560 | C18: =sum(C19,C20) -> 0 | D18: =sum(D19,D20) -> 2560 | E18: =sum(E19,E20) -> 0 | F18: =sum(F19,F20) -> 0 | G18: =sum(G19,G20) -> 0 | H18: =sum(H19,H20) -> 0 | I18: =sum(I19,I20) -> 0 | ... S18: =sum(S19,S20) -> 1920
A19: Corporate events | B19: 2560 | C19: 0 | D19: 2560 | E19: 0 | F19: 0 | G19: 0 | H19: 0 | I19: 0 | J19: 0 | K19: 2560 | L19: 0 | M19: 2560 | N19: 2560 | O19: 0 | P19: 2560 | Q19: 1920 | R19: 0 | S19: 1920
A20: All B2B partnerships | B20: 0 | C20: 0 | D20: 0 | E20: 0 | F20: 0 | G20: 0 | H20: 0 | I20: 0 | J20: 0 | K20: 0 | L20: 0 | M20: 0 | N20: 0 | O20: 0 | P20: 0 | Q20: 0 | R20: 0 | S20: 0
A21: Commerce | B21: =sum(B22:B24) -> 8225 | C21: =sum(C22:C24) -> 8225 | D21: =sum(D22:D24) -> 0 | E21: =sum(E22:E24) -> 3925 | F21: =sum(F22:F24) -> 3925 | G21: =sum(G22:G24) -> 0 | H21: =sum(H22:H24) -> 3525 | I21: =sum(I22:I24) -> 3525 | ... S21: =sum(S22:S24) -> 0
A22: Product rental | B22: 8225 | C22: 8225 | D22: 0 | E22: 3925 | F22: 3925 | G22: 0 | H22: 3525 | I22: 3525 | J22: 0 | K22: 1000 | L22: 1000 | M22: 0 | N22: 200 | O22: 200 | P22: 0 | Q22: 175 | R22: 175 | S22: 0
A23: Product sales | B23: 0 | C23: 0 | D23: 0 | E23: 0 | F23: 0 | G23: 0 | H23: 0 | I23: 0 | J23: 0 | K23: 0 | L23: 0 | M23: 0 | N23: 0 | O23: 0 | P23: 0 | Q23: 0 | R23: 0 | S23: 0
A24: F&B | B24: 0 | C24: 0 | D24: 0 | E24: 0 | F24: 0 | G24: 0 | H24: 0 | I24: 0 | J24: 0 | K24: 0 | L24: 0 | M24: 0 | N24: 0 | O24: 0 | P24: 0 | Q24: 0 | R24: 0 | S24: 0
A25: Other Income | B25: 0 | C25: 0 | D25: 0 | E25: 0 | F25: 0 | G25: 0 | H25: 0 | I25: 0 | J25: 0 | K25: 0 | L25: 0 | M25: 0 | N25: 0 | O25: 0 | P25: 0 | Q25: 0 | R25: 0 | S25: 0
A26: Total Gross Revenue | B26: =B3+B13+B17+B18+B21+B25 -> 183913 | C26: =C3+C13+C17+C18+C21+C25 -> 97738 | D26: =D3+D13+D17+D18+D21+D25 -> 85218 | E26: =E3+E13+E17+E18+E21+E25 -> 247268 | F26: =F3+F13+F17+F18+F21+F25 -> 137540 | G26: =G3+G13+G17+G18+G21+G25 -> 109728 | H26: =H4+H10+H13+H17+H18+H21+H25 -> 199285 | I26: =I4+I10+I13+I17+I18+I21+I25 -> 107239 | J26: =J4+J10+J13+J17+J18+J21+J25 -> 68046 | K26: =K4+K10+K13+K17+K18+K21+K25 -> 245199 | L26: =L4+L10+L13+L17+L18+L21+L25 -> 133437 | M26: =M4+M10+M13+M17+M18+M21+M25 -> 67309 | N26: =N4+N10+N13+N17+N18+N21+N25 -> 209847 | O26: =sum(O3+O13+O17+O18+O21+O25) -> 106073 | P26: =sum(P3+P13+P17+P18+P21+P25) -> 94374 | Q26: =Q4+Q10+Q13+Q17+Q18+Q21+Q25 -> 187469 | R26: =R4+R10+R13+R17+R18+R21+R25 -> 102755 | S26: =S4+S10+S13+S17+S18+S21+S25 -> 84714
A27: GST | B27: =B26-(B26/1.18) -> 28054.525 | C27: =C26-(C26/1.18) -> 14909.186 | D27: =D26-(D26/1.18) -> 12999.356 | E27: =E26-(E26/1.18) -> 37718.847 | F27: =F26-(F26/1.18) -> 20980.678 | G27: =G26-(G26/1.18) -> 16738.169 | H27: =H26-(H26/1.18) -> 30399.407 | K27: =K26-(K26/1.18) -> 37403.237 | N27: =N26-(N26/1.18) -> 32010.559 | Q27: =Q26-(Q26/1.18) -> 28596.966
A28: Net Revenue Post GST | B28: =B26-B27 -> 155858.47 | C28: =C26-C27 -> 82828.814 | D28: =D26-D27 -> 72218.644 | E28: =E26-E27 -> 209549.15 | F28: 13785 | G28: =G26-G27 -> 92989.831 | H28: =H26-H27 -> 168885.59 | K28: =K26-K27 -> 207795.76 | N28: =N26-N27 -> 177836.44 | Q28: =Q26-Q27 -> 158872.03

Sheet RallyGully | EOK
B1: Link | C1: Link | D1: Link | E1: July | F1: Link | G1: Link
A2: Venues | B2: April | C2: May | D2: June | E2: July | F2: August | G2: Sept | H2: Oct | I2: Nov | J2: Dec
A3: Pay & Play | B3: =sum(B4,B10) -> 205658 | C3: =sum(C4,C10) -> 209404 | D3: =sum(D4,D10) -> 185901 | E3: =sum(E4,E10) -> 117914 | F3: =sum(F4,F10) -> 122577 | G3: =sum(G4,G10) -> 138806
A4: Online | B4: =sum(B5:B9) -> 150228 | C4: =sum(C5:C9) -> 179124 | D4: =sum(D5:D9) -> 142976 | E4: =sum(E5:E9) -> 96864 | F4: =sum(F5:F9) -> 112960 | G4: =sum(G5:G9) -> 121236
A5: District | B5: 49400 | C5: 164897 | D5: 142976 | E5: 96864 | F5: 112960 | G5: 121236
A6: Hudle | B6: 98428 | C6: 14227 | D6: 0 | E6: 0 | F6: 0 | G6: 0
A7: Playo | B7: 1200 | C7: 0 | D7: 0 | E7: 0 | F7: 0 | G7: 0
A8: Khelomore | B8: 1200 | C8: 0 | D8: 0 | E8: 0 | F8: 0 | G8: 0
A9: Zplys | B9: 0 | C9: 0 | D9: 0 | E9: 0 | F9: 0 | G9: 0
A10: Offline | B10: =sum(B11:B12) -> 55430 | C10: =sum(C11:C12) -> 30280 | D10: =sum(D11:D12) -> 42925 | E10: =sum(E11:E12) -> 21050 | F10: =sum(F11:F12) -> 9617 | G10: =sum(G11:G12) -> 17570
A11: Bookings | B11: 55430 | C11: 30280 | D11: 42925 | E11: 21050 | F11: 9617 | G11: 17570
A12: Memberships | B12: 0 | C12: 0 | D12: 0 | E12: 0 | F12: 0 | G12: 0
A13: Community | B13: =sum(B14:B16) -> 78727 | C13: =sum(C14:C16) -> 92550 | D13: =sum(D14:D16) -> 134920 | E13: =sum(E14:E16) -> 38148 | F13: =sum(F14:F16) -> 28774 | G13: =sum(G14:G16) -> 42490
A14: Pickup games | B14: 60338 | C14: 61500 | D14: 40300 | E14: 34200 | F14: 18280 | G14: 35500
A15: Social Events/Tournaments | B15: 18389 | C15: 31050 | D15: 94620 | E15: 3948 | F15: 10494 | G15: 6990
A16: Community Partnerships | B16: 0 | C16: 0 | D16: 0 | E16: 0 | F16: 0 | G16: 0
A17: Academy | B17: 0 | C17: 38000 | D17: 28500 | E17: 29500 | F17: 48750 | G17: 3500
A18: B2B | B18: =sum(B19,B20) -> 0 | C18: =sum(C19,C20) -> 0 | D18: =sum(D19,D20) -> 20000 | E18: =sum(E19,E20) -> 0 | F18: =sum(F19,F20) -> 0 | G18: =sum(G19,G20) -> 20970
A19: Corporate events | B19: 0 | C19: 0 | D19: 0 | E19: 0 | F19: 0 | G19: 0
A20: All B2B partnerships | B20: 0 | C20: 0 | D20: 20000 | E20: 0 | F20: 0 | G20: 20970
A21: Commerce | B21: =sum(B22:B24) -> 17035 | C21: =sum(C22:C24) -> 10890 | D21: =sum(D22:D24) -> 19879 | E21: =sum(E22:E24) -> 7500 | F21: =sum(F22:F24) -> 8065 | G21: =sum(G22:G24) -> 11760
A22: Product rental | B22: 14350 | C22: 8500 | D22: 12400 | E22: 3450 | F22: 4000 | G22: 5750
A23: Product sales | B23: 0 | C23: 0 | D23: 2399 | E23: 0 | F23: 0 | G23: 0
A24: F&B | B24: 2685 | C24: 2390 | D24: 5080 | E24: 4050 | F24: 4065 | G24: 6010
A25: Other Income | B25: 0 | C25: 0 | D25: 0 | E25: 0 | F25: 0 | G25: 0
A26: Total Gross Revenue | B26: =B3+B13+B17+B18+B21+B25 -> 301420 | C26: =C3+C13+C17+C18+C21+C25 -> 350844 | D26: =D3+D13+D17+D18+D21+D25 -> 389200 | E26: =E3+E13+E17+E18+E21+E25 -> 193062 | F26: =F3+F13+F17+F18+F21+F25 -> 208166 | G26: =G3+G13+G17+G18+G21+G25 -> 217526
A27: GST | B27: =B26-(B26/1.18) -> 45979.322 | C27: =C26-(C26/1.18) -> 53518.576 | D27: =D26-(D26/1.18) -> 59369.492 | E27: =E26-(E26/1.18) -> 29450.136 | F27: =F26-(F26/1.18) -> 31754.136 | G27: =G26-(G26/1.18) -> 33181.932
A28: Net Revenue Post GST | B28: =B26-B27 -> 255440.68 | C28: =C26-C27 -> 297325.42 | D28: =D26-D27 -> 329830.51 | E28: =E26-E27 -> 163611.86 | F28: =F26-F27 -> 176411.86 | G28: =G26-G27 -> 184344.07
G29: =G26/1.18 -> 184344.07

Sheet RallyGully | DOK Dwarka
B1: Link | C1: Link | D1: Link | E1: Link | F1: Link | G1: Link
A2: Venues | B2: April | C2: May | D2: June | E2: July | F2: August | G2: Sept | H2: Oct | I2: Nov | J2: Dec
A3: Pay & Play | B3: =sum(B4,B10) -> 57505 | C3: =sum(C4,C10) -> 98847 | D3: =sum(D4,D10) -> 83272 | E3: =sum(E4,E10) -> 41860 | F3: =sum(F4,F10) -> 41255 | G3: =sum(G4,G10) -> 26638
A4: Online | B4: =sum(B5:B9) -> 39965 | C4: =sum(C5:C9) -> 82967 | D4: =sum(D5:D9) -> 61998 | E4: =sum(E5:E9) -> 31980 | F4: =sum(F5:F9) -> 32924 | G4: =sum(G5:G9) -> 23148
A5: District | B5: 17925 | C5: 78175 | D5: 61998 | E5: 31980 | F5: 32924 | G5: 23148
A6: Hudle | B6: 16440 | C6: 3192 | D6: 0 | E6: 0 | F6: 0 | G6: 0
A7: Playo | B7: 2400 | C7: 1600 | D7: 0 | E7: 0 | F7: 0 | G7: 0
A8: Khelomore | B8: 3200 | C8: 0 | D8: 0 | E8: 0 | F8: 0 | G8: 0
A9: Zplys | B9: 0 | C9: 0 | D9: 0 | E9: 0 | F9: 0 | G9: 0
A10: Offline | B10: =sum(B11:B12) -> 17540 | C10: =sum(C11:C12) -> 15880 | D10: =sum(D11:D12) -> 21274 | E10: =sum(E11:E12) -> 9880 | F10: =sum(F11:F12) -> 8331 | G10: =sum(G11:G12) -> 3490
A11: Bookings | B11: 17540 | C11: 15880 | D11: 21274 | E11: 9880 | F11: 8331 | G11: 3490
A12: Memberships | B12: 0 | C12: 0 | D12: 0 | E12: 0 | F12: 0 | G12: 0
A13: Community | B13: =sum(B14:B16) -> 5900 | C13: =sum(C14:C16) -> 7600 | D13: =sum(D14:D16) -> 6120 | E13: =sum(E14:E16) -> 5800 | F13: =sum(F14:F16) -> 1476 | G13: =sum(G14:G16) -> 4897
A14: Pickup games | B14: 5900 | C14: 7600 | D14: 6120 | E14: 5800 | F14: 1476 | G14: 4897
A15: Social Events/Tournaments | B15: 0 | C15: 0 | D15: 0 | E15: 0 | F15: 0 | G15: 0
A16: Community Partnerships | B16: 0 | C16: 0 | D16: 0 | E16: 0 | F16: 0 | G16: 0
A17: Academy | B17: 0 | C17: 0 | D17: 0 | E17: 18000 | F17: 18000 | G17: 18000
A18: B2B | B18: =sum(B19,B20) -> 0 | C18: =sum(C19,C20) -> 0 | D18: =sum(D19,D20) -> 0 | E18: =sum(E19,E20) -> 0 | F18: =sum(F19,F20) -> 0 | G18: =sum(G19,G20) -> 0
A19: Corporate events | B19: 0 | C19: 0 | D19: 0 | E19: 0 | F19: 0 | G19: 0
A20: All B2B partnerships | B20: 0 | C20: 0 | D20: 0 | E20: 0 | F20: 0 | G20: 0
A21: Commerce | B21: =sum(B22:B24) -> 3950 | C21: =sum(C22:C24) -> 7875 | D21: =sum(D22:D24) -> 3425 | E21: =sum(E22:E24) -> 2100 | F21: =sum(F22:F24) -> 3500 | G21: =sum(G22:G24) -> 3200
A22: Product rental | B22: 3950 | C22: 7875 | D22: 3425 | E22: 2100 | F22: 3500 | G22: 3200
A23: Product sales | B23: 0 | C23: 0 | D23: 0 | E23: 0 | F23: 0 | G23: 0
A24: F&B | B24: 0 | C24: 0 | D24: 0 | E24: 0 | F24: 0 | G24: 0
A25: Other Income | B25: 18000 | C25: 18000 | D25: 18000 | E25: 0 | F25: 0 | G25: 0
A26: Total Gross Revenue | B26: =B3+B13+B17+B18+B21+B25 -> 85355 | C26: =C3+C13+C17+C18+C21+C25 -> 132322 | D26: =D3+D13+D17+D18+D21+D25 -> 110817 | E26: =E3+E13+E17+E18+E21+E25 -> 67760 | F26: =F3+F13+F17+F18+F21+F25 -> 64231 | G26: =G3+G13+G17+G18+G21+G25 -> 52735
A27: GST | B27: =B26-(B26/1.18) -> 13020.254 | C27: =C26-(C26/1.18) -> 20184.712 | D27: =D26-(D26/1.18) -> 16904.288 | E27: =E26-(E26/1.18) -> 10336.271 | F27: =F26-(F26/1.18) -> 9797.9492 | G27: =G26-(G26/1.18) -> 8044.322
A28: Net Revenue Post GST | B28: =B26-B27 -> 72334.746 | C28: =C26-C27 -> 112137.29 | D28: =D26-D27 -> 93912.712 | E28: =E26-E27 -> 57423.729 | F28: =F26-F27 -> 54433.051 | G28: =G26-G27 -> 44690.678

Sheet RallyGully | DPSG
B1: Link | C1: Link | D1: Link | E1: Link | F1: Link | G1: Link
A2: Venues | B2: April | C2: May | D2: June | E2: July | F2: August | G2: Sept | H2: Oct | I2: Nov | J2: Dec
A3: Pay & Play | B3: =sum(B4,B10) -> 84355 | C3: =sum(C4,C10) -> 142228 | D3: =sum(D4,D10) -> 100617 | E3: =sum(E4,E10) -> 57151 | F3: =sum(F4,F10) -> 52819 | G3: =sum(G4,G10) -> 43289
A4: Online | B4: =sum(B5:B9) -> 33095 | C4: =sum(C5:C9) -> 97228 | D4: =sum(D5:D9) -> 39717 | E4: =sum(E5:E9) -> 36361 | F4: =sum(F5:F9) -> 36495 | G4: =sum(G5:G9) -> 32802
A5: District | B5: 21550 | C5: 93238 | D5: 39717 | E5: 36361 | F5: 36495 | G5: 32802
A6: Hudle | B6: 11545 | C6: 3990 | D6: 0 | E6: 0 | F6: 0 | G6: 0
A7: Playo | B7: 0 | C7: 0 | D7: 0 | E7: 0 | F7: 0 | G7: 0
A8: Khelomore | B8: 0 | C8: 0 | D8: 0 | E8: 0 | F8: 0 | G8: 0
A9: Zplys | B9: 0 | C9: 0 | D9: 0 | E9: 0 | F9: 0 | G9: 0
A10: Offline | B10: =sum(B11:B12) -> 51260 | C10: =sum(C11:C12) -> 45000 | D10: =sum(D11:D12) -> 60900 | E10: =sum(E11:E12) -> 20790 | F10: =sum(F11:F12) -> 16324 | G10: =sum(G11:G12) -> 10487
A11: Bookings | B11: 43760 | C11: 45000 | D11: 60900 | E11: 20790 | F11: 16324 | G11: 10487
A12: Memberships | B12: 7500 | C12: 0 | D12: 0 | E12: 0 | F12: 0 | G12: 0
A13: Community | B13: =sum(B14:B16) -> 3600 | C13: =sum(C14:C16) -> 3600 | D13: =sum(D14:D16) -> 1440 | E13: =sum(E14:E16) -> 6080 | F13: =sum(F14:F16) -> 3476 | G13: =sum(G14:G16) -> 1540
A14: Pickup games | B14: 3600 | C14: 3600 | D14: 1440 | E14: 6080 | F14: 3476 | G14: 1540
A15: Social Events/Tournaments | B15: 0 | C15: 0 | D15: 0 | E15: 0 | F15: 0 | G15: 0
A16: Community Partnerships | B16: 0 | C16: 0 | D16: 0 | E16: 0 | F16: 0 | G16: 0
A17: Academy | B17: 0 | C17: 0 | D17: 5000 | E17: 0 | F17: 0 | G17: 0
A18: B2B | B18: =sum(B19,B20) -> 0 | C18: =sum(C19,C20) -> 0 | D18: =sum(D19,D20) -> 0 | E18: =sum(E19,E20) -> 0 | F18: =sum(F19,F20) -> 0 | G18: =sum(G19,G20) -> 0
A19: Corporate events | B19: 0 | C19: 0 | D19: 0 | E19: 0 | F19: 0 | G19: 0
A20: All B2B partnerships | B20: 0 | C20: 0 | D20: 0 | E20: 0 | F20: 0 | G20: 0
A21: Commerce | B21: =sum(B22:B24) -> 7235 | C21: =sum(C22:C24) -> 11205 | D21: =sum(D22:D24) -> 10675 | E21: =sum(E22:E24) -> 4975 | F21: =sum(F22:F24) -> 6320 | G21: =sum(G22:G24) -> 4240
A22: Product rental | B22: 6850 | C22: 11100 | D22: 10290 | E22: 4800 | F22: 6250 | G22: 4240
A23: Product sales | B23: 0 | C23: 0 | D23: 0 | E23: 0 | F23: 0 | G23: 0
A24: F&B | B24: 385 | C24: 105 | D24: 385 | E24: 175 | F24: 70 | G24: 0
A25: Other Income | B25: 0 | C25: 0 | D25: 0 | E25: 0 | F25: 0 | G25: 0
A26: Total Gross Revenue | B26: =B3+B13+B17+B18+B21+B25 -> 95190 | C26: =C3+C13+C17+C18+C21+C25 -> 157033 | D26: =D3+D13+D17+D18+D21+D25 -> 117732 | E26: =E3+E13+E17+E18+E21+E25 -> 68206 | F26: =F3+F13+F17+F18+F21+F25 -> 62615 | G26: =G3+G13+G17+G18+G21+G25 -> 49069
A27: GST | B27: =B26-(B26/1.18) -> 14520.508 | C27: =C26-(C26/1.18) -> 23954.186 | D27: =D26-(D26/1.18) -> 17959.119 | E27: =E26-(E26/1.18) -> 10404.305 | F27: =F26-(F26/1.18) -> 9551.4407 | G27: =G26-(G26/1.18) -> 7485.1017
A28: Net Revenue Post GST | B28: =B26-B27 -> 80669.492 | C28: =C26-C27 -> 133078.81 | D28: =D26-D27 -> 99772.881 | E28: =E26-E27 -> 57801.695 | F28: =F26-F27 -> 53063.559 | G28: =G26-G27 -> 41583.898

Sheet RallyGully | Panchsheel
B1: Link | C1: Link | D1: Link | E1: Link | F1: Link | G1: Link
A2: Venues | B2: April | C2: May | D2: June | E2: July | F2: August | G2: Sept | H2: Oct | I2: Nov | J2: Dec
A3: Pay & Play | B3: =sum(B4,B10) -> 114996 | C3: =sum(C4,C10) -> 109675 | D3: =sum(D4,D10) -> 72234 | E3: =sum(E4,E10) -> 54301 | F3: =sum(F4,F10) -> 34608 | G3: =sum(G4,G10) -> 53046
A4: Online | B4: =sum(B5:B9) -> 107696 | C4: =sum(C5:C9) -> 96675 | D4: =sum(D5:D9) -> 62834 | E4: =sum(E5:E9) -> 24256 | F4: =sum(F5:F9) -> 31608 | G4: =sum(G5:G9) -> 39546
A5: District | B5: 49100 | C5: 71921 | D5: 62834 | E5: 24256 | F5: 31608 | G5: 39546
A6: Hudle | B6: 54696 | C6: 22954 | D6: 0 | E6: 0 | F6: 0 | G6: 0
A7: Playo | B7: 3900 | C7: 1800 | D7: 0 | E7: 0 | F7: 0 | G7: 0
A8: Khelomore | B8: 0 | C8: 0 | D8: 0 | E8: 0 | F8: 0 | G8: 0
A9: Zplys | B9: 0 | C9: 0 | D9: 0 | E9: 0 | F9: 0 | G9: 0
A10: Offline | B10: =sum(B11:B12) -> 7300 | C10: =sum(C11:C12) -> 13000 | D10: =sum(D11:D12) -> 9400 | E10: =sum(E11:E12) -> 30045 | F10: =sum(F11:F12) -> 3000 | G10: =sum(G11:G12) -> 13500
A11: Bookings | B11: 7300 | C11: 13000 | D11: 9400 | E11: 30045 | F11: 3000 | G11: 500
A12: Memberships | B12: 0 | C12: 0 | D12: 0 | E12: 0 | F12: 0 | G12: 13000
A13: Community | B13: =sum(B14:B16) -> 2756 | C13: =sum(C14:C16) -> 1800 | D13: =sum(D14:D16) -> 0 | E13: =sum(E14:E16) -> 0 | F13: =sum(F14:F16) -> 2450 | G13: =sum(G14:G16) -> 1500
A14: Pickup games | B14: 2756 | C14: 1800 | D14: 0 | E14: 0 | F14: 2450 | G14: 1500
A15: Social Events/Tournaments | B15: 0 | C15: 0 | D15: 0 | E15: 0 | F15: 0 | G15: 0
A16: Community Partnerships | B16: 0 | C16: 0 | D16: 0 | E16: 0 | F16: 0 | G16: 0
A17: Academy | B17: 0 | C17: 0 | D17: 0 | E17: 0 | F17: 0 | G17: 0
A18: B2B | B18: =sum(B19,B20) -> 0 | C18: =sum(C19,C20) -> 0 | D18: =sum(D19,D20) -> 0 | E18: =sum(E19,E20) -> 6000 | F18: =sum(F19,F20) -> 0 | G18: =sum(G19,G20) -> 2000
A19: Corporate events | B19: 0 | C19: 0 | D19: 0 | E19: 0 | F19: 0 | G19: 2000
A20: All B2B partnerships | B20: 0 | C20: 0 | D20: 0 | E20: 6000 | F20: 0 | G20: 0
A21: Commerce | B21: =sum(B22:B24) -> 8435 | C21: =sum(C22:C24) -> 7720 | D21: =sum(D22:D24) -> 5500 | E21: =sum(E22:E24) -> 5500 | F21: =sum(F22:F24) -> 1350 | G21: =sum(G22:G24) -> 275
A22: Product rental | B22: 8435 | C22: 7720 | D22: 5500 | E22: 5500 | F22: 1350 | G22: 275
A23: Product sales | B23: 0 | C23: 0 | D23: 0 | E23: 0 | F23: 0 | G23: 0
A24: F&B | B24: 0 | C24: 0 | D24: 0 | E24: 0 | F24: 0 | G24: 0
A25: Other Income | B25: 0 | C25: 0 | D25: 0 | E25: 0 | F25: 0 | G25: 0
A26: Total Gross Revenue | B26: =B3+B13+B17+B18+B21+B25 -> 126187 | C26: =C3+C13+C17+C18+C21+C25 -> 119195 | D26: =D3+D13+D17+D18+D21+D25 -> 77734 | E26: =E3+E13+E17+E18+E21+E25 -> 65801 | F26: =F3+F13+F17+F18+F21+F25 -> 38408 | G26: =G3+G13+G17+G18+G21+G25 -> 56821
A27: GST | B27: =B26-(B26/1.18) -> 19248.864 | C27: =C26-(C26/1.18) -> 18182.288 | D27: =D26-(D26/1.18) -> 11857.729 | E27: =E26-(E26/1.18) -> 10037.441 | F27: =F26-(F26/1.18) -> 5858.8475 | G27: =G26-(G26/1.18) -> 8667.6102
A28: Net Revenue Post GST | B28: =B26-B27 -> 106938.14 | C28: =C26-C27 -> 101012.71 | D28: =D26-D27 -> 65876.271 | E28: =E26-E27 -> 55763.559 | F28: =F26-F27 -> 32549.153 | G28: =G26-G27 -> 48153.39

Sheet RallyGully | LCR
B1: Link | C1: Link | D1: Link | E1: Link | F1: Link | G1: Link
A2: Venues | B2: April | C2: May | D2: June | E2: July | F2: August | G2: Sept | H2: Oct | I2: Nov | J2: Dec
A3: Pay & Play | B3: =sum(B4,B10) -> 179568 | C3: =sum(C4,C10) -> 283572 | D3: =sum(D4,D10) -> 164155 | E3: =sum(E4,E10) -> 74328 | F3: =sum(F4,F10) -> 82414 | G3: =sum(G4,G10) -> 109927
A4: Online | B4: =sum(B5:B9) -> 78287 | C4: =sum(C5:C9) -> 169817 | D4: =sum(D5:D9) -> 109600 | E4: =sum(E5:E9) -> 59528 | F4: =sum(F5:F9) -> 74519 | G4: =sum(G5:G9) -> 86293
A5: District | B5: 0 | C5: 87543 | D5: 45000 | E5: 42153 | F5: 43069 | G5: 52574
A6: Hudle | B6: 13450 | C6: 19250 | D6: 10500 | E6: 3650 | F6: 12250 | G6: 9370
A7: Playo | B7: 38962 | C7: 38749 | D7: 27850 | E7: 9600 | F7: 9175 | G7: 16025
A8: Khelomore | B8: 25875 | C8: 24275 | D8: 26250 | E8: 4125 | F8: 10025 | G8: 8324
A9: Zplys | B9: 0 | C9: 0 | D9: 0 | E9: 0 | F9: 0 | G9: 0
A10: Offline | B10: =sum(B11:B12) -> 101281 | C10: =sum(C11:C12) -> 113755 | D10: =sum(D11:D12) -> 54555 | E10: =sum(E11:E12) -> 14800 | F10: =sum(F11:F12) -> 7895 | G10: =sum(G11:G12) -> 23634
A11: Bookings | B11: 101281 | C11: 113755 | D11: 54555 | E11: 14800 | F11: 7895 | G11: 23634
A12: Memberships | B12: 0 | C12: 0 | D12: 0 | E12: 0 | F12: 0 | G12: 0
A13: Community | B13: =sum(B14:B16) -> 3588 | C13: =sum(C14:C16) -> 0 | D13: =sum(D14:D16) -> 0 | E13: =sum(E14:E16) -> 0 | F13: =sum(F14:F16) -> 0 | G13: =sum(G14:G16) -> 0
A14: Pickup games | B14: 0 | C14: 0 | D14: 0 | E14: 0 | F14: 0 | G14: 0
A15: Social Events/Tournaments | B15: 3588 | C15: 0 | D15: 0 | E15: 0 | F15: 0 | G15: 0
A16: Community Partnerships | B16: 0 | C16: 0 | D16: 0 | E16: 0 | F16: 0 | G16: 0
A17: Academy | B17: 0 | C17: 0 | D17: 0 | E17: 0 | F17: 0 | G17: 0
A18: B2B | B18: =sum(B19,B20) -> 18000 | C18: =sum(C19,C20) -> 0 | D18: =sum(D19,D20) -> 0 | E18: =sum(E19,E20) -> 0 | F18: =sum(F19,F20) -> 0 | G18: =sum(G19,G20) -> 0
A19: Corporate events | B19: 18000 | C19: 0 | D19: 0 | E19: 0 | F19: 0 | G19: 0
A20: All B2B partnerships | B20: 0 | C20: 0 | D20: 0 | E20: 0 | F20: 0 | G20: 0
A21: Commerce | B21: =sum(B22:B24) -> 21525 | C21: =sum(C22:C24) -> 19750 | D21: =sum(D22:D24) -> 19400 | E21: =sum(E22:E24) -> 10150 | F21: =sum(F22:F24) -> 13075 | G21: =sum(G22:G24) -> 13300
A22: Product rental | B22: 21525 | C22: 19750 | D22: 19400 | E22: 10150 | F22: 13075 | G22: 13300
A23: Product sales | B23: 0 | C23: 0 | D23: 0 | E23: 0 | F23: 0 | G23: 0
A24: F&B | B24: 0 | C24: 0 | D24: 0 | E24: 0 | F24: 0 | G24: 0
A25: Other Income | B25: 120000 | C25: 120000 | D25: 120000 | E25: 120000 | F25: 120000 | G25: 120000
A26: Total Gross Revenue | B26: =B3+B13+B17+B18+B21+B25 -> 342681 | C26: =C3+C13+C17+C18+C21+C25 -> 423322 | D26: =D3+D13+D17+D18+D21+D25 -> 303555 | E26: =E3+E13+E17+E18+E21+E25 -> 204478 | F26: =F3+F13+F17+F18+F21+F25 -> 215489 | G26: =G3+G13+G17+G18+G21+G25 -> 243227
A27: GST | B27: =B26-(B26/1.18) -> 52273.373 | C27: =C26-(C26/1.18) -> 64574.542 | D27: =D26-(D26/1.18) -> 46305 | E27: =E26-(E26/1.18) -> 31191.559 | F27: =F26-(F26/1.18) -> 32871.203 | G27: =G26-(G26/1.18) -> 37102.424
A28: Net Revenue Post GST | B28: =B26-B27 -> 290407.63 | C28: =C26-C27 -> 358747.46 | D28: =D26-D27 -> 257250 | E28: =E26-E27 -> 173286.44 | F28: =F26-F27 -> 182617.8 | G28: =G26-G27 -> 206124.58

Sheet RallyGully | Gandipath Jaipur
B1: Link | C1: Link | D1: Link | E1: Link | F1: Link
A2: Venues | B2: April | C2: May | D2: June | E2: July | F2: August
A3: Pay & Play | B3: =sum(B4,B10) -> 46515 | C3: =sum(C4,C10) -> 31460 | D3: =sum(D4,D10) -> 36755 | E3: =sum(E4,E10) -> 34021 | F3: =sum(F4,F10) -> 33197
A4: Online | B4: =sum(B5:B9) -> 37856 | C4: =sum(C5:C9) -> 22560 | D4: =sum(D5:D9) -> 32255 | E4: =sum(E5:E9) -> 31721 | F4: =sum(F5:F9) -> 31057
A5: District | B5: 0 | C5: 7128 | D5: 23861 | E5: 28546 | F5: 29905
A6: Hudle | B6: 950 | C6: 638 | D6: 1196 | E6: 1993 | F6: 0
A7: Playo | B7: 0 | C7: 800 | D7: 0 | E7: 598 | F7: 0
A8: Khelomore | B8: 0 | C8: 0 | D8: 0 | E8: 0 | F8: 0
A9: Zplys | B9: 36906 | C9: 13994 | D9: 7198 | E9: 584 | F9: 1152
A10: Offline | B10: =sum(B11:B12) -> 8659 | C10: =sum(C11:C12) -> 8900 | D10: =sum(D11:D12) -> 4500 | E10: =sum(E11:E12) -> 2300 | F10: =sum(F11:F12) -> 2140
A11: Bookings | B11: 8659 | C11: 8900 | D11: 4500 | E11: 2300 | F11: 2140
A12: Memberships | B12: 0 | C12: 0 | D12: 0 | E12: 0 | F12: 0
A13: Community | B13: =sum(B14:B16) -> 0 | C13: =sum(C14:C16) -> 0 | D13: =sum(D14:D16) -> 0 | E13: =sum(E14:E16) -> 0 | F13: =sum(F14:F16) -> 0
A14: Pickup games | B14: 0 | C14: 0 | D14: 0 | E14: 0 | F14: 0
A15: Social Events/Tournaments | B15: 0 | C15: 0 | D15: 0 | E15: 0 | F15: 0
A16: Community Partnerships | B16: 0 | C16: 0 | D16: 0 | E16: 0 | F16: 0
A17: Academy | B17: 0 | C17: 0 | D17: 0 | E17: 0 | F17: 0
A18: B2B | B18: =sum(B19,B20) -> 0 | C18: =sum(C19,C20) -> 0 | D18: =sum(D19,D20) -> 0 | E18: =sum(E19,E20) -> 0 | F18: =sum(F19,F20) -> 0
A19: Corporate events | B19: 0 | C19: 0 | D19: 0 | E19: 0 | F19: 0
A20: All B2B partnerships | B20: 0 | C20: 0 | D20: 0 | E20: 0 | F20: 0
A21: Commerce | B21: =sum(B22:B24) -> 0 | C21: =sum(C22:C24) -> 0 | D21: =sum(D22:D24) -> 0 | E21: =sum(E22:E24) -> 0 | F21: =sum(F22:F24) -> 0
A22: Product rental | B22: 0 | C22: 0 | D22: 0 | E22: 0 | F22: 0
A23: Product sales | B23: 0 | C23: 0 | D23: 0 | E23: 0 | F23: 0
A24: F&B | B24: 0 | C24: 0 | D24: 0 | E24: 0 | F24: 0
A25: Other Income | B25: 0 | C25: 0 | D25: 0 | E25: 15000 | F25: 7500
A26: Total Gross Revenue | B26: =B3+B13+B17+B18+B21+B25 -> 46515 | C26: =C3+C13+C17+C18+C21+C25 -> 31460 | D26: =D3+D13+D17+D18+D21+D25 -> 36755 | E26: =E3+E13+E17+E18+E21+E25 -> 49021 | F26: =F3+F13+F17+F18+F21+F25 -> 40697
A27: GST | B27: =B26-(B26/1.18) -> 7095.5085 | C27: =C26-(C26/1.18) -> 4798.9831 | D27: =D26-(D26/1.18) -> 5606.6949 | E27: =E26-(E26/1.18) -> 7477.7797 | F27: =F26-(F26/1.18) -> 6208.0169
A28: Net Revenue Post GST | B28: =B26-B27 -> 39419.492 | C28: =C26-C27 -> 26661.017 | D28: =D26-D27 -> 31148.305 | E28: =E26-E27 -> 41543.22 | F28: =F26-F27 -> 34488.983

Sheet RallyGully | Powerplay
B1: Link | F1: Link | J1: Link | N1: Link | R1: Link | V1: Link
A2: Venues | B2: April | C2: Pickleball | D2: Turf | E2: Padel | F2: May | G2: Pickleball | H2: Turf | I2: Padel | J2: June | K2: Pickleball | L2: Turf | M2: Padel | N2: July | O2: Pickleball | P2: Turf | Q2: Padel | R2: August | S2: Pickleball | T2: Turf | U2: Padel | V2: Sept | W2: Pickleball | X2: Turf | Y2: Padel
A3: Pay & Play | B3: =sum(B4,B10) -> 108511 | C3: =sum(C4,C10) -> 53909 | D3: =sum(D4,D10) -> 51089 | E3: =sum(E4,E10) -> 0 | F3: =sum(F4,F10) -> 134927 | G3: =sum(G4,G10) -> 87588 | H3: =sum(H4,H10) -> 50432 | I3: =sum(I4,I10) -> 0 | ... Y3: =sum(Y4,Y10) -> 0
A4: Online | B4: =sum(B5:B9) -> 63243 | C4: =sum(C5:C9) -> 25859 | D4: =sum(D5:D9) -> 33871 | E4: =sum(E5:E9) -> 0 | F4: =sum(F5:F9) -> 96037 | G4: =sum(G5:G9) -> 59638 | H4: =sum(H5:H9) -> 39492 | I4: =sum(I5:I9) -> 0 | ... Y4: =sum(Y5:Y9) -> 0
A5: District | B5: 0 | C5: 0 | D5: 0 | E5: 0 | F5: 9579 | G5: 5584 | H5: 3995 | I5: 0 | J5: 10819 | K5: 10819 | L5: 0 | M5: 0 | N5: 2946 | O5: 0 | P5: =N5-O5 -> 2946 | Q5: 0 | R5: 1943 | S5: 1943 | T5: 0 | U5: 0 | V5: 2990 | W5: 2990 | X5: 0 | Y5: 0
A6: Hudle | B6: 7457 | C6: 6686 | D6: 771 | E6: 0 | F6: 9213 | G6: 9213 | H6: 0 | I6: 0 | J6: 2240 | K6: 2240 | L6: 0 | M6: 0 | N6: 4400 | O6: 4400 | P6: =N6-O6 -> 0 | Q6: 0 | R6: 700 | S6: 700 | T6: 0 | U6: 0 | V6: 700 | W6: 700 | Y6: 0
A7: Playo | B7: 43173 | C7: 8960 | D7: 30700 | E7: 0 | F7: 60245 | G7: 30241 | H7: 33097 | I7: 0 | J7: 57025 | K7: 13120 | L7: 43905 | M7: 0 | N7: 17555 | O7: 3080 | P7: =N7-O7 -> 14475 | Q7: 0 | R7: 16830 | S7: 1580 | T7: 15150 | U7: 0 | V7: 28705 | W7: 7280 | X7: 21425 | Y7: 0
A8: Khelomore | B8: 12613 | C8: 10213 | D8: 2400 | E8: 0 | F8: 17000 | G8: 14600 | H8: 2400 | I8: 0 | J8: 8927 | K8: 7329 | L8: 1598 | M8: 0 | N8: 10029 | O8: 5235 | P8: =N8-O8 -> 4794 | Q8: 0 | R8: 1954 | S8: 1954 | T8: 0 | U8: 0 | V8: 4754 | W8: 0 | X8: 4754 | Y8: 0
A9: Zplys | B9: 0 | C9: 0 | D9: 0 | E9: 0 | F9: 0 | G9: 0 | H9: 0 | I9: 0 | J9: 0 | K9: 0 | L9: 0 | M9: 0 | N9: 0 | O9: 0 | P9: =N9-O9 -> 0 | Q9: 0 | R9: 0 | S9: 0 | T9: 0 | U9: 0 | V9: 0 | W9: 0 | X9: 0 | Y9: 0
A10: Offline | B10: =sum(B11:B12) -> 45268 | C10: =sum(C11:C12) -> 28050 | D10: =sum(D11:D12) -> 17218 | E10: =sum(E11:E12) -> 0 | F10: =sum(F11:F12) -> 38890 | G10: =sum(G11:G12) -> 27950 | H10: =sum(H11:H12) -> 10940 | I10: =sum(I11:I12) -> 0 | ... Y10: =sum(Y11:Y12) -> 0
A11: Bookings | B11: 45268 | C11: 28050 | D11: 17218 | E11: 0 | F11: 38890 | G11: 27950 | H11: 10940 | I11: 0 | J11: 20650 | K11: 11800 | L11: 11300 | M11: 0 | N11: 8890 | O11: 3100 | P11: =N11-O11 -> 5790 | Q11: 0 | R11: 2000 | S11: 1300 | T11: 700 | U11: 0 | V11: 2700 | W11: 1300 | X11: 1400 | Y11: 0
A12: Memberships | B12: 0 | C12: 0 | D12: 0 | E12: 0 | F12: 0 | G12: 0 | H12: 0 | I12: 0 | J12: 0 | K12: 0 | L12: 0 | M12: 0 | N12: 0 | O12: 0 | P12: 0 | Q12: 0 | R12: 0 | S12: 0 | T12: 0 | U12: 0 | V12: 0 | W12: 0 | X12: 0 | Y12: 0
A13: Community | B13: =sum(B14:B16) -> 0 | C13: =sum(C14:C15) -> 0 | D13: =sum(D14:D15) -> 0 | E13: =sum(E14:E15) -> 0 | F13: =sum(F14:F16) -> 0 | G13: =sum(G14:G15) -> 0 | H13: =sum(H14:H15) -> 0 | I13: =sum(I14:I15) -> 0 | J13: =sum(J14:J16) -> 0 | K13: =sum(K14:K16) -> 0 | L13: =sum(L14:L16) -> 0 | M13: =sum(M14:M16) -> 0 | N13: =sum(N14:N16) -> 0 | O13: =sum(O14:O16) -> 0 | P13: =sum(P14:P16) -> 0 | Q13: =sum(Q14:Q16) -> 0 | R13: =sum(R14:R15) -> 0 | S13: =sum(S14:S15) -> 0 | T13: =sum(T14:T15) -> 0 | U13: =sum(U14:U15) -> 0 | V13: =sum(V14:V16) -> 0 | W13: =sum(W14:W16) -> 0 | X13: =sum(X14:X16) -> 0 | Y13: =sum(Y14:Y16) -> 0
A14: Pickup games | B14: 0 | C14: 0 | D14: 0 | E14: 0 | F14: 0 | G14: 0 | H14: 0 | I14: 0 | J14: 0 | K14: 0 | L14: 0 | M14: 0 | N14: 0 | O14: 0 | P14: 0 | Q14: 0 | R14: 0 | S14: 0 | T14: 0 | U14: 0 | V14: 0 | W14: 0 | X14: 0 | Y14: 0
A15: Social Events/Tournaments | B15: 0 | C15: 0 | D15: 0 | E15: 0 | F15: 0 | G15: 0 | H15: 0 | I15: 0 | J15: 0 | K15: 0 | L15: 0 | M15: 0 | N15: 0 | O15: 0 | P15: 0 | Q15: 0 | R15: 0 | S15: 0 | T15: 0 | U15: 0 | V15: 0 | W15: 0 | X15: 0 | Y15: 0
A16: Community Partnerships | B16: 0 | F16: 0 | J16: 0 | K16: 0 | L16: 0 | M16: 0 | N16: 0 | O16: 0 | P16: 0 | Q16: 0 | R16: 0 | S16: 0 | T16: 0 | U16: 0 | V16: 0 | W16: 0 | X16: 0 | Y16: 0
A17: Academy | B17: 0 | C17: 0 | D17: 0 | E17: 0 | F17: 0 | G17: 0 | H17: 0 | I17: 0 | J17: =J15/1.18 -> 0 | K17: =K15/1.18 -> 0 | L17: =L15/1.18 -> 0 | M17: 0 | N17: =N15/1.18 -> 0 | O17: =O15/1.18 -> 0 | P17: =P15/1.18 -> 0 | Q17: 0 | R17: 0 | S17: 0 | T17: 0 | U17: 0 | V17: 0 | W17: 0 | X17: 0 | Y17: 0
A18: B2B | B18: =sum(B19,B20) -> 0 | C18: =sum(C19,C20) -> 0 | D18: =sum(D19,D20) -> 0 | E18: =sum(E19,E20) -> 0 | F18: =sum(F19,F20) -> 0 | G18: =sum(G19,G20) -> 0 | H18: =sum(H19,H20) -> 0 | I18: =sum(I19,I20) -> 0 | ... V18: =sum(V19,V20) -> 2720 | W18: =sum(W19) -> 0 | X18: =sum(X19) -> 2720 | Y18: 0
A19: Corporate events | B19: 0 | C19: 0 | D19: 0 | E19: 0 | F19: 0 | G19: 0 | H19: 0 | I19: 0 | J19: 0 | K19: 0 | L19: 0 | M19: 0 | N19: 0 | O19: 0 | P19: 0 | Q19: 0 | R19: 0 | S19: 0 | T19: 0 | U19: 0 | V19: 2720 | W19: 0 | X19: 2720 | Y19: 0
A20: All B2B partnerships | B20: 0 | C20: 0 | D20: 0 | E20: 0 | F20: 0 | G20: 0 | H20: 0 | I20: 0 | J20: 0 | K20: 0 | L20: 0 | M20: 0 | N20: 0 | O20: 0 | P20: 0 | Q20: 0 | R20: 0 | S20: 0 | T20: 0 | U20: 0 | V20: 0 | W20: =SUM(W21:W24) -> 0 | X20: 0 | Y20: 0
A21: Commerce | B21: =sum(B22:B24) -> 0 | C21: =sum(C22:C24) -> 0 | D21: =sum(D22:D24) -> 0 | E21: =sum(E22:E24) -> 0 | F21: =sum(F22:F24) -> 0 | G21: =sum(G22:G24) -> 0 | H21: =sum(H22:H24) -> 0 | I21: =sum(I22:I24) -> 0 | ... X21: =sum(X22:X24) -> 0 | Y21: 0
A22: Product rental | B22: 0 | C22: 0 | D22: 0 | E22: 0 | F22: 0 | G22: 0 | H22: 0 | I22: 0 | J22: 0 | K22: 0 | L22: 0 | M22: 0 | N22: 0 | O22: 0 | P22: 0 | Q22: 0 | R22: 0 | S22: 0 | T22: 0 | U22: 0 | V22: 0 | W22: 0 | X22: 0 | Y22: 0
A23: Product sales | B23: 0 | C23: 0 | D23: 0 | E23: 0 | F23: 0 | G23: 0 | H23: 0 | I23: 0 | J23: 0 | K23: 0 | L23: 0 | M23: 0 | N23: 0 | O23: 0 | P23: 0 | Q23: 0 | R23: 0 | S23: 0 | T23: 0 | U23: 0 | V23: 0 | W23: 0 | X23: 0 | Y23: 0
A24: F&B | B24: 0 | C24: 0 | D24: 0 | E24: 0 | F24: 0 | G24: 0 | H24: 0 | I24: 0 | J24: 0 | K24: 0 | L24: 0 | M24: 0 | N24: 0 | O24: 0 | P24: 0 | Q24: 0 | R24: 0 | S24: 0 | T24: 0 | U24: 0 | V24: 0 | W24: 0 | X24: 0 | Y24: 0
A25: Other Income | B25: 118000 | C25: 0 | D25: 0 | E25: 118000 | F25: 118000 | G25: 0 | H25: 0 | I25: 118000 | J25: 118000 | K25: 0 | L25: 0 | M25: 118000 | N25: 118000 | O25: 0 | P25: 0 | Q25: 118000 | R25: 118000 | S25: 0 | T25: 0 | U25: 118000 | V25: 118000 | W25: 0 | X25: 0 | Y25: 118000
A26: Total Gross Revenue | B26: =B3+B13+B17+B18+B21+B25 -> 226511 | C26: =C3+C13+C17+C18+C21+C25 -> 53909 | D26: =D3+D13+D17+D18+D21+D25 -> 51089 | E26: =E3+E13+E17+E18+E21+E25 -> 118000 | F26: =F3+F13+F17+F18+F21+F25 -> 252927 | G26: =G3+G13+G17+G18+G21+G25 -> 87588 | J26: =J3+J13+J17+J18+J21+J25 -> 217661 | K26: =K4+K10+K13+K17+K18+K21+K25 -> 45308 | L26: =L4+L10+L13+L17+L18+L21+L25 -> 56803 | M26: =M4+M10+M13+M17+M18+M21+M25 -> 118000 | N26: =N4+N10+N13+N17+N18+N21+N25 -> 161820 | O26: =O4+O10+O13+O17+O18+O21+O25 -> 15815 | P26: =P4+P10+P13+P17+P18+P21+P25 -> 28005 | Q26: =Q4+Q10+Q13+Q17+Q18+Q21+Q25 -> 118000 | R26: =sum(R3+R13+R17+R18+R21+R25) -> 141427 | S26: =S3+S13+S17+S18+S21+S25 -> 7477 | T26: =T3+T13+T17+T18+T21+T25 -> 15850 | U26: =sum(U3+U13+U17+U18+U21+U25) -> 118000 | V26: =V3+V13+V17+V18+V21+V25 -> 160569 | W26: =W3+W13+W17+W18+W21+W25 -> 12270 | X26: =X3+X13+X17+X18+X21+X25 -> 30299 | Y26: =Y3+Y13+Y17+Y18+Y21+Y25 -> 118000
A27: GST | B27: =B26-(B26/1.18) -> 34552.525 | C27: =C26-(C26/1.18) -> 8223.4068 | D27: =D26-(D26/1.18) -> 7793.2373 | E27: =E26-(E26/1.18) -> 18000 | F27: =F26-(F26/1.18) -> 38582.085 | G27: =G26-(G26/1.18) -> 13360.881 | J27: =J26-(J26/1.18) -> 33202.525 | N27: =N26-(N26/1.18) -> 24684.407 | R27: =R26-(R26/1.18) -> 21573.61 | V27: =V26-(V26/1.18) -> 24493.576
A28: Net Revenue Post GST | B28: =B26-B27 -> 191958.47 | C28: =C26-C27 -> 45685.593 | D28: =D26-D27 -> 43295.763 | E28: =E26-E27 -> 100000 | F28: =F26-F27 -> 214344.92 | G28: =G26-G27 -> 74227.119 | J28: =J26-J27 -> 184458.47 | N28: =N26-N27 -> 137135.59 | R28: =R26-R27 -> 119853.39 | V28: =V26-V27 -> 136075.42

Sheet RallyGully | Commons
B1: Link | F1: Link | J1: Link | N1: Link | R1: Link | V1: Link
A2: Venues | B2: April | C2: Pickleball | D2: Turf | E2: Padel | F2: May | G2: Pickleball | H2: Turf | I2: Padel | J2: June | K2: Pickleball | L2: Turf | M2: Padel | N2: July | O2: Pickleball | P2: Turf | Q2: Padel | R2: August | S2: Pickleball | T2: Turf | U2: Padel | V2: Sept | W2: Pickleball | X2: Turf | Y2: Padel
A3: Pay & Play | B3: =sum(B4,B10) -> 313618 | C3: =sum(C4,C10) -> 31257 | D3: =sum(D4,D10) -> 163556 | E3: =sum(E4,E10) -> 84413 | F3: =sum(F4,F10) -> 363668 | G3: =sum(G4,G10) -> 91770 | H3: =sum(H4,H10) -> 206991 | I3: =sum(I4,I10) -> 64907 | ... Y3: =sum(Y4,Y10) -> 96132
A4: Online | B4: =sum(B5:B9) -> 144764 | C4: =sum(C5:C9) -> 23611 | D4: =sum(D5:D9) -> 99368 | E4: =sum(E5:E9) -> 21785 | F4: =sum(F5:F9) -> 175870 | G4: =sum(G5:G9) -> 63403 | H4: =sum(H5:H9) -> 69443 | I4: =sum(I5:I9) -> 43024 | ... Y4: =sum(Y5:Y9) -> 31077
