Workbook

Sheet Central Dashboard
L1: Link
A2: Sno. | B2: Venues | C2: July | D2: August | E2: September | F2: October | G2: November | H2: December | I2: January | J2: February | K2: March | L2: April (26-27)
A3: 1 | B3: RallyGully I Sector 10 Dwarka | C3: ='RallyGully I Sector 10 Dwarka'!C24 -> 103615 | D3: ='RallyGully I Sector 10 Dwarka'!D24 -> 298839 | E3: ='RallyGully I Sector 10 Dwarka'!E24 -> 245054 | F3: ='RallyGully I Sector 10 Dwarka'!F24 -> 200720 | G3: ='RallyGully I Sector 10 Dwarka'!G24 -> 168129 | H3: ='RallyGully I Sector 10 Dwarka'!H24 -> 206326 | I3: ='RallyGully I Sector 10 Dwarka'!I24 -> 301217 | J3: ='RallyGully I Sector 10 Dwarka'!J24 -> 263730 | K3: ='RallyGully I Sector 10 Dwarka'!K24 -> 251120
A4: 2 | B4: RallyGully I Sector 83 Gurgaon | C4: 0 | D4: ='RallyGully I Sector 83 Gurgaon'!D24 -> 37420 | E4: ='RallyGully I Sector 83 Gurgaon'!E24 -> 154961 | F4: 90075 | G4: ='RallyGully I Sector 83 Gurgaon'!G24 -> 151276 | H4: ='RallyGully I Sector 83 Gurgaon'!H24 -> 175700 | I4: ='RallyGully I Sector 83 Gurgaon'!I24 -> 169521 | J4: ='RallyGully I Sector 83 Gurgaon'!J24 -> 210880 | K4: ='RallyGully I Sector 83 Gurgaon'!K24 -> 226770
A5: 3 | B5: RallyGully I East of Kailash | C5: 0 | D5: 0 | E5: ='RallyGully I East of Kailash'!E24 -> 78858.8 | F5: ='RallyGully I East of Kailash'!F24 -> 183432.6 | G5: ='RallyGully I East of Kailash'!G24 -> 144284 | H5: ='RallyGully I East of Kailash'!H24 -> 123338 | I5: ='RallyGully I East of Kailash'!I24 -> 279567 | J5: ='RallyGully I East of Kailash'!J24 -> 365154 | K5: ='RallyGully I East of Kailash'!K24 -> 281064
A6: 4 | B6: RallyGully I Sector 19 Dwarka Drive Kick | C6: 0 | D6: 0 | E6: 0 | F6: ='RallyGully I Sector 19 Dwarka'!F24 -> 71245 | G6: ='RallyGully I Sector 19 Dwarka'!$G$24 -> 78029 | H6: ='RallyGully I Sector 19 Dwarka'!H24 -> 50925 | I6: ='RallyGully I Sector 19 Dwarka'!I24 -> 125214 | J6: ='RallyGully I Sector 19 Dwarka'!J24 -> 86460 | K6: ='RallyGully I Sector 19 Dwarka'!K24 -> 104875
A7: 5 | B7: RallyGully | DPSG | C7: 0 | D7: 0 | E7: 0 | F7: 0 | G7: 0 | H7: ='RallyGully | DPSG'!H24 -> 21637 | I7: ='RallyGully | DPSG'!I24 -> 49820 | J7: ='RallyGully | DPSG'!J24 -> 113460 | K7: ='RallyGully | DPSG'!K24 -> 179380
A8: 6 | B8: RallyGully I Panchsheel | C8: 0 | D8: 0 | E8: 0 | F8: 0 | G8: 0 | H8: 0 | I8: ='RallyGully | Panchsheel'!I24 -> 78588 | J8: ='RallyGully | Panchsheel'!J24 -> 88970 | K8: ='RallyGully | Panchsheel'!K24 -> 141013
A9: 7 | B9: RallyGully | LCR Pune | C9: 0 | D9: 0 | E9: 0 | F9: 0 | G9: ='RallyGully | LCR Pune'!G24 -> 40125 | H9: ='RallyGully | LCR Pune'!H24 -> 171603 | I9: ='RallyGully | LCR Pune'!I24 -> 399500 | J9: ='RallyGully | LCR Pune'!J24 -> 450865 | K9: ='RallyGully | LCR Pune'!K24 -> 415235
A10: 8 | B10: RallyGully I Gandhipath | C10: 0 | D10: 0 | E10: 0 | F10: 0 | G10: 0 | H10: ='RallyGully | Gandipath'!H24 -> 4900 | I10: ='RallyGully | Gandipath'!I24 -> 98125 | J10: ='RallyGully | Gandipath'!J24 -> 74878 | K10: ='RallyGully | Gandipath'!K24 -> 139155
A11: 9 | B11: Powerplay Park | C11: 0 | D11: 0 | E11: 0 | F11: 0 | G11: 0 | H11: 0 | I11: 0 | J11: ='Powerplay Park, Pune'!J24 -> 59161 | K11: ='Powerplay Park, Pune'!K24 -> 186760
A12: 10 | B12: Commons | RallyGully x Delhi Padel Collective | C12: 0 | D12: 0 | E12: 0 | F12: 0 | G12: 0 | H12: 0 | I12: 0 | J12: 0 | K12: ='Commons, Noida'!K24 -> 136660
B13: Total Gross Revenue | C13: =SUM(C3:C10) -> 103615 | D13: =SUM(D3:D10) -> 336259 | E13: =SUM(E3:E10) -> 478873.8 | F13: =SUM(F3:F10) -> 545472.6 | G13: =SUM(G3:G10) -> 581843 | H13: =SUM(H3:H12) -> 754429 | I13: =SUM(I3:I12) -> 1501552 | J13: =SUM(J3:J12) -> 1713558 | K13: =SUM(K3:K12) -> 2062032
B14: Net Revenue (Post Commissions) | E14: ='RallyGully I Sector 10 Dwarka'!E25+'RallyGully I Sector 83 Gurgaon'!E25+'RallyGully I East of Kailash'!E25+'RallyGully I Sector 19 Dwarka'!E25+'RallyGully | LCR Pune'!E25+'RallyGully | DPSG'!E25+'RallyGully | Gandipath'!E25+'RallyGully | Panchsheel'!E25+'Powerplay Park, Pune'!E25+'Commons, Noida'!E25 -> 383752.5 | F14: ='RallyGully I Sector 10 Dwarka'!F25+'RallyGully I Sector 83 Gurgaon'!F25+'RallyGully I East of Kailash'!F25+'RallyGully I Sector 19 Dwarka'!F25+'RallyGully | LCR Pune'!F25+'RallyGully | DPSG'!F25+'RallyGully | Gandipath'!F25+'RallyGully | Panchsheel'!F25+'Powerplay Park, Pune'!F25+'Commons, Noida'!F25 -> 472432 | G14: ='RallyGully I Sector 10 Dwarka'!G25+'RallyGully I Sector 83 Gurgaon'!G25+'RallyGully I East of Kailash'!G25+'RallyGully I Sector 19 Dwarka'!G25+'RallyGully | LCR Pune'!G25+'RallyGully | DPSG'!G25+'RallyGully | Gandipath'!G25+'RallyGully | Panchsheel'!G25+'Powerplay Park, Pune'!G25+'Commons, Noida'!G25 -> 550598.68 | H14: ='RallyGully I Sector 10 Dwarka'!H25+'RallyGully I Sector 83 Gurgaon'!H25+'RallyGully I East of Kailash'!H25+'RallyGully I Sector 19 Dwarka'!H25+'RallyGully | LCR Pune'!H25+'RallyGully | DPSG'!H25+'RallyGully | Gandipath'!H25+'RallyGully | Panchsheel'!H25+'Powerplay Park, Pune'!H25+'Commons, Noida'!H25 -> 724015.27 | I14: ='RallyGully I Sector 10 Dwarka'!I25+'RallyGully I Sector 83 Gurgaon'!I25+'RallyGully I East of Kailash'!I25+'RallyGully I Sector 19 Dwarka'!I25+'RallyGully | LCR Pune'!I25+'RallyGully | DPSG'!I25+'RallyGully | Gandipath'!I25+'RallyGully | Panchsheel'!I25+'Powerplay Park, Pune'!I25+'Commons, Noida'!I25 -> 1447146.4 | J14: ='RallyGully I Sector 10 Dwarka'!J25+'RallyGully I Sector 83 Gurgaon'!J25+'RallyGully I East of Kailash'!J25+'RallyGully I Sector 19 Dwarka'!J25+'RallyGully | LCR Pune'!J25+'RallyGully | DPSG'!J25+'RallyGully | Gandipath'!J25+'RallyGully | Panchsheel'!J25+'Powerplay Park, Pune'!J25+'Commons, Noida'!J25 -> 1640747 | K14: ='RallyGully I Sector 10 Dwarka'!K25+'RallyGully I Sector 83 Gurgaon'!K25+'RallyGully I East of Kailash'!K25+'RallyGully I Sector 19 Dwarka'!K25+'RallyGully | LCR Pune'!K25+'RallyGully | DPSG'!K25+'RallyGully | Gandipath'!K25+'RallyGully | Panchsheel'!K25+'Powerplay Park, Pune'!K25+'Commons, Noida'!K25 -> 1942531.6
B17: Verticle Vise | C17: July | D17: August | E17: September | F17: October | G17: November | H17: December | I17: January | J17: February | K17: March
A19: 1 | B19: Offline | C19: =SUM('RallyGully I Sector 10 Dwarka'!C3+'RallyGully I Sector 83 Gurgaon'!C3+'RallyGully I East of Kailash'!C3+'RallyGully I Sector 19 Dwarka'!C3+'RallyGully | LCR Pune'!C3+'RallyGully | DPSG'!C3+'RallyGully | Gandipath'!C3+'RallyGully | Panchsheel'!C3) -> 4835 | D19: =SUM('RallyGully I Sector 10 Dwarka'!D3+'RallyGully I Sector 83 Gurgaon'!D3+'RallyGully I East of Kailash'!D3+'RallyGully I Sector 19 Dwarka'!D3+'RallyGully | LCR Pune'!D3+'RallyGully | DPSG'!D3+'RallyGully | Gandipath'!D3+'RallyGully | Panchsheel'!D3) -> 51040 | E19: =SUM('RallyGully I Sector 10 Dwarka'!E3+'RallyGully I Sector 83 Gurgaon'!E3+'RallyGully I East of Kailash'!E3+'RallyGully I Sector 19 Dwarka'!E3+'RallyGully | LCR Pune'!E3+'RallyGully | DPSG'!E3+'RallyGully | Gandipath'!E3+'RallyGully | Panchsheel'!E3) -> 139520 | F19: =SUM('RallyGully I Sector 10 Dwarka'!F3+'RallyGully I Sector 83 Gurgaon'!F3+'RallyGully I East of Kailash'!F3+'RallyGully I Sector 19 Dwarka'!F3+'RallyGully | LCR Pune'!F3+'RallyGully | DPSG'!F3+'RallyGully | Gandipath'!F3+'RallyGully | Panchsheel'!F3) -> 73240 | G19: =SUM('RallyGully I Sector 10 Dwarka'!G3+'RallyGully I Sector 83 Gurgaon'!G3+'RallyGully I East of Kailash'!G3+'RallyGully I Sector 19 Dwarka'!G3+'RallyGully | LCR Pune'!G3+'RallyGully | DPSG'!G3+'RallyGully | Gandipath'!G3+'RallyGully | Panchsheel'!G3) -> 175494 | H19: =SUM('RallyGully I Sector 10 Dwarka'!H3+'RallyGully I Sector 83 Gurgaon'!H3+'RallyGully I East of Kailash'!H3+'RallyGully I Sector 19 Dwarka'!H3+'RallyGully | LCR Pune'!H3+'RallyGully | DPSG'!H3+'RallyGully | Gandipath'!H3+'RallyGully | Panchsheel'!H3) -> 269512 | I19: =SUM('RallyGully I Sector 10 Dwarka'!I3+'RallyGully I Sector 83 Gurgaon'!I3+'RallyGully I East of Kailash'!I3+'RallyGully I Sector 19 Dwarka'!I3+'RallyGully | LCR Pune'!I3+'RallyGully | DPSG'!I3+'RallyGully | Gandipath'!I3+'RallyGully | Panchsheel'!I3) -> 481369 | J19: =SUM('RallyGully I Sector 10 Dwarka'!J3+'RallyGully I Sector 83 Gurgaon'!J3+'RallyGully I East of Kailash'!J3+'RallyGully I Sector 19 Dwarka'!J3+'RallyGully | LCR Pune'!J3+'RallyGully | DPSG'!J3+'RallyGully | Gandipath'!J3+'RallyGully | Panchsheel'!J3+'Powerplay Park, Pune'!J3+'Commons, Noida'!J3) -> 515675 | K19: =SUM('RallyGully I Sector 10 Dwarka'!K3+'RallyGully I Sector 83 Gurgaon'!K3+'RallyGully I East of Kailash'!K3+'RallyGully I Sector 19 Dwarka'!K3+'RallyGully | LCR Pune'!K3+'RallyGully | DPSG'!K3+'RallyGully | Gandipath'!K3+'RallyGully | Panchsheel'!K3+'Powerplay Park, Pune'!K3+'Commons, Noida'!K3) -> 528815
A20: 1.1 | B20: Rentals | C20: =SUM('RallyGully I Sector 10 Dwarka'!C4+'RallyGully I Sector 83 Gurgaon'!C4+'RallyGully I East of Kailash'!C4+'RallyGully I Sector 19 Dwarka'!C4+'RallyGully | LCR Pune'!C4+'RallyGully | DPSG'!C4+'RallyGully | Gandipath'!C4+'RallyGully | Panchsheel'!C4) -> 4475 | D20: =SUM('RallyGully I Sector 10 Dwarka'!D4+'RallyGully I Sector 83 Gurgaon'!D4+'RallyGully I East of Kailash'!D4+'RallyGully I Sector 19 Dwarka'!D4+'RallyGully | LCR Pune'!D4+'RallyGully | DPSG'!D4+'RallyGully | Gandipath'!D4+'RallyGully | Panchsheel'!D4) -> 15580 | E20: =SUM('RallyGully I Sector 10 Dwarka'!E4+'RallyGully I Sector 83 Gurgaon'!E4+'RallyGully I East of Kailash'!E4+'RallyGully I Sector 19 Dwarka'!E4+'RallyGully | LCR Pune'!E4+'RallyGully | DPSG'!E4+'RallyGully | Gandipath'!E4+'RallyGully | Panchsheel'!E4) -> 22280 | F20: =SUM('RallyGully I Sector 10 Dwarka'!F4+'RallyGully I Sector 83 Gurgaon'!F4+'RallyGully I East of Kailash'!F4+'RallyGully I Sector 19 Dwarka'!F4+'RallyGully | LCR Pune'!F4+'RallyGully | DPSG'!F4+'RallyGully | Gandipath'!F4+'RallyGully | Panchsheel'!F4) -> 24840 | G20: =SUM('RallyGully I Sector 10 Dwarka'!G4+'RallyGully I Sector 83 Gurgaon'!G4+'RallyGully I East of Kailash'!G4+'RallyGully I Sector 19 Dwarka'!G4+'RallyGully | LCR Pune'!G4+'RallyGully | DPSG'!G4+'RallyGully | Gandipath'!G4+'RallyGully | Panchsheel'!G4) -> 27820 | H20: =SUM('RallyGully I Sector 10 Dwarka'!H4+'RallyGully I Sector 83 Gurgaon'!H4+'RallyGully I East of Kailash'!H4+'RallyGully I Sector 19 Dwarka'!H4+'RallyGully | LCR Pune'!H4+'RallyGully | DPSG'!H4+'RallyGully | Gandipath'!H4+'RallyGully | Panchsheel'!H4) -> 60775 | I20: =SUM('RallyGully I Sector 10 Dwarka'!I4+'RallyGully I Sector 83 Gurgaon'!I4+'RallyGully I East of Kailash'!I4+'RallyGully I Sector 19 Dwarka'!I4+'RallyGully | LCR Pune'!I4+'RallyGully | DPSG'!I4+'RallyGully | Gandipath'!I4+'RallyGully | Panchsheel'!I4) -> 91339 | J20: =SUM('RallyGully I Sector 10 Dwarka'!J4+'RallyGully I Sector 83 Gurgaon'!J4+'RallyGully I East of Kailash'!J4+'RallyGully I Sector 19 Dwarka'!J4+'RallyGully | LCR Pune'!J4+'RallyGully | DPSG'!J4+'RallyGully | Gandipath'!J4+'RallyGully | Panchsheel'!J4) -> 94325 | K20: =SUM('RallyGully I Sector 10 Dwarka'!K4+'RallyGully I Sector 83 Gurgaon'!K4+'RallyGully I East of Kailash'!K4+'RallyGully I Sector 19 Dwarka'!K4+'RallyGully | LCR Pune'!K4+'RallyGully | DPSG'!K4+'RallyGully | Gandipath'!K4+'RallyGully | Panchsheel'!K4+'Powerplay Park, Pune'!K4+'Commons, Noida'!K4) -> 82830
A21: 1.2 | B21: F&B | C21: =SUM('RallyGully I Sector 10 Dwarka'!C5+'RallyGully I Sector 83 Gurgaon'!C5+'RallyGully I East of Kailash'!C5+'RallyGully I Sector 19 Dwarka'!C5+'RallyGully | LCR Pune'!C5+'RallyGully | DPSG'!C5+'RallyGully | Gandipath'!C5+'RallyGully | Panchsheel'!C5) -> 360 | D21: =SUM('RallyGully I Sector 10 Dwarka'!D5+'RallyGully I Sector 83 Gurgaon'!D5+'RallyGully I East of Kailash'!D5+'RallyGully I Sector 19 Dwarka'!D5+'RallyGully | LCR Pune'!D5+'RallyGully | DPSG'!D5+'RallyGully | Gandipath'!D5+'RallyGully | Panchsheel'!D5) -> 1920 | E21: =SUM('RallyGully I Sector 10 Dwarka'!E5+'RallyGully I Sector 83 Gurgaon'!E5+'RallyGully I East of Kailash'!E5+'RallyGully I Sector 19 Dwarka'!E5+'RallyGully | LCR Pune'!E5+'RallyGully | DPSG'!E5+'RallyGully | Gandipath'!E5+'RallyGully | Panchsheel'!E5) -> 4400 | F21: =SUM('RallyGully I Sector 10 Dwarka'!F5+'RallyGully I Sector 83 Gurgaon'!F5+'RallyGully I East of Kailash'!F5+'RallyGully I Sector 19 Dwarka'!F5+'RallyGully | LCR Pune'!F5+'RallyGully | DPSG'!F5+'RallyGully | Gandipath'!F5+'RallyGully | Panchsheel'!F5) -> 2490 | G21: =SUM('RallyGully I Sector 10 Dwarka'!G5+'RallyGully I Sector 83 Gurgaon'!G5+'RallyGully I East of Kailash'!G5+'RallyGully I Sector 19 Dwarka'!G5+'RallyGully | LCR Pune'!G5+'RallyGully | DPSG'!G5+'RallyGully | Gandipath'!G5+'RallyGully | Panchsheel'!G5) -> 1890 | H21: =SUM('RallyGully I Sector 10 Dwarka'!H5+'RallyGully I Sector 83 Gurgaon'!H5+'RallyGully I East of Kailash'!H5+'RallyGully I Sector 19 Dwarka'!H5+'RallyGully | LCR Pune'!H5+'RallyGully | DPSG'!H5+'RallyGully | Gandipath'!H5+'RallyGully | Panchsheel'!H5) -> 5260 | I21: =SUM('RallyGully I Sector 10 Dwarka'!I5+'RallyGully I Sector 83 Gurgaon'!I5+'RallyGully I East of Kailash'!I5+'RallyGully I Sector 19 Dwarka'!I5+'RallyGully | LCR Pune'!I5+'RallyGully | DPSG'!I5+'RallyGully | Gandipath'!I5+'RallyGully | Panchsheel'!I5) -> 4055 | J21: =SUM('RallyGully I Sector 10 Dwarka'!J5+'RallyGully I Sector 83 Gurgaon'!J5+'RallyGully I East of Kailash'!J5+'RallyGully I Sector 19 Dwarka'!J5+'RallyGully | LCR Pune'!J5+'RallyGully | DPSG'!J5+'RallyGully | Gandipath'!J5+'RallyGully | Panchsheel'!J5) -> 5445 | K21: =SUM('RallyGully I Sector 10 Dwarka'!K5+'RallyGully I Sector 83 Gurgaon'!K5+'RallyGully I East of Kailash'!K5+'RallyGully I Sector 19 Dwarka'!K5+'RallyGully | LCR Pune'!K5+'RallyGully | DPSG'!K5+'RallyGully | Gandipath'!K5+'RallyGully | Panchsheel'!K5+'Powerplay Park, Pune'!K5+'Commons, Noida'!K5) -> 3825
A22: 1.3 | B22: Product Sales | C22: =SUM('RallyGully I Sector 10 Dwarka'!C6+'RallyGully I Sector 83 Gurgaon'!C6+'RallyGully I East of Kailash'!C6+'RallyGully I Sector 19 Dwarka'!C6+'RallyGully | LCR Pune'!C6+'RallyGully | DPSG'!C6+'RallyGully | Gandipath'!C6+'RallyGully | Panchsheel'!C6) -> 0 | D22: =SUM('RallyGully I Sector 10 Dwarka'!D6+'RallyGully I Sector 83 Gurgaon'!D6+'RallyGully I East of Kailash'!D6+'RallyGully I Sector 19 Dwarka'!D6+'RallyGully | LCR Pune'!D6+'RallyGully | DPSG'!D6+'RallyGully | Gandipath'!D6+'RallyGully | Panchsheel'!D6) -> 0 | E22: =SUM('RallyGully I Sector 10 Dwarka'!E6+'RallyGully I Sector 83 Gurgaon'!E6+'RallyGully I East of Kailash'!E6+'RallyGully I Sector 19 Dwarka'!E6+'RallyGully | LCR Pune'!E6+'RallyGully | DPSG'!E6+'RallyGully | Gandipath'!E6+'RallyGully | Panchsheel'!E6) -> 12050 | F22: =SUM('RallyGully I Sector 10 Dwarka'!F6+'RallyGully I Sector 83 Gurgaon'!F6+'RallyGully I East of Kailash'!F6+'RallyGully I Sector 19 Dwarka'!F6+'RallyGully | LCR Pune'!F6+'RallyGully | DPSG'!F6+'RallyGully | Gandipath'!F6+'RallyGully | Panchsheel'!F6) -> 0 | G22: =SUM('RallyGully I Sector 10 Dwarka'!G6+'RallyGully I Sector 83 Gurgaon'!G6+'RallyGully I East of Kailash'!G6+'RallyGully I Sector 19 Dwarka'!G6+'RallyGully | LCR Pune'!G6+'RallyGully | DPSG'!G6+'RallyGully | Gandipath'!G6+'RallyGully | Panchsheel'!G6) -> 0 | H22: =SUM('RallyGully I Sector 10 Dwarka'!H6+'RallyGully I Sector 83 Gurgaon'!H6+'RallyGully I East of Kailash'!H6+'RallyGully I Sector 19 Dwarka'!H6+'RallyGully | LCR Pune'!H6+'RallyGully | DPSG'!H6+'RallyGully | Gandipath'!H6+'RallyGully | Panchsheel'!H6) -> 0 | I22: =SUM('RallyGully I Sector 10 Dwarka'!I6+'RallyGully I Sector 83 Gurgaon'!I6+'RallyGully I East of Kailash'!I6+'RallyGully I Sector 19 Dwarka'!I6+'RallyGully | LCR Pune'!I6+'RallyGully | DPSG'!I6+'RallyGully | Gandipath'!I6+'RallyGully | Panchsheel'!I6) -> 18000 | J22: =SUM('RallyGully I Sector 10 Dwarka'!J6+'RallyGully I Sector 83 Gurgaon'!J6+'RallyGully I East of Kailash'!J6+'RallyGully I Sector 19 Dwarka'!J6+'RallyGully | LCR Pune'!J6+'RallyGully | DPSG'!J6+'RallyGully | Gandipath'!J6+'RallyGully | Panchsheel'!J6) -> 0 | K22: =SUM('RallyGully I Sector 10 Dwarka'!K6+'RallyGully I Sector 83 Gurgaon'!K6+'RallyGully I East of Kailash'!K6+'RallyGully I Sector 19 Dwarka'!K6+'RallyGully | LCR Pune'!K6+'RallyGully | DPSG'!K6+'RallyGully | Gandipath'!K6+'RallyGully | Panchsheel'!K6+'Powerplay Park, Pune'!K6+'Commons, Noida'!K6) -> 0
A23: 1.4 | B23: Bookings | C23: =SUM('RallyGully I Sector 10 Dwarka'!C7+'RallyGully I Sector 83 Gurgaon'!C7+'RallyGully I East of Kailash'!C7+'RallyGully I Sector 19 Dwarka'!C7+'RallyGully | LCR Pune'!C7+'RallyGully | DPSG'!C7+'RallyGully | Gandipath'!C7+'RallyGully | Panchsheel'!C7) -> 0 | D23: =SUM('RallyGully I Sector 10 Dwarka'!D7+'RallyGully I Sector 83 Gurgaon'!D7+'RallyGully I East of Kailash'!D7+'RallyGully I Sector 19 Dwarka'!D7+'RallyGully | LCR Pune'!D7+'RallyGully | DPSG'!D7+'RallyGully | Gandipath'!D7+'RallyGully | Panchsheel'!D7) -> 33540 | E23: =SUM('RallyGully I Sector 10 Dwarka'!E7+'RallyGully I Sector 83 Gurgaon'!E7+'RallyGully I East of Kailash'!E7+'RallyGully I Sector 19 Dwarka'!E7+'RallyGully | LCR Pune'!E7+'RallyGully | DPSG'!E7+'RallyGully | Gandipath'!E7+'RallyGully | Panchsheel'!E7) -> 100790 | F23: =SUM('RallyGully I Sector 10 Dwarka'!F7+'RallyGully I Sector 83 Gurgaon'!F7+'RallyGully I East of Kailash'!F7+'RallyGully I Sector 19 Dwarka'!F7+'RallyGully | LCR Pune'!F7+'RallyGully | DPSG'!F7+'RallyGully | Gandipath'!F7+'RallyGully | Panchsheel'!F7) -> 40710 | G23: =SUM('RallyGully I Sector 10 Dwarka'!G7+'RallyGully I Sector 83 Gurgaon'!G7+'RallyGully I East of Kailash'!G7+'RallyGully I Sector 19 Dwarka'!G7+'RallyGully | LCR Pune'!G7+'RallyGully | DPSG'!G7+'RallyGully | Gandipath'!G7+'RallyGully | Panchsheel'!G7) -> 145784 | H23: =SUM('RallyGully I Sector 10 Dwarka'!H7+'RallyGully I Sector 83 Gurgaon'!H7+'RallyGully I East of Kailash'!H7+'RallyGully I Sector 19 Dwarka'!H7+'RallyGully | LCR Pune'!H7+'RallyGully | DPSG'!H7+'RallyGully | Gandipath'!H7+'RallyGully | Panchsheel'!H7) -> 203477 | I23: =SUM('RallyGully I Sector 10 Dwarka'!I7+'RallyGully I Sector 83 Gurgaon'!I7+'RallyGully I East of Kailash'!I7+'RallyGully I Sector 19 Dwarka'!I7+'RallyGully | LCR Pune'!I7+'RallyGully | DPSG'!I7+'RallyGully | Gandipath'!I7+'RallyGully | Panchsheel'!I7) -> 367975 | J23: =SUM('RallyGully I Sector 10 Dwarka'!J7+'RallyGully I Sector 83 Gurgaon'!J7+'RallyGully I East of Kailash'!J7+'RallyGully I Sector 19 Dwarka'!J7+'RallyGully | LCR Pune'!J7+'RallyGully | DPSG'!J7+'RallyGully | Gandipath'!J7+'RallyGully | Panchsheel'!J7) -> 415905 | K23: =SUM('RallyGully I Sector 10 Dwarka'!K7+'RallyGully I Sector 83 Gurgaon'!K7+'RallyGully I East of Kailash'!K7+'RallyGully I Sector 19 Dwarka'!K7+'RallyGully | LCR Pune'!K7+'RallyGully | DPSG'!K7+'RallyGully | Gandipath'!K7+'RallyGully | Panchsheel'!K7+'Powerplay Park, Pune'!K7+'Commons, Noida'!K7) -> 442160
A24: 2 | B24: Online: Third Party Platform | C24: =SUM('RallyGully I Sector 10 Dwarka'!C8+'RallyGully I Sector 83 Gurgaon'!C8+'RallyGully I East of Kailash'!C8+'RallyGully I Sector 19 Dwarka'!C8+'RallyGully | LCR Pune'!C8+'RallyGully | DPSG'!C8+'RallyGully | Gandipath'!C8+'RallyGully | Panchsheel'!C8) -> 88280 | D24: =SUM('RallyGully I Sector 10 Dwarka'!D8+'RallyGully I Sector 83 Gurgaon'!D8+'RallyGully I East of Kailash'!D8+'RallyGully I Sector 19 Dwarka'!D8+'RallyGully | LCR Pune'!D8+'RallyGully | DPSG'!D8+'RallyGully | Gandipath'!D8+'RallyGully | Panchsheel'!D8) -> 220132 | E24: =SUM('RallyGully I Sector 10 Dwarka'!E8+'RallyGully I Sector 83 Gurgaon'!E8+'RallyGully I East of Kailash'!E8+'RallyGully I Sector 19 Dwarka'!E8+'RallyGully | LCR Pune'!E8+'RallyGully | DPSG'!E8+'RallyGully | Gandipath'!E8+'RallyGully | Panchsheel'!E8) -> 282863.8 | F24: =SUM('RallyGully I Sector 10 Dwarka'!F8+'RallyGully I Sector 83 Gurgaon'!F8+'RallyGully I East of Kailash'!F8+'RallyGully I Sector 19 Dwarka'!F8+'RallyGully | LCR Pune'!F8+'RallyGully | DPSG'!F8+'RallyGully | Gandipath'!F8+'RallyGully | Panchsheel'!F8) -> 299312.6 | G24: =SUM('RallyGully I Sector 10 Dwarka'!G8+'RallyGully I Sector 83 Gurgaon'!G8+'RallyGully I East of Kailash'!G8+'RallyGully I Sector 19 Dwarka'!G8+'RallyGully | LCR Pune'!G8+'RallyGully | DPSG'!G8+'RallyGully | Gandipath'!G8+'RallyGully | Panchsheel'!G8) -> 262229 | H24: =SUM('RallyGully I Sector 10 Dwarka'!H8+'RallyGully I Sector 83 Gurgaon'!H8+'RallyGully I East of Kailash'!H8+'RallyGully I Sector 19 Dwarka'!H8+'RallyGully | LCR Pune'!H8+'RallyGully | DPSG'!H8+'RallyGully | Gandipath'!H8+'RallyGully | Panchsheel'!H8) -> 281135 | I24: =SUM('RallyGully I Sector 10 Dwarka'!I8+'RallyGully I Sector 83 Gurgaon'!I8+'RallyGully I East of Kailash'!I8+'RallyGully I Sector 19 Dwarka'!I8+'RallyGully | LCR Pune'!I8+'RallyGully | DPSG'!I8+'RallyGully | Gandipath'!I8+'RallyGully | Panchsheel'!I8) -> 520434 | J24: =SUM('RallyGully I Sector 10 Dwarka'!J8+'RallyGully I Sector 83 Gurgaon'!J8+'RallyGully I East of Kailash'!J8+'RallyGully I Sector 19 Dwarka'!J8+'RallyGully | LCR Pune'!J8+'RallyGully | DPSG'!J8+'RallyGully | Gandipath'!J8+'RallyGully | Panchsheel'!J8+'Powerplay Park, Pune'!J8+'Commons, Noida'!J8) -> 603109 | K24: =SUM('RallyGully I Sector 10 Dwarka'!K8+'RallyGully I Sector 83 Gurgaon'!K8+'RallyGully I East of Kailash'!K8+'RallyGully I Sector 19 Dwarka'!K8+'RallyGully | LCR Pune'!K8+'RallyGully | DPSG'!K8+'RallyGully | Gandipath'!K8+'RallyGully | Panchsheel'!K8+'Powerplay Park, Pune'!K8+'Commons, Noida'!K8) -> 861713
A25: 2.1 | B25: Hudle | C25: =SUM('RallyGully I Sector 10 Dwarka'!C9+'RallyGully I Sector 83 Gurgaon'!C9+'RallyGully I East of Kailash'!C9+'RallyGully I Sector 19 Dwarka'!C9+'RallyGully | LCR Pune'!C9+'RallyGully | DPSG'!C9+'RallyGully | Gandipath'!C9+'RallyGully | Panchsheel'!C9) -> 73440 | D25: =SUM('RallyGully I Sector 10 Dwarka'!D9+'RallyGully I Sector 83 Gurgaon'!D9+'RallyGully I East of Kailash'!D9+'RallyGully I Sector 19 Dwarka'!D9+'RallyGully | LCR Pune'!D9+'RallyGully | DPSG'!D9+'RallyGully | Gandipath'!D9+'RallyGully | Panchsheel'!D9) -> 162660 | E25: =SUM('RallyGully I Sector 10 Dwarka'!E9+'RallyGully I Sector 83 Gurgaon'!E9+'RallyGully I East of Kailash'!E9+'RallyGully I Sector 19 Dwarka'!E9+'RallyGully | LCR Pune'!E9+'RallyGully | DPSG'!E9+'RallyGully | Gandipath'!E9+'RallyGully | Panchsheel'!E9) -> 244051 | F25: =SUM('RallyGully I Sector 10 Dwarka'!F9+'RallyGully I Sector 83 Gurgaon'!F9+'RallyGully I East of Kailash'!F9+'RallyGully I Sector 19 Dwarka'!F9+'RallyGully | LCR Pune'!F9+'RallyGully | DPSG'!F9+'RallyGully | Gandipath'!F9+'RallyGully | Panchsheel'!F9) -> 257545 | G25: =SUM('RallyGully I Sector 10 Dwarka'!G9+'RallyGully I Sector 83 Gurgaon'!G9+'RallyGully I East of Kailash'!G9+'RallyGully I Sector 19 Dwarka'!G9+'RallyGully | LCR Pune'!G9+'RallyGully | DPSG'!G9+'RallyGully | Gandipath'!G9+'RallyGully | Panchsheel'!G9) -> 201485 | H25: =SUM('RallyGully I Sector 10 Dwarka'!H9+'RallyGully I Sector 83 Gurgaon'!H9+'RallyGully I East of Kailash'!H9+'RallyGully I Sector 19 Dwarka'!H9+'RallyGully | LCR Pune'!H9+'RallyGully | DPSG'!H9+'RallyGully | Gandipath'!H9+'RallyGully | Panchsheel'!H9) -> 173633 | I25: =SUM('RallyGully I Sector 10 Dwarka'!I9+'RallyGully I Sector 83 Gurgaon'!I9+'RallyGully I East of Kailash'!I9+'RallyGully I Sector 19 Dwarka'!I9+'RallyGully | LCR Pune'!I9+'RallyGully | DPSG'!I9+'RallyGully | Gandipath'!I9+'RallyGully | Panchsheel'!I9) -> 263500 | J25: =SUM('RallyGully I Sector 10 Dwarka'!J9+'RallyGully I Sector 83 Gurgaon'!J9+'RallyGully I East of Kailash'!J9+'RallyGully I Sector 19 Dwarka'!J9+'RallyGully | LCR Pune'!J9+'RallyGully | DPSG'!J9+'RallyGully | Gandipath'!J9+'RallyGully | Panchsheel'!J9+'Powerplay Park, Pune'!J9+'Commons, Noida'!J9) -> 263802 | K25: =SUM('RallyGully I Sector 10 Dwarka'!K9+'RallyGully I Sector 83 Gurgaon'!K9+'RallyGully I East of Kailash'!K9+'RallyGully I Sector 19 Dwarka'!K9+'RallyGully | LCR Pune'!K9+'RallyGully | DPSG'!K9+'RallyGully | Gandipath'!K9+'RallyGully | Panchsheel'!K9+'Powerplay Park, Pune'!K9+'Commons, Noida'!K9) -> 377943
A26: 2.2 | B26: Playo | C26: =SUM('RallyGully I Sector 10 Dwarka'!C10+'RallyGully I Sector 83 Gurgaon'!C10+'RallyGully I East of Kailash'!C10+'RallyGully I Sector 19 Dwarka'!C10+'RallyGully | LCR Pune'!C10+'RallyGully | DPSG'!C10+'RallyGully | Gandipath'!C10+'RallyGully | Panchsheel'!C10) -> 14840 | D26: =SUM('RallyGully I Sector 10 Dwarka'!D10+'RallyGully I Sector 83 Gurgaon'!D10+'RallyGully I East of Kailash'!D10+'RallyGully I Sector 19 Dwarka'!D10+'RallyGully | LCR Pune'!D10+'RallyGully | DPSG'!D10+'RallyGully | Gandipath'!D10+'RallyGully | Panchsheel'!D10) -> 46790 | E26: =SUM('RallyGully I Sector 10 Dwarka'!E10+'RallyGully I Sector 83 Gurgaon'!E10+'RallyGully I East of Kailash'!E10+'RallyGully I Sector 19 Dwarka'!E10+'RallyGully | LCR Pune'!E10+'RallyGully | DPSG'!E10+'RallyGully | Gandipath'!E10+'RallyGully | Panchsheel'!E10) -> 32658.8 | F26: =SUM('RallyGully I Sector 10 Dwarka'!F10+'RallyGully I Sector 83 Gurgaon'!F10+'RallyGully I East of Kailash'!F10+'RallyGully I Sector 19 Dwarka'!F10+'RallyGully | LCR Pune'!F10+'RallyGully | DPSG'!F10+'RallyGully | Gandipath'!F10+'RallyGully | Panchsheel'!F10) -> 30067.6 | G26: =SUM('RallyGully I Sector 10 Dwarka'!G10+'RallyGully I Sector 83 Gurgaon'!G10+'RallyGully I East of Kailash'!G10+'RallyGully I Sector 19 Dwarka'!G10+'RallyGully | LCR Pune'!G10+'RallyGully | DPSG'!G10+'RallyGully | Gandipath'!G10+'RallyGully | Panchsheel'!G10) -> 27305 | H26: =SUM('RallyGully I Sector 10 Dwarka'!H10+'RallyGully I Sector 83 Gurgaon'!H10+'RallyGully I East of Kailash'!H10+'RallyGully I Sector 19 Dwarka'!H10+'RallyGully | LCR Pune'!H10+'RallyGully | DPSG'!H10+'RallyGully | Gandipath'!H10+'RallyGully | Panchsheel'!H10) -> 45577 | I26: =SUM('RallyGully I Sector 10 Dwarka'!I10+'RallyGully I Sector 83 Gurgaon'!I10+'RallyGully I East of Kailash'!I10+'RallyGully I Sector 19 Dwarka'!I10+'RallyGully | LCR Pune'!I10+'RallyGully | DPSG'!I10+'RallyGully | Gandipath'!I10+'RallyGully | Panchsheel'!I10) -> 93017 | J26: =SUM('RallyGully I Sector 10 Dwarka'!J10+'RallyGully I Sector 83 Gurgaon'!J10+'RallyGully I East of Kailash'!J10+'RallyGully I Sector 19 Dwarka'!J10+'RallyGully | LCR Pune'!J10+'RallyGully | DPSG'!J10+'RallyGully | Gandipath'!J10+'RallyGully | Panchsheel'!J10+'Powerplay Park, Pune'!J10+'Commons, Noida'!J10) -> 87503 | K26: =SUM('RallyGully I Sector 10 Dwarka'!K10+'RallyGully I Sector 83 Gurgaon'!K10+'RallyGully I East of Kailash'!K10+'RallyGully I Sector 19 Dwarka'!K10+'RallyGully | LCR Pune'!K10+'RallyGully | DPSG'!K10+'RallyGully | Gandipath'!K10+'RallyGully | Panchsheel'!K10+'Powerplay Park, Pune'!K10+'Commons, Noida'!K10) -> 123355
A27: 2.3 | B27: District | C27: =SUM('RallyGully I Sector 10 Dwarka'!C11+'RallyGully I Sector 83 Gurgaon'!C11+'RallyGully I East of Kailash'!C11+'RallyGully I Sector 19 Dwarka'!C11+'RallyGully | LCR Pune'!C11+'RallyGully | DPSG'!C11+'RallyGully | Gandipath'!C11+'RallyGully | Panchsheel'!C11) -> 0 | D27: =SUM('RallyGully I Sector 10 Dwarka'!D11+'RallyGully I Sector 83 Gurgaon'!D11+'RallyGully I East of Kailash'!D11+'RallyGully I Sector 19 Dwarka'!D11+'RallyGully | LCR Pune'!D11+'RallyGully | DPSG'!D11+'RallyGully | Gandipath'!D11+'RallyGully | Panchsheel'!D11) -> 0 | E27: =SUM('RallyGully I Sector 10 Dwarka'!E11+'RallyGully I Sector 83 Gurgaon'!E11+'RallyGully I East of Kailash'!E11+'RallyGully I Sector 19 Dwarka'!E11+'RallyGully | LCR Pune'!E11+'RallyGully | DPSG'!E11+'RallyGully | Gandipath'!E11+'RallyGully | Panchsheel'!E11) -> 0 | F27: =SUM('RallyGully I Sector 10 Dwarka'!F11+'RallyGully I Sector 83 Gurgaon'!F11+'RallyGully I East of Kailash'!F11+'RallyGully I Sector 19 Dwarka'!F11+'RallyGully | LCR Pune'!F11+'RallyGully | DPSG'!F11+'RallyGully | Gandipath'!F11+'RallyGully | Panchsheel'!F11) -> 1200 | G27: =SUM('RallyGully I Sector 10 Dwarka'!G11+'RallyGully I Sector 83 Gurgaon'!G11+'RallyGully I East of Kailash'!G11+'RallyGully I Sector 19 Dwarka'!G11+'RallyGully | LCR Pune'!G11+'RallyGully | DPSG'!G11+'RallyGully | Gandipath'!G11+'RallyGully | Panchsheel'!G11) -> 3106 | H27: =SUM('RallyGully I Sector 10 Dwarka'!H11+'RallyGully I Sector 83 Gurgaon'!H11+'RallyGully I East of Kailash'!H11+'RallyGully I Sector 19 Dwarka'!H11+'RallyGully | LCR Pune'!H11+'RallyGully | DPSG'!H11+'RallyGully | Gandipath'!H11+'RallyGully | Panchsheel'!H11) -> 18150 | I27: =SUM('RallyGully I Sector 10 Dwarka'!I11+'RallyGully I Sector 83 Gurgaon'!I11+'RallyGully I East of Kailash'!I11+'RallyGully I Sector 19 Dwarka'!I11+'RallyGully | LCR Pune'!I11+'RallyGully | DPSG'!I11+'RallyGully | Gandipath'!I11+'RallyGully | Panchsheel'!I11) -> 101150 | J27: =SUM('RallyGully I Sector 10 Dwarka'!J11+'RallyGully I Sector 83 Gurgaon'!J11+'RallyGully I East of Kailash'!J11+'RallyGully I Sector 19 Dwarka'!J11+'RallyGully | LCR Pune'!J11+'RallyGully | DPSG'!J11+'RallyGully | Gandipath'!J11+'RallyGully | Panchsheel'!J11+'Powerplay Park, Pune'!J11+'Commons, Noida'!J11) -> 163600 | K27: =SUM('RallyGully I Sector 10 Dwarka'!K11+'RallyGully I Sector 83 Gurgaon'!K11+'RallyGully I East of Kailash'!K11+'RallyGully I Sector 19 Dwarka'!K11+'RallyGully | LCR Pune'!K11+'RallyGully | DPSG'!K11+'RallyGully | Gandipath'!K11+'RallyGully | Panchsheel'!K11+'Powerplay Park, Pune'!K11+'Commons, Noida'!K11) -> 209600
A28: 2.4 | B28: Khelomore | C28: =SUM('RallyGully I Sector 10 Dwarka'!C12+'RallyGully I Sector 83 Gurgaon'!C12+'RallyGully I East of Kailash'!C12+'RallyGully I Sector 19 Dwarka'!C12+'RallyGully | LCR Pune'!C12+'RallyGully | DPSG'!C12+'RallyGully | Gandipath'!C12+'RallyGully | Panchsheel'!C12) -> 0 | D28: =SUM('RallyGully I Sector 10 Dwarka'!D12+'RallyGully I Sector 83 Gurgaon'!D12+'RallyGully I East of Kailash'!D12+'RallyGully I Sector 19 Dwarka'!D12+'RallyGully | LCR Pune'!D12+'RallyGully | DPSG'!D12+'RallyGully | Gandipath'!D12+'RallyGully | Panchsheel'!D12) -> 10682 | E28: =SUM('RallyGully I Sector 10 Dwarka'!E12+'RallyGully I Sector 83 Gurgaon'!E12+'RallyGully I East of Kailash'!E12+'RallyGully I Sector 19 Dwarka'!E12+'RallyGully | LCR Pune'!E12+'RallyGully | DPSG'!E12+'RallyGully | Gandipath'!E12+'RallyGully | Panchsheel'!E12) -> 6154 | F28: =SUM('RallyGully I Sector 10 Dwarka'!F12+'RallyGully I Sector 83 Gurgaon'!F12+'RallyGully I East of Kailash'!F12+'RallyGully I Sector 19 Dwarka'!F12+'RallyGully | LCR Pune'!F12+'RallyGully | DPSG'!F12+'RallyGully | Gandipath'!F12+'RallyGully | Panchsheel'!F12) -> 10500 | G28: =SUM('RallyGully I Sector 10 Dwarka'!G12+'RallyGully I Sector 83 Gurgaon'!G12+'RallyGully I East of Kailash'!G12+'RallyGully I Sector 19 Dwarka'!G12+'RallyGully | LCR Pune'!G12+'RallyGully | DPSG'!G12+'RallyGully | Gandipath'!G12+'RallyGully | Panchsheel'!G12) -> 30333 | H28: =SUM('RallyGully I Sector 10 Dwarka'!H12+'RallyGully I Sector 83 Gurgaon'!H12+'RallyGully I East of Kailash'!H12+'RallyGully I Sector 19 Dwarka'!H12+'RallyGully | LCR Pune'!H12+'RallyGully | DPSG'!H12+'RallyGully | Gandipath'!H12+'RallyGully | Panchsheel'!H12) -> 42525 | I28: =SUM('RallyGully I Sector 10 Dwarka'!I12+'RallyGully I Sector 83 Gurgaon'!I12+'RallyGully I East of Kailash'!I12+'RallyGully I Sector 19 Dwarka'!I12+'RallyGully | LCR Pune'!I12+'RallyGully | DPSG'!I12+'RallyGully | Gandipath'!I12+'RallyGully | Panchsheel'!I12) -> 37394 | J28: =SUM('RallyGully I Sector 10 Dwarka'!J12+'RallyGully I Sector 83 Gurgaon'!J12+'RallyGully I East of Kailash'!J12+'RallyGully I Sector 19 Dwarka'!J12+'RallyGully | LCR Pune'!J12+'RallyGully | DPSG'!J12+'RallyGully | Gandipath'!J12+'RallyGully | Panchsheel'!J12+'Powerplay Park, Pune'!J12+'Commons, Noida'!J12) -> 47546 | K28: =SUM('RallyGully I Sector 10 Dwarka'!K12+'RallyGully I Sector 83 Gurgaon'!K12+'RallyGully I East of Kailash'!K12+'RallyGully I Sector 19 Dwarka'!K12+'RallyGully | LCR Pune'!K12+'RallyGully | DPSG'!K12+'RallyGully | Gandipath'!K12+'RallyGully | Panchsheel'!K12+'Powerplay Park, Pune'!K12+'Commons, Noida'!K12) -> 55690
A29: 2.5 | B29: Zplys | C29: =SUM('RallyGully I Sector 10 Dwarka'!C13+'RallyGully I Sector 83 Gurgaon'!C13+'RallyGully I East of Kailash'!C13+'RallyGully I Sector 19 Dwarka'!C13+'RallyGully | LCR Pune'!C13+'RallyGully | DPSG'!C13+'RallyGully | Gandipath'!C13+'RallyGully | Panchsheel'!C13) -> 0 | D29: =SUM('RallyGully I Sector 10 Dwarka'!D13+'RallyGully I Sector 83 Gurgaon'!D13+'RallyGully I East of Kailash'!D13+'RallyGully I Sector 19 Dwarka'!D13+'RallyGully | LCR Pune'!D13+'RallyGully | DPSG'!D13+'RallyGully | Gandipath'!D13+'RallyGully | Panchsheel'!D13) -> 0 | E29: =SUM('RallyGully I Sector 10 Dwarka'!E13+'RallyGully I Sector 83 Gurgaon'!E13+'RallyGully I East of Kailash'!E13+'RallyGully I Sector 19 Dwarka'!E13+'RallyGully | LCR Pune'!E13+'RallyGully | DPSG'!E13+'RallyGully | Gandipath'!E13+'RallyGully | Panchsheel'!E13) -> 0 | F29: =SUM('RallyGully I Sector 10 Dwarka'!F13+'RallyGully I Sector 83 Gurgaon'!F13+'RallyGully I East of Kailash'!F13+'RallyGully I Sector 19 Dwarka'!F13+'RallyGully | LCR Pune'!F13+'RallyGully | DPSG'!F13+'RallyGully | Gandipath'!F13+'RallyGully | Panchsheel'!F13) -> 0 | G29: =SUM('RallyGully I Sector 10 Dwarka'!G13+'RallyGully I Sector 83 Gurgaon'!G13+'RallyGully I East of Kailash'!G13+'RallyGully I Sector 19 Dwarka'!G13+'RallyGully | LCR Pune'!G13+'RallyGully | DPSG'!G13+'RallyGully | Gandipath'!G13+'RallyGully | Panchsheel'!G13) -> 0 | H29: =SUM('RallyGully I Sector 10 Dwarka'!H13+'RallyGully I Sector 83 Gurgaon'!H13+'RallyGully I East of Kailash'!H13+'RallyGully I Sector 19 Dwarka'!H13+'RallyGully | LCR Pune'!H13+'RallyGully | DPSG'!H13+'RallyGully | Gandipath'!H13+'RallyGully | Panchsheel'!H13) -> 1250 | I29: =SUM('RallyGully I Sector 10 Dwarka'!I13+'RallyGully I Sector 83 Gurgaon'!I13+'RallyGully I East of Kailash'!I13+'RallyGully I Sector 19 Dwarka'!I13+'RallyGully | LCR Pune'!I13+'RallyGully | DPSG'!I13+'RallyGully | Gandipath'!I13+'RallyGully | Panchsheel'!I13) -> 25373 | J29: =SUM('RallyGully I Sector 10 Dwarka'!J13+'RallyGully I Sector 83 Gurgaon'!J13+'RallyGully I East of Kailash'!J13+'RallyGully I Sector 19 Dwarka'!J13+'RallyGully | LCR Pune'!J13+'RallyGully | DPSG'!J13+'RallyGully | Gandipath'!J13+'RallyGully | Panchsheel'!J13+'Powerplay Park, Pune'!J13+'Commons, Noida'!J13) -> 40658 | K29: =SUM('RallyGully I Sector 10 Dwarka'!K13+'RallyGully I Sector 83 Gurgaon'!K13+'RallyGully I East of Kailash'!K13+'RallyGully I Sector 19 Dwarka'!K13+'RallyGully | LCR Pune'!K13+'RallyGully | DPSG'!K13+'RallyGully | Gandipath'!K13+'RallyGully | Panchsheel'!K13+'Powerplay Park, Pune'!K13+'Commons, Noida'!K13) -> 95125
A30: 3 | B30: Community | C30: =SUM('RallyGully I Sector 10 Dwarka'!C14+'RallyGully I Sector 83 Gurgaon'!C14+'RallyGully I East of Kailash'!C14+'RallyGully I Sector 19 Dwarka'!C14+'RallyGully | LCR Pune'!C14+'RallyGully | DPSG'!C14+'RallyGully | Gandipath'!C14+'RallyGully | Panchsheel'!C14) -> 10500 | D30: =SUM('RallyGully I Sector 10 Dwarka'!D14+'RallyGully I Sector 83 Gurgaon'!D14+'RallyGully I East of Kailash'!D14+'RallyGully I Sector 19 Dwarka'!D14+'RallyGully | LCR Pune'!D14+'RallyGully | DPSG'!D14+'RallyGully | Gandipath'!D14+'RallyGully | Panchsheel'!D14) -> 15087 | E30: =SUM('RallyGully I Sector 10 Dwarka'!E14+'RallyGully I Sector 83 Gurgaon'!E14+'RallyGully I East of Kailash'!E14+'RallyGully I Sector 19 Dwarka'!E14+'RallyGully | LCR Pune'!E14+'RallyGully | DPSG'!E14+'RallyGully | Gandipath'!E14+'RallyGully | Panchsheel'!E14) -> 29490 | F30: =SUM('RallyGully I Sector 10 Dwarka'!F14+'RallyGully I Sector 83 Gurgaon'!F14+'RallyGully I East of Kailash'!F14+'RallyGully I Sector 19 Dwarka'!F14+'RallyGully | LCR Pune'!F14+'RallyGully | DPSG'!F14+'RallyGully | Gandipath'!F14+'RallyGully | Panchsheel'!F14) -> 40340 | G30: =SUM('RallyGully I Sector 10 Dwarka'!G14+'RallyGully I Sector 83 Gurgaon'!G14+'RallyGully I East of Kailash'!G14+'RallyGully I Sector 19 Dwarka'!G14+'RallyGully | LCR Pune'!G14+'RallyGully | DPSG'!G14+'RallyGully | Gandipath'!G14+'RallyGully | Panchsheel'!G14) -> 40260 | H30: =SUM('RallyGully I Sector 10 Dwarka'!H14+'RallyGully I Sector 83 Gurgaon'!H14+'RallyGully I East of Kailash'!H14+'RallyGully I Sector 19 Dwarka'!H14+'RallyGully | LCR Pune'!H14+'RallyGully | DPSG'!H14+'RallyGully | Gandipath'!H14+'RallyGully | Panchsheel'!H14) -> 31109 | I30: =SUM('RallyGully I Sector 10 Dwarka'!I14+'RallyGully I Sector 83 Gurgaon'!I14+'RallyGully I East of Kailash'!I14+'RallyGully I Sector 19 Dwarka'!I14+'RallyGully | LCR Pune'!I14+'RallyGully | DPSG'!I14+'RallyGully | Gandipath'!I14+'RallyGully | Panchsheel'!I14) -> 131439 | J30: =SUM('RallyGully I Sector 10 Dwarka'!J14+'RallyGully I Sector 83 Gurgaon'!J14+'RallyGully I East of Kailash'!J14+'RallyGully I Sector 19 Dwarka'!J14+'RallyGully | LCR Pune'!J14+'RallyGully | DPSG'!J14+'RallyGully | Gandipath'!J14+'RallyGully | Panchsheel'!J14+'Powerplay Park, Pune'!J14+'Commons, Noida'!J14) -> 176514 | K30: =SUM('RallyGully I Sector 10 Dwarka'!K14+'RallyGully I Sector 83 Gurgaon'!K14+'RallyGully I East of Kailash'!K14+'RallyGully I Sector 19 Dwarka'!K14+'RallyGully | LCR Pune'!K14+'RallyGully | DPSG'!K14+'RallyGully | Gandipath'!K14+'RallyGully | Panchsheel'!K14+'Powerplay Park, Pune'!K14+'Commons, Noida'!K14) -> 256304
A31: 3.1 | B31: Courtly (Organized by RallyGully) | C31: =SUM('RallyGully I Sector 10 Dwarka'!C15+'RallyGully I Sector 83 Gurgaon'!C15+'RallyGully I East of Kailash'!C15+'RallyGully I Sector 19 Dwarka'!C15+'RallyGully | LCR Pune'!C15+'RallyGully | DPSG'!C15+'RallyGully | Gandipath'!C15+'RallyGully | Panchsheel'!C15) -> 0 | D31: =SUM('RallyGully I Sector 10 Dwarka'!D15+'RallyGully I Sector 83 Gurgaon'!D15+'RallyGully I East of Kailash'!D15+'RallyGully I Sector 19 Dwarka'!D15+'RallyGully | LCR Pune'!D15+'RallyGully | DPSG'!D15+'RallyGully | Gandipath'!D15+'RallyGully | Panchsheel'!D15) -> 0 | E31: =SUM('RallyGully I Sector 10 Dwarka'!E15+'RallyGully I Sector 83 Gurgaon'!E15+'RallyGully I East of Kailash'!E15+'RallyGully I Sector 19 Dwarka'!E15+'RallyGully | LCR Pune'!E15+'RallyGully | DPSG'!E15+'RallyGully | Gandipath'!E15+'RallyGully | Panchsheel'!E15) -> 0 | F31: =SUM('RallyGully I Sector 10 Dwarka'!F15+'RallyGully I Sector 83 Gurgaon'!F15+'RallyGully I East of Kailash'!F15+'RallyGully I Sector 19 Dwarka'!F15+'RallyGully | LCR Pune'!F15+'RallyGully | DPSG'!F15+'RallyGully | Gandipath'!F15+'RallyGully | Panchsheel'!F15) -> 0 | G31: =SUM('RallyGully I Sector 10 Dwarka'!G15+'RallyGully I Sector 83 Gurgaon'!G15+'RallyGully I East of Kailash'!G15+'RallyGully I Sector 19 Dwarka'!G15+'RallyGully | LCR Pune'!G15+'RallyGully | DPSG'!G15+'RallyGully | Gandipath'!G15+'RallyGully | Panchsheel'!G15) -> 8500 | H31: =SUM('RallyGully I Sector 10 Dwarka'!H15+'RallyGully I Sector 83 Gurgaon'!H15+'RallyGully I East of Kailash'!H15+'RallyGully I Sector 19 Dwarka'!H15+'RallyGully | LCR Pune'!H15+'RallyGully | DPSG'!H15+'RallyGully | Gandipath'!H15+'RallyGully | Panchsheel'!H15) -> 0 | I31: =SUM('RallyGully I Sector 10 Dwarka'!I15+'RallyGully I Sector 83 Gurgaon'!I15+'RallyGully I East of Kailash'!I15+'RallyGully I Sector 19 Dwarka'!I15+'RallyGully | LCR Pune'!I15+'RallyGully | DPSG'!I15+'RallyGully | Gandipath'!I15+'RallyGully | Panchsheel'!I15) -> 38300 | J31: =SUM('RallyGully I Sector 10 Dwarka'!J15+'RallyGully I Sector 83 Gurgaon'!J15+'RallyGully I East of Kailash'!J15+'RallyGully I Sector 19 Dwarka'!J15+'RallyGully | LCR Pune'!J15+'RallyGully | DPSG'!J15+'RallyGully | Gandipath'!J15+'RallyGully | Panchsheel'!J15) -> 55200 | K31: =SUM('RallyGully I Sector 10 Dwarka'!K15+'RallyGully I Sector 83 Gurgaon'!K15+'RallyGully I East of Kailash'!K15+'RallyGully I Sector 19 Dwarka'!K15+'RallyGully | LCR Pune'!K15+'RallyGully | DPSG'!K15+'RallyGully | Gandipath'!K15+'RallyGully | Panchsheel'!K15+'Powerplay Park, Pune'!K15+'Commons, Noida'!K15) -> 93300
A32: 3.2 | B32: Sportomic (Organized by RallyGully) | C32: =SUM('RallyGully I Sector 10 Dwarka'!C16+'RallyGully I Sector 83 Gurgaon'!C16+'RallyGully I East of Kailash'!C16+'RallyGully I Sector 19 Dwarka'!C16+'RallyGully | LCR Pune'!C16+'RallyGully | DPSG'!C16+'RallyGully | Gandipath'!C16+'RallyGully | Panchsheel'!C16) -> 0 | D32: =SUM('RallyGully I Sector 10 Dwarka'!D16+'RallyGully I Sector 83 Gurgaon'!D16+'RallyGully I East of Kailash'!D16+'RallyGully I Sector 19 Dwarka'!D16+'RallyGully | LCR Pune'!D16+'RallyGully | DPSG'!D16+'RallyGully | Gandipath'!D16+'RallyGully | Panchsheel'!D16) -> 0 | E32: =SUM('RallyGully I Sector 10 Dwarka'!E16+'RallyGully I Sector 83 Gurgaon'!E16+'RallyGully I East of Kailash'!E16+'RallyGully I Sector 19 Dwarka'!E16+'RallyGully | LCR Pune'!E16+'RallyGully | DPSG'!E16+'RallyGully | Gandipath'!E16+'RallyGully | Panchsheel'!E16) -> 0 | F32: =SUM('RallyGully I Sector 10 Dwarka'!F16+'RallyGully I Sector 83 Gurgaon'!F16+'RallyGully I East of Kailash'!F16+'RallyGully I Sector 19 Dwarka'!F16+'RallyGully | LCR Pune'!F16+'RallyGully | DPSG'!F16+'RallyGully | Gandipath'!F16+'RallyGully | Panchsheel'!F16) -> 0 | G32: =SUM('RallyGully I Sector 10 Dwarka'!G16+'RallyGully I Sector 83 Gurgaon'!G16+'RallyGully I East of Kailash'!G16+'RallyGully I Sector 19 Dwarka'!G16+'RallyGully | LCR Pune'!G16+'RallyGully | DPSG'!G16+'RallyGully | Gandipath'!G16+'RallyGully | Panchsheel'!G16) -> 0 | H32: =SUM('RallyGully I Sector 10 Dwarka'!H16+'RallyGully I Sector 83 Gurgaon'!H16+'RallyGully I East of Kailash'!H16+'RallyGully I Sector 19 Dwarka'!H16+'RallyGully | LCR Pune'!H16+'RallyGully | DPSG'!H16+'RallyGully | Gandipath'!H16+'RallyGully | Panchsheel'!H16) -> 23290 | I32: =SUM('RallyGully I Sector 10 Dwarka'!I16+'RallyGully I Sector 83 Gurgaon'!I16+'RallyGully I East of Kailash'!I16+'RallyGully I Sector 19 Dwarka'!I16+'RallyGully | LCR Pune'!I16+'RallyGully | DPSG'!I16+'RallyGully | Gandipath'!I16+'RallyGully | Panchsheel'!I16) -> 13650 | J32: =SUM('RallyGully I Sector 10 Dwarka'!J16+'RallyGully I Sector 83 Gurgaon'!J16+'RallyGully I East of Kailash'!J16+'RallyGully I Sector 19 Dwarka'!J16+'RallyGully | LCR Pune'!J16+'RallyGully | DPSG'!J16+'RallyGully | Gandipath'!J16+'RallyGully | Panchsheel'!J16) -> 42360 | K32: =SUM('RallyGully I Sector 10 Dwarka'!K16+'RallyGully I Sector 83 Gurgaon'!K16+'RallyGully I East of Kailash'!K16+'RallyGully I Sector 19 Dwarka'!K16+'RallyGully | LCR Pune'!K16+'RallyGully | DPSG'!K16+'RallyGully | Gandipath'!K16+'RallyGully | Panchsheel'!K16+'Powerplay Park, Pune'!K16+'Commons, Noida'!K16) -> 29390
A33: 3.3 | B33: Rallygully Community games | C33: =SUM('RallyGully I Sector 10 Dwarka'!C17+'RallyGully I Sector 83 Gurgaon'!C17+'RallyGully I East of Kailash'!C17+'RallyGully I Sector 19 Dwarka'!C17+'RallyGully | LCR Pune'!C17+'RallyGully | DPSG'!C17+'RallyGully | Gandipath'!C17+'RallyGully | Panchsheel'!C17) -> 10500 | D33: =SUM('RallyGully I Sector 10 Dwarka'!D17+'RallyGully I Sector 83 Gurgaon'!D17+'RallyGully I East of Kailash'!D17+'RallyGully I Sector 19 Dwarka'!D17+'RallyGully | LCR Pune'!D17+'RallyGully | DPSG'!D17+'RallyGully | Gandipath'!D17+'RallyGully | Panchsheel'!D17) -> 15087 | E33: =SUM('RallyGully I Sector 10 Dwarka'!E17+'RallyGully I Sector 83 Gurgaon'!E17+'RallyGully I East of Kailash'!E17+'RallyGully I Sector 19 Dwarka'!E17+'RallyGully | LCR Pune'!E17+'RallyGully | DPSG'!E17+'RallyGully | Gandipath'!E17+'RallyGully | Panchsheel'!E17) -> 19900 | F33: =SUM('RallyGully I Sector 10 Dwarka'!F17+'RallyGully I Sector 83 Gurgaon'!F17+'RallyGully I East of Kailash'!F17+'RallyGully I Sector 19 Dwarka'!F17+'RallyGully | LCR Pune'!F17+'RallyGully | DPSG'!F17+'RallyGully | Gandipath'!F17+'RallyGully | Panchsheel'!F17) -> 28350 | G33: =SUM('RallyGully I Sector 10 Dwarka'!G17+'RallyGully I Sector 83 Gurgaon'!G17+'RallyGully I East of Kailash'!G17+'RallyGully I Sector 19 Dwarka'!G17+'RallyGully | LCR Pune'!G17+'RallyGully | DPSG'!G17+'RallyGully | Gandipath'!G17+'RallyGully | Panchsheel'!G17) -> 20780 | H33: =SUM('RallyGully I Sector 10 Dwarka'!H17+'RallyGully I Sector 83 Gurgaon'!H17+'RallyGully I East of Kailash'!H17+'RallyGully I Sector 19 Dwarka'!H17+'RallyGully | LCR Pune'!H17+'RallyGully | DPSG'!H17+'RallyGully | Gandipath'!H17+'RallyGully | Panchsheel'!H17) -> 2510 | I33: =SUM('RallyGully I Sector 10 Dwarka'!I17+'RallyGully I Sector 83 Gurgaon'!I17+'RallyGully I East of Kailash'!I17+'RallyGully I Sector 19 Dwarka'!I17+'RallyGully | LCR Pune'!I17+'RallyGully | DPSG'!I17+'RallyGully | Gandipath'!I17+'RallyGully | Panchsheel'!I17) -> 79489 | J33: =SUM('RallyGully I Sector 10 Dwarka'!J17+'RallyGully I Sector 83 Gurgaon'!J17+'RallyGully I East of Kailash'!J17+'RallyGully I Sector 19 Dwarka'!J17+'RallyGully | LCR Pune'!J17+'RallyGully | DPSG'!J17+'RallyGully | Gandipath'!J17+'RallyGully | Panchsheel'!J17) -> 63275 | K33: =SUM('RallyGully I Sector 10 Dwarka'!K17+'RallyGully I Sector 83 Gurgaon'!K17+'RallyGully I East of Kailash'!K17+'RallyGully I Sector 19 Dwarka'!K17+'RallyGully | LCR Pune'!K17+'RallyGully | DPSG'!K17+'RallyGully | Gandipath'!K17+'RallyGully | Panchsheel'!K17+'Powerplay Park, Pune'!K17+'Commons, Noida'!K17) -> 125670
A34: 3.4 | B34: Misfits Community | C34: =SUM('RallyGully I Sector 10 Dwarka'!C18+'RallyGully I Sector 83 Gurgaon'!C18+'RallyGully I East of Kailash'!C18+'RallyGully I Sector 19 Dwarka'!C18+'RallyGully | LCR Pune'!C18+'RallyGully | DPSG'!C18+'RallyGully | Gandipath'!C18+'RallyGully | Panchsheel'!C18) -> 0 | D34: =SUM('RallyGully I Sector 10 Dwarka'!D18+'RallyGully I Sector 83 Gurgaon'!D18+'RallyGully I East of Kailash'!D18+'RallyGully I Sector 19 Dwarka'!D18+'RallyGully | LCR Pune'!D18+'RallyGully | DPSG'!D18+'RallyGully | Gandipath'!D18+'RallyGully | Panchsheel'!D18) -> 0 | E34: =SUM('RallyGully I Sector 10 Dwarka'!E18+'RallyGully I Sector 83 Gurgaon'!E18+'RallyGully I East of Kailash'!E18+'RallyGully I Sector 19 Dwarka'!E18+'RallyGully | LCR Pune'!E18+'RallyGully | DPSG'!E18+'RallyGully | Gandipath'!E18+'RallyGully | Panchsheel'!E18) -> 9590 | F34: =SUM('RallyGully I Sector 10 Dwarka'!F18+'RallyGully I Sector 83 Gurgaon'!F18+'RallyGully I East of Kailash'!F18+'RallyGully I Sector 19 Dwarka'!F18+'RallyGully | LCR Pune'!F18+'RallyGully | DPSG'!F18+'RallyGully | Gandipath'!F18+'RallyGully | Panchsheel'!F18) -> 11990 | G34: =SUM('RallyGully I Sector 10 Dwarka'!G18+'RallyGully I Sector 83 Gurgaon'!G18+'RallyGully I East of Kailash'!G18+'RallyGully I Sector 19 Dwarka'!G18+'RallyGully | LCR Pune'!G18+'RallyGully | DPSG'!G18+'RallyGully | Gandipath'!G18+'RallyGully | Panchsheel'!G18) -> 10980 | H34: =SUM('RallyGully I Sector 10 Dwarka'!H18+'RallyGully I Sector 83 Gurgaon'!H18+'RallyGully I East of Kailash'!H18+'RallyGully I Sector 19 Dwarka'!H18+'RallyGully | LCR Pune'!H18+'RallyGully | DPSG'!H18+'RallyGully | Gandipath'!H18+'RallyGully | Panchsheel'!H18) -> 5309 | I34: =SUM('RallyGully I Sector 10 Dwarka'!I18+'RallyGully I Sector 83 Gurgaon'!I18+'RallyGully I East of Kailash'!I18+'RallyGully I Sector 19 Dwarka'!I18+'RallyGully | LCR Pune'!I18+'RallyGully | DPSG'!I18+'RallyGully | Gandipath'!I18+'RallyGully | Panchsheel'!I18) -> 0 | J34: =SUM('RallyGully I Sector 10 Dwarka'!J18+'RallyGully I Sector 83 Gurgaon'!J18+'RallyGully I East of Kailash'!J18+'RallyGully I Sector 19 Dwarka'!J18+'RallyGully | LCR Pune'!J18+'RallyGully | DPSG'!J18+'RallyGully | Gandipath'!J18+'RallyGully | Panchsheel'!J18) -> 15679 | K34: =SUM('RallyGully I Sector 10 Dwarka'!K18+'RallyGully I Sector 83 Gurgaon'!K18+'RallyGully I East of Kailash'!K18+'RallyGully I Sector 19 Dwarka'!K18+'RallyGully | LCR Pune'!K18+'RallyGully | DPSG'!K18+'RallyGully | Gandipath'!K18+'RallyGully | Panchsheel'!K18+'Powerplay Park, Pune'!K18+'Commons, Noida'!K18) -> 7944
A35: 4 | B35: Memberships | C35: =SUM('RallyGully I Sector 10 Dwarka'!C19+'RallyGully I Sector 83 Gurgaon'!C19+'RallyGully I East of Kailash'!C19+'RallyGully I Sector 19 Dwarka'!C19+'RallyGully | LCR Pune'!C19+'RallyGully | DPSG'!C19+'RallyGully | Gandipath'!C19+'RallyGully | Panchsheel'!C19) -> 0 | D35: =SUM('RallyGully I Sector 10 Dwarka'!D19+'RallyGully I Sector 83 Gurgaon'!D19+'RallyGully I East of Kailash'!D19+'RallyGully I Sector 19 Dwarka'!D19+'RallyGully | LCR Pune'!D19+'RallyGully | DPSG'!D19+'RallyGully | Gandipath'!D19+'RallyGully | Panchsheel'!D19) -> 50000 | E35: =SUM('RallyGully I Sector 10 Dwarka'!E19+'RallyGully I Sector 83 Gurgaon'!E19+'RallyGully I East of Kailash'!E19+'RallyGully I Sector 19 Dwarka'!E19+'RallyGully | LCR Pune'!E19+'RallyGully | DPSG'!E19+'RallyGully | Gandipath'!E19+'RallyGully | Panchsheel'!E19) -> 27000 | F35: =SUM('RallyGully I Sector 10 Dwarka'!F19+'RallyGully I Sector 83 Gurgaon'!F19+'RallyGully I East of Kailash'!F19+'RallyGully I Sector 19 Dwarka'!F19+'RallyGully | LCR Pune'!F19+'RallyGully | DPSG'!F19+'RallyGully | Gandipath'!F19+'RallyGully | Panchsheel'!F19) -> 91300 | G35: =SUM('RallyGully I Sector 10 Dwarka'!G19+'RallyGully I Sector 83 Gurgaon'!G19+'RallyGully I East of Kailash'!G19+'RallyGully I Sector 19 Dwarka'!G19+'RallyGully | LCR Pune'!G19+'RallyGully | DPSG'!G19+'RallyGully | Gandipath'!G19+'RallyGully | Panchsheel'!G19) -> 74380 | H35: =SUM('RallyGully I Sector 10 Dwarka'!H19+'RallyGully I Sector 83 Gurgaon'!H19+'RallyGully I East of Kailash'!H19+'RallyGully I Sector 19 Dwarka'!H19+'RallyGully | LCR Pune'!H19+'RallyGully | DPSG'!H19+'RallyGully | Gandipath'!H19+'RallyGully | Panchsheel'!H19) -> 99380 | I35: =SUM('RallyGully I Sector 10 Dwarka'!I19+'RallyGully I Sector 83 Gurgaon'!I19+'RallyGully I East of Kailash'!I19+'RallyGully I Sector 19 Dwarka'!I19+'RallyGully | LCR Pune'!I19+'RallyGully | DPSG'!I19+'RallyGully | Gandipath'!I19+'RallyGully | Panchsheel'!I19) -> 79480 | J35: =SUM('RallyGully I Sector 10 Dwarka'!J19+'RallyGully I Sector 83 Gurgaon'!J19+'RallyGully I East of Kailash'!J19+'RallyGully I Sector 19 Dwarka'!J19+'RallyGully | LCR Pune'!J19+'RallyGully | DPSG'!J19+'RallyGully | Gandipath'!J19+'RallyGully | Panchsheel'!J19+'Powerplay Park, Pune'!J19+'Commons, Noida'!J19) -> 141880 | K35: =SUM('RallyGully I Sector 10 Dwarka'!K19+'RallyGully I Sector 83 Gurgaon'!K19+'RallyGully I East of Kailash'!K19+'RallyGully I Sector 19 Dwarka'!K19+'RallyGully | LCR Pune'!K19+'RallyGully | DPSG'!K19+'RallyGully | Gandipath'!K19+'RallyGully | Panchsheel'!K19+'Powerplay Park, Pune'!K19+'Commons, Noida'!K19) -> 109180
A36: 5 | B36: Coaching | C36: =SUM('RallyGully I Sector 10 Dwarka'!C20+'RallyGully I Sector 83 Gurgaon'!C20+'RallyGully I East of Kailash'!C20+'RallyGully I Sector 19 Dwarka'!C20+'RallyGully | LCR Pune'!C20+'RallyGully | DPSG'!C20+'RallyGully | Gandipath'!C20+'RallyGully | Panchsheel'!C20) -> 0 | D36: =SUM('RallyGully I Sector 10 Dwarka'!D20+'RallyGully I Sector 83 Gurgaon'!D20+'RallyGully I East of Kailash'!D20+'RallyGully I Sector 19 Dwarka'!D20+'RallyGully | LCR Pune'!D20+'RallyGully | DPSG'!D20+'RallyGully | Gandipath'!D20+'RallyGully | Panchsheel'!D20) -> 0 | E36: =SUM('RallyGully I Sector 10 Dwarka'!E20+'RallyGully I Sector 83 Gurgaon'!E20+'RallyGully I East of Kailash'!E20+'RallyGully I Sector 19 Dwarka'!E20+'RallyGully | LCR Pune'!E20+'RallyGully | DPSG'!E20+'RallyGully | Gandipath'!E20+'RallyGully | Panchsheel'!E20) -> 0 | F36: =SUM('RallyGully I Sector 10 Dwarka'!F20+'RallyGully I Sector 83 Gurgaon'!F20+'RallyGully I East of Kailash'!F20+'RallyGully I Sector 19 Dwarka'!F20+'RallyGully | LCR Pune'!F20+'RallyGully | DPSG'!F20+'RallyGully | Gandipath'!F20+'RallyGully | Panchsheel'!F20) -> 0 | G36: =SUM('RallyGully I Sector 10 Dwarka'!G20+'RallyGully I Sector 83 Gurgaon'!G20+'RallyGully I East of Kailash'!G20+'RallyGully I Sector 19 Dwarka'!G20+'RallyGully | LCR Pune'!G20+'RallyGully | DPSG'!G20+'RallyGully | Gandipath'!G20+'RallyGully | Panchsheel'!G20) -> 0 | H36: =SUM('RallyGully I Sector 10 Dwarka'!H20+'RallyGully I Sector 83 Gurgaon'!H20+'RallyGully I East of Kailash'!H20+'RallyGully I Sector 19 Dwarka'!H20+'RallyGully | LCR Pune'!H20+'RallyGully | DPSG'!H20+'RallyGully | Gandipath'!H20+'RallyGully | Panchsheel'!H20) -> 0 | I36: =SUM('RallyGully I Sector 10 Dwarka'!I20+'RallyGully I Sector 83 Gurgaon'!I20+'RallyGully I East of Kailash'!I20+'RallyGully I Sector 19 Dwarka'!I20+'RallyGully | LCR Pune'!I20+'RallyGully | DPSG'!I20+'RallyGully | Gandipath'!I20+'RallyGully | Panchsheel'!I20) -> 98000 | J36: =SUM('RallyGully I Sector 10 Dwarka'!J20+'RallyGully I Sector 83 Gurgaon'!J20+'RallyGully I East of Kailash'!J20+'RallyGully I Sector 19 Dwarka'!J20+'RallyGully | LCR Pune'!J20+'RallyGully | DPSG'!J20+'RallyGully | Gandipath'!J20+'RallyGully | Panchsheel'!J20+'Powerplay Park, Pune'!J20+'Commons, Noida'!J20) -> 37500 | K36: =SUM('RallyGully I Sector 10 Dwarka'!K20+'RallyGully I Sector 83 Gurgaon'!K20+'RallyGully I East of Kailash'!K20+'RallyGully I Sector 19 Dwarka'!K20+'RallyGully | LCR Pune'!K20+'RallyGully | DPSG'!K20+'RallyGully | Gandipath'!K20+'RallyGully | Panchsheel'!K20+'Powerplay Park, Pune'!K20+'Commons, Noida'!K20) -> 11500
A37: 6 | B37: Corporate Events | C37: =SUM('RallyGully I Sector 10 Dwarka'!C21+'RallyGully I Sector 83 Gurgaon'!C21+'RallyGully I East of Kailash'!C21+'RallyGully I Sector 19 Dwarka'!C21+'RallyGully | LCR Pune'!C21+'RallyGully | DPSG'!C21+'RallyGully | Gandipath'!C21+'RallyGully | Panchsheel'!C21) -> 0 | D37: =SUM('RallyGully I Sector 10 Dwarka'!D21+'RallyGully I Sector 83 Gurgaon'!D21+'RallyGully I East of Kailash'!D21+'RallyGully I Sector 19 Dwarka'!D21+'RallyGully | LCR Pune'!D21+'RallyGully | DPSG'!D21+'RallyGully | Gandipath'!D21+'RallyGully | Panchsheel'!D21) -> 0 | E37: =SUM('RallyGully I Sector 10 Dwarka'!E21+'RallyGully I Sector 83 Gurgaon'!E21+'RallyGully I East of Kailash'!E21+'RallyGully I Sector 19 Dwarka'!E21+'RallyGully | LCR Pune'!E21+'RallyGully | DPSG'!E21+'RallyGully | Gandipath'!E21+'RallyGully | Panchsheel'!E21) -> 0 | F37: =SUM('RallyGully I Sector 10 Dwarka'!F21+'RallyGully I Sector 83 Gurgaon'!F21+'RallyGully I East of Kailash'!F21+'RallyGully I Sector 19 Dwarka'!F21+'RallyGully | LCR Pune'!F21+'RallyGully | DPSG'!F21+'RallyGully | Gandipath'!F21+'RallyGully | Panchsheel'!F21) -> 5400 | G37: =SUM('RallyGully I Sector 10 Dwarka'!G21+'RallyGully I Sector 83 Gurgaon'!G21+'RallyGully I East of Kailash'!G21+'RallyGully I Sector 19 Dwarka'!G21+'RallyGully | LCR Pune'!G21+'RallyGully | DPSG'!G21+'RallyGully | Gandipath'!G21+'RallyGully | Panchsheel'!G21) -> 0 | H37: =SUM('RallyGully I Sector 10 Dwarka'!H21+'RallyGully I Sector 83 Gurgaon'!H21+'RallyGully I East of Kailash'!H21+'RallyGully I Sector 19 Dwarka'!H21+'RallyGully | LCR Pune'!H21+'RallyGully | DPSG'!H21+'RallyGully | Gandipath'!H21+'RallyGully | Panchsheel'!H21) -> 20680 | I37: =SUM('RallyGully I Sector 10 Dwarka'!I21+'RallyGully I Sector 83 Gurgaon'!I21+'RallyGully I East of Kailash'!I21+'RallyGully I Sector 19 Dwarka'!I21+'RallyGully | LCR Pune'!I21+'RallyGully | DPSG'!I21+'RallyGully | Gandipath'!I21+'RallyGully | Panchsheel'!I21) -> 28730 | J37: =SUM('RallyGully I Sector 10 Dwarka'!J21+'RallyGully I Sector 83 Gurgaon'!J21+'RallyGully I East of Kailash'!J21+'RallyGully I Sector 19 Dwarka'!J21+'RallyGully | LCR Pune'!J21+'RallyGully | DPSG'!J21+'RallyGully | Gandipath'!J21+'RallyGully | Panchsheel'!J21+'Powerplay Park, Pune'!J21+'Commons, Noida'!J21) -> 11880 | K37: =SUM('RallyGully I Sector 10 Dwarka'!K21+'RallyGully I Sector 83 Gurgaon'!K21+'RallyGully I East of Kailash'!K21+'RallyGully I Sector 19 Dwarka'!K21+'RallyGully | LCR Pune'!K21+'RallyGully | DPSG'!K21+'RallyGully | Gandipath'!K21+'RallyGully | Panchsheel'!K21+'Powerplay Park, Pune'!K21+'Commons, Noida'!K21) -> 10520
A38: 7 | B38: Brand Activation | C38: =SUM('RallyGully I Sector 10 Dwarka'!C22+'RallyGully I Sector 83 Gurgaon'!C22+'RallyGully I East of Kailash'!C22+'RallyGully I Sector 19 Dwarka'!C22+'RallyGully | LCR Pune'!C22+'RallyGully | DPSG'!C22+'RallyGully | Gandipath'!C22+'RallyGully | Panchsheel'!C22) -> 0 | D38: =SUM('RallyGully I Sector 10 Dwarka'!D22+'RallyGully I Sector 83 Gurgaon'!D22+'RallyGully I East of Kailash'!D22+'RallyGully I Sector 19 Dwarka'!D22+'RallyGully | LCR Pune'!D22+'RallyGully | DPSG'!D22+'RallyGully | Gandipath'!D22+'RallyGully | Panchsheel'!D22) -> 0 | E38: =SUM('RallyGully I Sector 10 Dwarka'!E22+'RallyGully I Sector 83 Gurgaon'!E22+'RallyGully I East of Kailash'!E22+'RallyGully I Sector 19 Dwarka'!E22+'RallyGully | LCR Pune'!E22+'RallyGully | DPSG'!E22+'RallyGully | Gandipath'!E22+'RallyGully | Panchsheel'!E22) -> 0 | F38: =SUM('RallyGully I Sector 10 Dwarka'!F22+'RallyGully I Sector 83 Gurgaon'!F22+'RallyGully I East of Kailash'!F22+'RallyGully I Sector 19 Dwarka'!F22+'RallyGully | LCR Pune'!F22+'RallyGully | DPSG'!F22+'RallyGully | Gandipath'!F22+'RallyGully | Panchsheel'!F22) -> 15000 | G38: =SUM('RallyGully I Sector 10 Dwarka'!G22+'RallyGully I Sector 83 Gurgaon'!G22+'RallyGully I East of Kailash'!G22+'RallyGully I Sector 19 Dwarka'!G22+'RallyGully | LCR Pune'!G22+'RallyGully | DPSG'!G22+'RallyGully | Gandipath'!G22+'RallyGully | Panchsheel'!G22) -> 4480 | H38: =SUM('RallyGully I Sector 10 Dwarka'!H22+'RallyGully I Sector 83 Gurgaon'!H22+'RallyGully I East of Kailash'!H22+'RallyGully I Sector 19 Dwarka'!H22+'RallyGully | LCR Pune'!H22+'RallyGully | DPSG'!H22+'RallyGully | Gandipath'!H22+'RallyGully | Panchsheel'!H22) -> 23313 | I38: =SUM('RallyGully I Sector 10 Dwarka'!I22+'RallyGully I Sector 83 Gurgaon'!I22+'RallyGully I East of Kailash'!I22+'RallyGully I Sector 19 Dwarka'!I22+'RallyGully | LCR Pune'!I22+'RallyGully | DPSG'!I22+'RallyGully | Gandipath'!I22+'RallyGully | Panchsheel'!I22) -> 24100 | J38: =SUM('RallyGully I Sector 10 Dwarka'!J22+'RallyGully I Sector 83 Gurgaon'!J22+'RallyGully I East of Kailash'!J22+'RallyGully I Sector 19 Dwarka'!J22+'RallyGully | LCR Pune'!J22+'RallyGully | DPSG'!J22+'RallyGully | Gandipath'!J22+'RallyGully | Panchsheel'!J22+'Powerplay Park, Pune'!J22+'Commons, Noida'!J22) -> 30000 | K38: =SUM('RallyGully I Sector 10 Dwarka'!K22+'RallyGully I Sector 83 Gurgaon'!K22+'RallyGully I East of Kailash'!K22+'RallyGully I Sector 19 Dwarka'!K22+'RallyGully | LCR Pune'!K22+'RallyGully | DPSG'!K22+'RallyGully | Gandipath'!K22+'RallyGully | Panchsheel'!K22+'Powerplay Park, Pune'!K22+'Commons, Noida'!K22) -> 28000
