Workbook

Sheet Summary
B2: 1 - 30 Sept
C3: Amount
B4: Particulars | C4: Total | D4: Pickleball | E4: Turf | F4: Padel | H4: Payment Mode | I4: Amount | J4: Notes
B5: Pay & Play | C5: =sum(C7,C13) -> 336888 | D5: =sum(D7,D13) -> 71777 | E5: =sum(E7,E13) -> 168979 | F5: =sum(F7,F13) -> 96132 | H5: Razorpay (after deduction) | I5: 240769 | J5: All the Razorpay payment post deductions
H6: Cash Collection | I6: =I7-I5 -> 242026 | J6: Amount received from cash in hand, Neft and other payment methods
B7: Online | C7: =sum(C8:C12) -> 152594 | D7: =sum(D8:D12) -> 40494 | E7: =sum(E8:E12) -> 81023 | F7: =sum(F8:F12) -> 31077 | H7: Total Offline Collection | I7: =C13+C16+C20+C21+C24 -> 482795 | J7: Payments from offline bookings, Community, events, Memberships, Academy and Corporate events
B8: District | C8: =District!C2 -> 152594 | D8: =District!B5 -> 40494 | E8: =District!B6 -> 81023 | F8: =District!B7 -> 31077 | H8: Total District Collection | I8: =C8 -> 152594
B9: Hudle | C9: 0 | D9: 0 | E9: 0 | F9: 0 | H9: Grand Total | I9: =I8+I7 -> 635389
B10: Playo | C10: 0 | D10: 0 | E10: 0 | F10: 0
B11: Khelomore | C11: 0 | D11: 0 | E11: 0 | F11: 0
B12: Zplys | C12: 0 | D12: 0 | E12: 0 | F12: 0
B13: Offline | C13: =sum(C14:C15) -> 184294 | D13: =sum(D14:D15) -> 31283 | E13: =sum(E14:E15) -> 87956 | F13: =sum(F14:F15) -> 65055
B14: Bookings | C14: ='Offline Bookings'!D32+'Offline Bookings'!E32+'Offline Bookings'!F32 -> 109494 | D14: ='Offline Bookings'!D32 -> 31283 | E14: ='Offline Bookings'!F32 -> 13156 | F14: ='Offline Bookings'!E32 -> 65055
B15: Memberships | C15: =Memberships!E4 -> 74800 | D15: 0 | E15: =Memberships!E4 -> 74800 | F15: 0
B16: Community | C16: =sum(C17:C19) -> 40133 | D16: =sum(D17:D19) -> 11922 | E16: =sum(E17:E19) -> 28211 | F16: =sum(F17:F19) -> 0
B17: Pickup games | C17: ='Offline Bookings'!J32 -> 2700 | D17: ='Offline Bookings'!J32 -> 2700 | E17: 0 | F17: 0
B18: Social Events/Tournaments | C18: ='Social EventsTournament'!E4 -> 9222 | D18: ='Social EventsTournament'!E4 -> 9222 | E18: 0 | F18: 0
B19: Community Partnerships | C19: ='Offline Bookings'!I32 -> 28211 | D19: 0 | E19: ='Offline Bookings'!I32 -> 28211 | F19: 0
B20: Academy | C20: =Academy!F4 -> 87320 | D20: 0 | E20: =Academy!F2+Academy!F3 -> 87320 | F20: 0
B21: B2B | C21: =sum(C22,C23) -> 142005 | D21: =sum(D22,D23) -> 0 | E21: =sum(E22,E23) -> 142005 | F21: =sum(F22) -> 0
B22: Corporate events | C22: =B2B!G2+B2B!G3+B2B!G4+B2B!G5+B2B!G6+B2B!G7+B2B!G8+B2B!G9 -> 125890 | D22: 0 | E22: =C22 -> 125890 | F22: 0
B23: All B2B partnerships | C23: =B2B!G11+B2B!G10 -> 16115 | D23: 0 | E23: =C23 -> 16115 | F23: 0
B24: Commerce | C24: =sum(C25:C27) -> 29043 | D24: =sum(D25:D27) -> 10200 | E24: =sum(E25:E27) -> 0 | F24: =sum(F25:F27) -> 3350
B25: Product rental | C25: ='Offline Bookings'!G32+'Offline Bookings'!H32 -> 13550 | D25: ='Offline Bookings'!G32 -> 10200 | E25: 0 | F25: ='Offline Bookings'!H32 -> 3350
B26: Product sales | C26: 0 | D26: 0 | E26: 0 | F26: 0
B27: F&B | C27: ='F&B'!B32 -> 15493 | D27: 0 | E27: 0 | F27: 0
B28: Other Income | C28: 0 | D28: 0 | E28: 0 | F28: 0
B29: Total Gross Revenue | C29: =C5+C16+C20+C21+C24+C28 -> 635389 | D29: =D5+D16+D24+D20+D21+D28 -> 93899 | E29: =E5+E16+E24+E20+E21+E28 -> 426515 | F29: =F5+F16+F24+F20+F21+F28 -> 99482
B30: GST | C30: =C29-(C29/1.18) -> 96923.746
B31: Net Revenue Post GST | C31: =C29-C30 -> 538465.25
B32: Commissions, Payment gateway & Event Expense | C32: =District!D2+District!E2+'Offline Bookings'!L32+Memberships!F4+'Social EventsTournament'!F4+'Social EventsTournament'!H4+Academy!G4+B2B!H12+B2B!I12+'F&B'!C32+'F&B'!E32 -> 57511.69
B33: Net Revenue | C33: =C29-C30-C32 -> 480953.56
B34: SD Vidya School's Share (60%) | C34: =C33*60% -> 288572.14
B35: RG & DPC's Share (40%) | C35: =C33*40% -> 192381.43
B36: Expenses
B37: Venue Manager + Housekeeping + Coach Salary
B38: VM Travel conveyance
B39: Diesel consumption charges | C39: 0
B40: Ops Managers Reimbursements
B41: Marketing Expense
...

Sheet District
A1: Link | B1: Date | C1: Paid to District | D1: Commissions (₹) | E1: GST on Commission | F1: Net Revenue | G1: TCS | H1: TDS | I1: Final Amount (₹)
B2: 1 - 30 Sept | C2: 152594 | D2: 9185 | E2: 1653 | F2: =C2-D2-E2 -> 141756 | G2: 763 | H2: 152 | I2: =F2-G2-H2 -> 140841
A3: Total | C3: =SUM(C2) -> 152594 | F3: =SUM(F2) -> 141756 | I3: =SUM(I2) -> 140841
A5: Pickleball | B5: =C3-B6-B7 -> 40494
A6: Turf | B6: 81023
A7: Padel | B7: 31077

Sheet Offline Bookings
A1: Date | B1: Day | C1: Offline booking hours | D1: Pickleball | E1: Padel | F1: Turf | G1: Pickleball Rental | H1: Padel Rental | I1: Community Partnership (Turf) | J1: Community (Pickleball) | K1: Total Revenue | L1: Payment Gateway | M1: Net Revenue
A2: 46266 | B2: Tuesday | C2: 6 | D2: 2476 | E2: 2640 | F2: 0 | G2: 150 | H2: 350 | I2: 0 | J2: 0 | K2: =sum(C2:J2) -> 5622 | L2: =K2*1.75% -> 98.385 | M2: =K2-L2 -> 5523.615
A3: 46267 | B3: Wednesday | C3: 2 | D3: 0 | E3: 1600 | F3: 3200 | G3: 0 | H3: 400 | I3: 0 | J3: 0 | K3: =sum(C3:J3) -> 5202 | L3: =K3*1.75% -> 91.035 | M3: =K3-L3 -> 5110.965
A4: 46268 | B4: Thursday | C4: 2 | D4: 0 | E4: 2400 | F4: 0 | G4: 0 | H4: 0 | I4: 0 | J4: 0 | K4: =sum(C4:J4) -> 2402 | L4: =K4*1.75% -> 42.035 | M4: =K4-L4 -> 2359.965
A5: 46269 | B5: Friday | C5: 1 | D5: 630 | E5: 0 | F5: 0 | G5: 200 | H5: 0 | I5: 0 | J5: 0 | K5: =sum(C5:J5) -> 831 | L5: =K5*1.75% -> 14.5425 | M5: =K5-L5 -> 816.4575
A6: 46270 | B6: Saturday | C6: 5.5 | D6: 0 | E6: 0 | F6: 0 | G6: 0 | H6: 0 | I6: 10836 | J6: 0 | K6: =sum(C6:J6) -> 10841.5 | L6: =K6*1.75% -> 189.72625 | M6: =K6-L6 -> 10651.774
A7: 46271 | B7: Sunday | C7: 2 | D7: 0 | E7: 2400 | F7: 0 | G7: 0 | H7: 0 | I7: 0 | J7: 0 | K7: =sum(C7:J7) -> 2402 | L7: =K7*1.75% -> 42.035 | M7: =K7-L7 -> 2359.965
A8: 46272 | B8: Monday | C8: 4 | D8: 1276 | E8: 2640 | F8: 0 | G8: 500 | H8: 200 | I8: 0 | J8: 0 | K8: =sum(C8:J8) -> 4620 | L8: =K8*1.75% -> 80.85 | M8: =K8-L8 -> 4539.15
A9: 46273 | B9: Tuesday | C9: 3.5 | D9: 1276 | E9: 4125 | F9: 0 | G9: 650 | H9: 0 | I9: 0 | J9: 0 | K9: =sum(C9:J9) -> 6054.5 | L9: =K9*1.75% -> 105.95375 | M9: =K9-L9 -> 5948.5463
A10: 46274 | B10: Wednesday | C10: 3 | D10: 638 | E10: 1600 | F10: 0 | G10: 250 | H10: 300 | I10: 0 | J10: 0 | K10: =sum(C10:J10) -> 2791 | L10: =K10*1.75% -> 48.8425 | M10: =K10-L10 -> 2742.1575
A11: 46275 | B11: Thursday | C11: 3 | D11: 638 | E11: 3200 | F11: 0 | G11: 300 | H11: 200 | I11: 0 | J11: 0 | K11: =sum(C11:J11) -> 4341 | L11: =K11*1.75% -> 75.9675 | M11: =K11-L11 -> 4265.0325
A12: 46276 | B12: Friday | C12: 2.5 | D12: 638 | E12: 2175 | F12: 0 | G12: 300 | H12: 200 | I12: 0 | J12: 0 | K12: =sum(C12:J12) -> 3315.5 | L12: =K12*1.75% -> 58.02125 | M12: =K12-L12 -> 3257.4788
A13: 46277 | B13: Saturday | C13: 6 | D13: 638 | E13: 0 | F13: 3996 | G13: 450 | H13: 0 | I13: 4275 | J13: 0 | K13: =sum(C13:J13) -> 9365 | L13: =K13*1.75% -> 163.8875 | M13: =K13-L13 -> 9201.1125
... A28: 46292 | B28: Sunday | C28: 4.5 | D28: 1778 | E28: 1800 | F28: 0 | G28: 450 | H28: 0 | I28: 0 | J28: 375 | K28: =sum(C28:J28) -> 4407.5 | L28: =K28*1.75% -> 77.13125 | M28: =K28-L28 -> 4330.3687
A29: 46293 | B29: Monday | C29: 5.5 | D29: 1276 | E29: 3700 | G29: 350 | H29: 400 | I29: 0 | J29: 0 | K29: =sum(C29:J29) -> 5731.5 | L29: =K29*1.75% -> 100.30125 | M29: =K29-L29 -> 5631.1987
A30: 46294 | B30: Tuesday | C30: 5 | D30: 957 | E30: 3200 | F30: 0 | G30: 450 | H30: 0 | I30: 0 | J30: 0 | K30: =sum(C30:J30) -> 4612 | L30: =K30*1.75% -> 80.71 | M30: =K30-L30 -> 4531.29
A31: 46295 | B31: Wednesday | C31: 2 | D31: 0 | E31: 1600 | F31: 0 | G31: 0 | H31: 0 | I31: 6260 | J31: 0 | K31: =sum(C31:J31) -> 7862 | L31: =K31*1.75% -> 137.585 | M31: =K31-L31 -> 7724.415
A32: Total | D32: =SUM(D2:D31) -> 31283 | E32: =SUM(E2:E31) -> 65055 | F32: =SUM(F2:F31) -> 13156 | G32: =SUM(G2:G31) -> 10200 | H32: =SUM(H2:H31) -> 3350 | I32: =SUM(I2:I31) -> 28211 | J32: =SUM(J2:J31) -> 2700 | K32: =SUM(K2:K31) -> 154073 | ... M32: =SUM(M2:M31) -> 151376.72

Sheet Memberships
A1: S.NO. | B1: Member Name | C1: Sports Type | D1: Membership Type | E1: Amount Collected | F1: Payment Gateway | G1: Net Revenue
A2: 1 | B2: Nikhil | C2: Football | D2: Monthly | E2: 50000 | F2: =E2*1.75% -> 875 | G2: =E2-F2 -> 49125
A3: 2 | B3: Punit | C3: Football | D3: Monthly | E3: 24800 | F3: =E3*1.75% -> 434 | G3: =E3-F3 -> 24366
A4: Total | E4: =SUM(E3,E2) -> 74800 | F4: =SUM(F3,F2) -> 1309 | G4: =SUM(G3,G2) -> 73491

Sheet Social EventsTournament
A1: S.NO. | B1: Date | C1: Sport | D1: Type | E1: Amt | F1: Commissions | G1: Event Expenses | H1: Payment Gateway | I1: Net Revenue | J1: TDS | K1: Final Amt | L1: Notes
A2: 1 | B2: 19 Sept | C2: Pickleball | D2: Mixer | E2: 3980 | F2: 0 | G2: 0 | H2: =E2*1.75% -> 69.65 | I2: =E2-H2 -> 3910.35 | J2: 0 | K2: =I2 -> 3910.35
A3: 2 | B3: 26 Sept | C3: Pickleball | D3: Mixer | E3: 5242 | F3: =E3*50% -> 2621 | G3: 0 | H3: =E3*1.75% -> 91.735 | I3: =E3-F3 -> 2621 | J3: 0 | K3: =I3 -> 2621
A4: Total | E4: =SUM(E2:E3) -> 9222 | F4: =SUM(F2:F3) -> 2621 | G4: =SUM(G2:G3) -> 0 | H4: =SUM(H2:H3) -> 161.385 | I4: =SUM(I2:I3) -> 6531.35 | J4: =SUM(J2:J3) -> 0 | K4: =SUM(K2:K3) -> 6531.35

Sheet Academy
A1: Sno. | B1: Date | C1: Organisation | D1: Sport | E1: Type | F1: Amt | G1: Payment Gateway | H1: Net Revenue
A2: 1 | B2: Sept | C2: BFFS | D2: Football | E2: Academy | F2: 40120 | G2: 0 | H2: =F2-G2 -> 40120
A3: 2 | B3: Sept | C3: TFS | D3: Football | E3: Academy | F3: 47200 | G3: 0 | H3: =F3-G3 -> 47200
A4: Total | F4: =SUM(F2:F3) -> 87320 | G4: =SUM(G2:G3) -> 0 | H4: =SUM(H2:H3) -> 87320

Sheet B2B
A1: S.NO. | B1: Date | C1: Name | D1: Type | E1: Sports Type | F1: Deliverables | G1: Amount Collected | H1: Event Cost | I1: Payment Gateway | J1: Net Revenue
A2: 1 | B2: 4 and 13 Sept | C2: Barclays | D2: Team Event | E2: Football | F2: 4 Hours of turf | G2: 20500 | H2: 8000 | I2: =G2*1.75% -> 358.75 | J2: =G2-I2-H2 -> 12141.25
A3: 2 | B3: 6 Sept | C3: Dron Football tournament | D3: Tournament | E3: Football | F3: 2 Hours of turf | G3: 3600 | H3: 0 | I3: =G3*1.75% -> 63 | J3: =G3-I3-H3 -> 3537
A4: 3 | B4: Many Dates | C4: Mediatek | D4: Corporate Tournament | E4: Football | F4: 4.5 Hours of turf | G4: 9750 | H4: 0 | I4: =G4*1.75% -> 170.625 | J4: =G4-I4-H4 -> 9579.375
A5: 4 | B5: Thu and Sundays | C5: Kick with Diva | D5: Weekly Sessions | E5: Football | F5: 12 Hours of Turf | G5: 19200 | H5: 0 | I5: =G5*1.75% -> 336 | J5: =G5-I5-H5 -> 18864
A6: 5 | B6: 26 Sept | C6: Shadow FC | D6: Tournament | E6: Football | F6: 3 Hours of turf | G6: 8640 | H6: 0 | I6: =G6*1.75% -> 151.2 | J6: =G6-I6-H6 -> 8488.8
A7: 6 | B7: 26 Sept | C7: PW | D7: Corporate Tournament | E7: Football | F7: 6 Hours of turf and add ons (Ref, Coolers, Table and chairs) | G7: 37800 | H7: 18200 | I7: 0 | J7: =G7-I7-H7 -> 19600
A8: 7 | B8: 26 Sept | C8: Sept Rising | D8: Charity Event | E8: - | F8: Open ground | G8: 12000 | H8: 0 | I8: =G8*1.75% -> 210 | J8: =G8-I8-H8 -> 11790
A9: 8 | B9: 12,20,27 Sept | C9: Goal Club | D9: Weekly Sessions | E9: Football | F9: 1.5 Hours turf each day | G9: 14400 | H9: 0 | I9: =G9*1.75% -> 252 | J9: =G9-I9-H9 -> 14148
A10: 9 | B10: 30 Sept | C10: Wasco | D10: Product Shoot | E10: Pickleball | F10: 4 Hours of court | G10: 1625 | H10: 0 | I10: 0 | J10: =G10-I10-H10 -> 1625
A11: 10 | B11: 30 Sept | C11: Skergo | D11: Product Shoot | E11: Whole Venue | F11: Whole Venue | G11: 14490 | H11: 0 | I11: =G11*1.75% -> 253.575 | J11: =G11-I11-H11 -> 14236.425
A12: Total | G12: =SUM(G2:G11) -> 142005 | H12: =SUM(H2:H11) -> 26200 | I12: =SUM(I2:I11) -> 1795.15 | J12: =SUM(J2:J11) -> 114009.85

Sheet F&B
A1: Date | B1: F&B | C1: Paid to brand (75%) | D1: Our Margin (25%) | E1: Payment Gateway | F1: Net Revenue
A2: 46266 | B2: 445 | C2: =B2*75% -> 333.75 | D2: =B2*25% -> 111.25 | E2: =B2*1.75% -> 7.7875 | F2: =D2-E2 -> 103.4625
A3: 46267 | B3: 125 | C3: =B3*75% -> 93.75 | D3: =B3*25% -> 31.25 | E3: =B3*1.75% -> 2.1875 | F3: =D3-E3 -> 29.0625
A4: 46268 | B4: 450 | C4: =B4*75% -> 337.5 | D4: =B4*25% -> 112.5 | E4: =B4*1.75% -> 7.875 | F4: =D4-E4 -> 104.625
A5: 46269 | B5: 0 | C5: =B5*75% -> 0 | D5: =B5*25% -> 0 | E5: =B5*1.75% -> 0 | F5: =D5-E5 -> 0
A6: 46270 | B6: 0 | C6: =B6*75% -> 0 | D6: =B6*25% -> 0 | E6: =B6*1.75% -> 0 | F6: =D6-E6 -> 0
A7: 46271 | B7: 0 | C7: =B7*75% -> 0 | D7: =B7*25% -> 0 | E7: =B7*1.75% -> 0 | F7: =D7-E7 -> 0
A8: 46272 | B8: 0 | C8: =B8*75% -> 0 | D8: =B8*25% -> 0 | E8: =B8*1.75% -> 0 | F8: =D8-E8 -> 0
A9: 46273 | B9: 0 | C9: =B9*75% -> 0 | D9: =B9*25% -> 0 | E9: =B9*1.75% -> 0 | F9: =D9-E9 -> 0
A10: 46274 | B10: 655 | C10: =B10*75% -> 491.25 | D10: =B10*25% -> 163.75 | E10: =B10*1.75% -> 11.4625 | F10: =D10-E10 -> 152.2875
A11: 46275 | B11: 1465 | C11: =B11*75% -> 1098.75 | D11: =B11*25% -> 366.25 | E11: =B11*1.75% -> 25.6375 | F11: =D11-E11 -> 340.6125
A12: 46276 | B12: 175 | C12: =B12*75% -> 131.25 | D12: =B12*25% -> 43.75 | E12: =B12*1.75% -> 3.0625 | F12: =D12-E12 -> 40.6875
A13: 46277 | B13: 550 | C13: =B13*75% -> 412.5 | D13: =B13*25% -> 137.5 | E13: =B13*1.75% -> 9.625 | F13: =D13-E13 -> 127.875
... A31: 46295 | B31: 230 | C31: =B31*75% -> 172.5 | D31: =B31*25% -> 57.5 | E31: =B31*1.75% -> 4.025 | F31: =D31-E31 -> 53.475
A32: Total | B32: =SUM(B2:B31) -> 15493 | C32: =SUM(C2:C31) -> 11619.75 | D32: =SUM(D2:D31) -> 3873.25 | E32: =SUM(E2:E31) -> 271.1275 | F32: =SUM(F2:F31) -> 3602.1225
