Workbook

Sheet Summary
B2: 1 - 30 June
C3: Amount
B4: Particulars | C4: Total | D4: Pickleball | E4: Padel | F4: Turf
B5: Pay & Play | C5: =sum(C6,C12) -> 440490 | D5: =sum(D6,D12) -> 92185 | E5: =sum(E6,E12) -> 56951 | F5: =sum(F6,F12) -> 291354
B6: Online | C6: =sum(C7:C11) -> 211794 | D6: =sum(D7:D11) -> 62484 | E6: =sum(E7:E11) -> 29243 | F6: =sum(F7:F11) -> 120067
B7: District | C7: =District!C3 -> 211794 | D7: =District!B5 -> 62484 | E7: =District!B7 -> 29243 | F7: =District!B6 -> 120067
B8: Hudle | C8: 0 | D8: 0 | E8: 0 | F8: 0
B9: Playo | C9: 0 | D9: 0 | E9: 0 | F9: 0
B10: Khelomore | C10: 0 | D10: 0 | E10: 0 | F10: 0
B11: Zplys | C11: 0 | D11: 0 | E11: 0 | F11: 0
B12: Offline | C12: =sum(C13:C14) -> 228696 | D12: =sum(D13:D14) -> 29701 | E12: =sum(E13:E14) -> 27708 | F12: =sum(F13:F14) -> 171287
B13: Bookings | C13: ='Offline & RG Community'!E33+'Offline & RG Community'!F33+'Offline & RG Community'!G33 -> 184716 | D13: ='Offline & RG Community'!E33 -> 29701 | E13: ='Offline & RG Community'!F33 -> 27708 | F13: ='Offline & RG Community'!G33 -> 127307
B14: Memberships | C14: =Memberships!E4 -> 43980 | D14: 0 | E14: 0 | F14: =Memberships!E4 -> 43980
B15: Community | C15: =sum(C16:C17) -> 12426 | D15: =sum(D16:D17) -> 0 | E15: =sum(E16:E17) -> 0 | F15: =sum(F16:F17) -> 12426
B16: Pickup games | C16: 0 | D16: 0 | E16: 0 | F16: 0
B17: Social Events/Tournaments | C17: ='Social EventsTournament'!D4 -> 12426 | D17: 0 | E17: 0 | F17: ='Social EventsTournament'!D4 -> 12426
B18: Academy | C18: =Academy!D4 -> 50200 | D18: =Academy!D3 -> 3000 | E18: 0 | F18: =Academy!D2 -> 47200
B19: Events & Partnership | C19: =sum(C20,C21) -> 182766 | D19: =sum(D20,D21) -> 59340 | E19: =sum(E20) -> 0 | F19: =sum(F20,F21) -> 123426
B20: Corporate events | C20: ='Corporate Events'!F5 -> 105880 | D20: ='Corporate Events'!F4+'Corporate Events'!F3/2 -> 59340 | E20: 0 | F20: ='Corporate Events'!F2+'Corporate Events'!F3/2 -> 46540
B21: All B2B partnerships | C21: =B2B!D5 -> 76886 | D21: 0 | E21: 0 | F21: =B2B!D5 -> 76886
B22: Commerce | C22: =sum(C23:C25) -> 25190 | D22: =sum(D23:D25) -> 13950 | E22: =sum(E23:E25) -> 6550 | F22: =sum(F23:F25) -> 0
B23: Product rental | C23: ='Offline & RG Community'!H33+'Offline & RG Community'!I33 -> 20500 | D23: ='Offline & RG Community'!H33 -> 13950 | E23: ='Offline & RG Community'!I33 -> 6550 | F23: 0
B24: Product sales | C24: 0 | D24: 0 | E24: 0 | F24: 0
B25: F&B | C25: ='Offline & RG Community'!J33 -> 4690 | D25: 0 | E25: 0 | F25: 0
B26: Other Income | C26: 0 | D26: 0 | E26: 0 | F26: 0
B27: Total Gross Revenue | C27: =sum(C5,C15,C18,C19,C22) -> 711072 | D27: =D5+D15+D22+D18+D19+D26 -> 168475 | E27: =E5+E15+E22+E18+E19+E26 -> 63501 | F27: =F5+F15+F22+F18+F19+F26 -> 474406
B28: Total Net Revenue (Post Commissions) | C28: ='Offline & RG Community'!M33+District!F3+Memberships!E4+'Social EventsTournament'!G4+Academy!D4+B2B!F5+'Corporate Events'!H5 -> 676464.2 | H28: =C27-C28 -> 34607.795
B29: Total Revenue post GST | C29: =C28/1.18 -> 573274.75
B30: SD Vidya School's Share (60%) | C30: =C29*60% -> 343964.85
B31: RG & DPC's Share (40%) | C31: =C29*40% -> 229309.9
B32: Expenses
B33: Venue Manager Salary (Shubham -25k base) | C33: =25000+10833+2500 -> 38333 | D33: Includes overtime/leave not taken for 11 days in July and 2500rs from last month we missed adding
B34: FnF Housekeeping (Arun) | C34: 4000
B35: Housekeeping Salary (Shiva) | C35: 9500 | D35: Includes 1500 for paid leaves not taken
B36: Additional Manager/Coach Salary (Govind - 25k base) | C36: =16/30*25000 -> 13333.333
B37: VM Conveyance Reimbursement | C37: 3640
B38: Geenerator for Event | C38: 3844
B39: Ops Managers Reimbursements | C39: =5970+225 -> 6195 | D39: This is for expenses incurred by ops manager for the noida venue operations
B40: Inventory (fastnup) | C40: 3629
B41: Event Expenses | C41: =5000+320 -> 5320 | D41: medals and prize money
...

Sheet Offline & RG Community
A1: Date | B1: Day | C1: Offline booking hours | D1: Discount Given | H1: Pickleball Rental | I1: Padel Rental | J1: F&B | K1: Total Revenue | L1: Payment Gateway | M1: Net Revenue
E2: Pickleball | F2: Padel | G2: Turf
A3: 46174 | B3: Monday | C3: 0 | D3: 15 and 20% | E3: 0 | F3: 0 | G3: 0 | H3: 0 | I3: 875 | J3: 0 | K3: =sum(E3:J3) -> 875 | L3: =K3*1.75% -> 15.3125 | M3: =K3-L3 -> 859.6875
A4: 46175 | B4: Tuesday | C4: 0 | D4: 15 and 20% | E4: 0 | F4: 0 | G4: 0 | H4: 200 | I4: 0 | J4: 0 | K4: =sum(E4:J4) -> 200 | L4: =K4*1.75% -> 3.5 | M4: =K4-L4 -> 196.5
A5: 46176 | B5: Wednesday | C5: 0 | D5: 15 and 20% | E5: 0 | F5: 0 | G5: 0 | H5: 350 | I5: 425 | J5: 0 | K5: =sum(E5:J5) -> 775 | L5: =K5*1.75% -> 13.5625 | M5: =K5-L5 -> 761.4375
A6: 46177 | B6: Thursday | C6: 3.5 | D6: 15 and 20% | E6: 2430 | F6: 0 | G6: 0 | H6: 800 | I6: 75 | J6: 0 | K6: =sum(E6:J6) -> 3305 | L6: =K6*1.75% -> 57.8375 | M6: =K6-L6 -> 3247.1625
A7: 46178 | B7: Friday | C7: 3.5 | D7: 15 and 20% | E7: 1000 | F7: 0 | G7: 3000 | H7: 400 | I7: 150 | J7: 0 | K7: =sum(E7:J7) -> 4550 | L7: =K7*1.75% -> 79.625 | M7: =K7-L7 -> 4470.375
A8: 46179 | B8: Saturday | C8: 9.5 | D8: 15 and 20% | E8: 1635 | F8: 2175 | G8: 7995 | H8: 1350 | I8: 525 | J8: 0 | K8: =sum(E8:J8) -> 13680 | L8: =K8*1.75% -> 239.4 | M8: =K8-L8 -> 13440.6
A9: 46180 | B9: Sunday | C9: 2.5 | D9: 15 and 20% | E9: 400 | F9: 0 | G9: 6460 | H9: 700 | I9: 300 | J9: 0 | K9: =sum(E9:J9) -> 7860 | L9: =K9*1.75% -> 137.55 | M9: =K9-L9 -> 7722.45
A10: 46181 | B10: Monday | C10: 1 | D10: 15 and 20% | E10: 0 | F10: 0 | G10: 3420 | H10: 50 | I10: 0 | J10: 0 | K10: =sum(E10:J10) -> 3470 | L10: =K10*1.75% -> 60.725 | M10: =K10-L10 -> 3409.275
A11: 46182 | B11: Tuesday | C11: 4 | D11: 15 and 20% | E11: 1635 | F11: 700 | G11: 3228 | H11: 1000 | I11: 300 | J11: 0 | K11: =sum(E11:J11) -> 6863 | L11: =K11*1.75% -> 120.1025 | M11: =K11-L11 -> 6742.8975
A12: 46183 | B12: Wednesday | C12: 3.5 | D12: 15 and 20% | E12: 545 | F12: 0 | G12: 3998 | H12: 600 | I12: 0 | J12: 0 | K12: =sum(E12:J12) -> 5143 | L12: =K12*1.75% -> 90.0025 | M12: =K12-L12 -> 5052.9975
A13: 46184 | B13: Thursday | C13: 2.5 | D13: 15 and 20% | E13: 0 | F13: 3500 | G13: 0 | H13: 400 | I13: 450 | J13: 0 | K13: =sum(E13:J13) -> 4350 | L13: =K13*1.75% -> 76.125 | M13: =K13-L13 -> 4273.875
A14: 46185 | B14: Friday | C14: 9 | D14: 15 and 20% | E14: 1345 | F14: 2800 | G14: 7996 | H14: 650 | I14: 675 | J14: 0 | K14: =sum(E14:J14) -> 13466 | L14: =K14*1.75% -> 235.655 | M14: =K14-L14 -> 13230.345
... A16: 46187 | B16: Sunday | C16: 7.5 | D16: 15 and 20% | E16: 400 | F16: 3200 | G16: 9856 | H16: 500 | I16: 150 | J16: 0 | K16: =sum(E16:J16) -> 14106 | L16: =K16*1.75% -> 246.855 | M16: =K16-L16 -> 13859.145
A17: 46188 | B17: Monday | C17: 6 | D17: 15 and 20% | E17: =1810+800 -> 2610 | F17: 3200 | G17: 0 | H17: 550 | I17: 0 | J17: 0 | K17: =sum(E17:J17) -> 6360 | L17: =K17*1.75% -> 111.3 | M17: =K17-L17 -> 6248.7
A18: 46189 | B18: Tuesday | C18: 7 | D18: 15 and 20% | E18: 2035 | F18: 533 | G18: 5718 | H18: 600 | I18: 0 | J18: 0 | K18: =sum(E18:J18) -> 8886 | L18: =K18*1.75% -> 155.505 | M18: =K18-L18 -> 8730.495
A19: 46190 | B19: Wednesday | C19: 4 | D19: 15 and 20% | E19: 720 | F19: 0 | G19: 7427 | H19: 400 | I19: 0 | J19: 0 | K19: =sum(E19:J19) -> 8547 | L19: =K19*1.75% -> 149.5725 | M19: =K19-L19 -> 8397.4275
A20: 46191 | B20: Thursday | C20: 3 | D20: 15 and 20% | E20: 1635 | F20: 0 | G20: 0 | H20: 250 | I20: 0 | J20: 0 | K20: =sum(E20:J20) -> 1885 | L20: =K20*1.75% -> 32.9875 | M20: =K20-L20 -> 1852.0125
A21: 46192 | B21: Friday | C21: 3.5 | D21: 15 and 20% | E21: 0 | F21: 2400 | G21: 3200 | H21: 500 | I21: 0 | J21: 0 | K21: =sum(E21:J21) -> 6100 | L21: =K21*1.75% -> 106.75 | M21: =K21-L21 -> 5993.25
A22: 46193 | B22: Saturday | C22: 7 | D22: 15 and 20% | E22: 350 | F22: 0 | G22: 10296 | H22: 600 | I22: 300 | J22: 0 | K22: =sum(E22:J22) -> 11546 | L22: =K22*1.75% -> 202.055 | M22: =K22-L22 -> 11343.945
A23: 46194 | B23: Sunday | C23: 6 | D23: 15 and 20% | E23: 1450 | F23: 0 | G23: 6276 | H23: 1300 | I23: 300 | J23: 1015 | K23: =sum(E23:J23) -> 10341 | L23: =K23*1.75% -> 180.9675 | M23: =K23-L23 -> 10160.032
A24: 46195 | B24: Monday | C24: 6 | D24: 15 and 20% | E24: 2188 | F24: 2400 | G24: 3228 | H24: 150 | I24: 0 | J24: 140 | K24: =sum(E24:J24) -> 8106 | L24: =K24*1.75% -> 141.855 | M24: =K24-L24 -> 7964.145
A25: 46196 | B25: Tuesday | C25: 4 | D25: 15 and 20% | E25: 1728 | F25: 1600 | G25: 0 | H25: 350 | I25: 500 | J25: 140 | K25: =sum(E25:J25) -> 4318 | L25: =K25*1.75% -> 75.565 | M25: =K25-L25 -> 4242.435
A26: 46197 | B26: Wednesday | C26: 7 | D26: 15 and 20% | E26: 1040 | F26: 1600 | G26: 5500 | H26: 350 | I26: 600 | J26: 245 | K26: =sum(E26:J26) -> 9335 | L26: =K26*1.75% -> 163.3625 | M26: =K26-L26 -> 9171.6375
A27: 46198 | B27: Thursday | C27: 5.5 | D27: 15 and 20% | E27: 2790 | F27: 0 | G27: 3400 | H27: 550 | I27: 0 | J27: 315 | K27: =sum(E27:J27) -> 7055 | L27: =K27*1.75% -> 123.4625 | M27: =K27-L27 -> 6931.5375
A28: 46199 | B28: Friday | C28: 5 | D28: 15 and 20% | E28: 1040 | F28: 0 | G28: 7228 | H28: 200 | I28: 450 | J28: 525 | K28: =sum(E28:J28) -> 9443 | L28: =K28*1.75% -> 165.2525 | M28: =K28-L28 -> 9277.7475
A29: 46200 | B29: Saturday | C29: 5.5 | D29: 15 and 20% | E29: 0 | F29: 0 | G29: 9693 | H29: 300 | I29: 300 | J29: 560 | K29: =sum(E29:J29) -> 10853 | L29: =K29*1.75% -> 189.9275 | M29: =K29-L29 -> 10663.073
... A32: 46203 | B32: Tuesday | C32: 3.5 | D32: 15 and 20% | E32: 1090 | F32: 3000 | G32: 0 | H32: 250 | I32: 100 | J32: 455 | K32: =sum(E32:J32) -> 4895 | L32: =K32*1.75% -> 85.6625 | M32: =K32-L32 -> 4809.3375
A33: Total | C33: =SUM(C2:C32) -> 132 | E33: =SUM(E2:E32) -> 29701 | F33: =SUM(F2:F32) -> 27708 | G33: =SUM(G2:G32) -> 127307 | H33: =SUM(H2:H32) -> 13950 | I33: =SUM(I2:I32) -> 6550 | J33: =SUM(J2:J32) -> 4690 | K33: =SUM(K2:K32) -> 209906 | L33: =SUM(L2:L32) -> 3673.355 | M33: =SUM(M2:M32) -> 206232.64

Sheet District
A1: Link | B1: Date | C1: Paid to District | D1: Commissions (₹) | E1: GST on Commission | F1: Net Revenue | G1: TCS | H1: TDS | I1: Final Amount (₹)
B2: 1 - 30 June | C2: 211794 | D2: 13501 | E2: 2430 | F2: =C2-D2-E2 -> 195863 | G2: 1059 | H2: 212 | I2: =F2-G2-H2 -> 194592
B3: Total | C3: =SUM(C2) -> 211794 | F3: =SUM(F2) -> 195863 | I3: =SUM(I2) -> 194592
A5: Pickleball | B5: =C3-B6-B7 -> 62484
A6: Turf | B6: 120067
A7: Padel | B7: 29243

Sheet Memberships
A1: Member Name | B1: Sports Type | C1: Membership Type | D1: Start Date | E1: Amount Collected | F1: Payment Gateway | G1: Net Revenue
A2: Punit | B2: Football | C2: 8 Slots | D2: June | E2: 24800 | F2: =E2*1.75% -> 434 | G2: =E2-F2 -> 24366
A3: Divanshu | B3: Football | C3: 12 Slots | D3: June | E3: 19180 | F3: =E3*1.75% -> 335.65 | G3: =E3-F3 -> 18844.35
A4: Total | E4: =SUM(E2:E3) -> 43980 | G4: =SUM(G2:G3) -> 43210.35

Sheet Social EventsTournament
A1: Date | B1: Sport | C1: Type | D1: Amt | E1: Courtly Comission | F1: Payment Gateway | G1: Net Revenue
A2: 46194 | B2: Pickleball | C2: DUPR | D2: 9018 | E2: =D2*5% -> 450.9 | F2: 0 | G2: =D2-E2-F2 -> 8567.1
A3: 46194 | B3: Pickleball | C3: DUPR | D3: 3408 | E3: 0 | F3: =D3*1.75% -> 59.64 | G3: =D3-E3-F3 -> 3348.36
A4: Total | D4: =SUM(D2:D3) -> 12426 | E4: =SUM(E2:E3) -> 450.9 | F4: =SUM(F2:F3) -> 59.64 | G4: =SUM(G2:G3) -> 11915.46

Sheet Academy
A1: Date | B1: Sport | C1: Type | D1: Amt
A2: June | B2: Football | C2: Academy | D2: 47200
A3: June | B3: Pickleball | C3: Academy | D3: 3000
A4: Total | D4: =SUM(D2:D3) -> 50200

Sheet B2B
A1: Date | B1: Brand | C1: Type | D1: Amt | E1: Commission | F1: Net
A2: 46180 | B2: Nivia | C2: Activation | D2: 23600 | E2: =D2*40% -> 9440 | F2: =D2-E2 -> 14160
A3: 46191 | B3: Nivia | C3: Brand Shoot | D3: 42286 | E3: 0 | F3: =D3-E3 -> 42286
A4: 46194 | B4: Bubble Ball Arena | C4: Slip & Slide | D4: =8000+3000 -> 11000 | E4: =8000*40% -> 3200 | F4: =D4-E4 -> 7800
A5: Total | D5: =SUM(D2:D4) -> 76886 | E5: =SUM(E2:E4) -> 12640 | F5: =SUM(F2:F4) -> 64246

Sheet Corporate Events
A1: Date | B1: Name | C1: Type | D1: Sports Type | E1: Deliverables | F1: Amount Collected | G1: Payment Gateway | H1: Net Revenue
A2: 18-19 June | B2: Kitab Cup | C2: Corporate Event | D2: Football | E2: Turf and open ground | F2: 43000 | G2: =F2*1.75% -> 752.5 | H2: =F2-G2 -> 42247.5
A3: 46201 | B3: Basil | C3: Corporate Event | D3: Cricket Turf | E3: Turf & Pickleball | F3: 7080 | G3: =F3*1.75% -> 123.9 | H3: =F3-G3 -> 6956.1
A4: 46203 | B4: Maulik | C4: Corporate Event | D4: Football | E4: Turf | F4: 55800 | G4: =F4*1.75% -> 976.5 | H4: =F4-G4 -> 54823.5
A5: Total | F5: =SUM(F2:F4) -> 105880 | G5: =SUM(G2:G4) -> 1852.9 | H5: =SUM(H2:H4) -> 104027.1
