Workbook

Sheet Summary
V1: Helping Table
B2: Date: 20th - 30th Nov | V2: Particulars | W2: Amount
B3: Particulars | C3: Amount | V3: =B4 -> Offline | W3: =C4 -> 24225
B4: Offline | C4: =SUM(C5,C6,C7,C18, C8) -> 24225 | V4: =B9 -> Online: Third Party Platform | W4: =C9 -> 15900
B5: Rentals | C5: ='Offline & RG Community'!G13 -> 6225 | V5: =#REF! -> #REF! | W5: =#REF! -> #REF!
B6: F&B | C6: 0 | V6: =B19 -> Memberships | W6: =C19 -> 0
B7: Product Sales | C7: 0 | V7: =B20 -> Corporate Events | W7: =C20 -> 0
B8: Bookings | C8: ='Offline & RG Community'!E13 -> 18000 | V8: =B21 -> Brand Activation | W8: =C21 -> 0
B9: Online: Third Party Platform | C9: =sum(C10:C17) -> 15900 | V9: =B22 -> Other Income | W9: =C22 -> 0
B10: Hudle | C10: =Hudle!C8 -> 0
B11: Playo | C11: =Playo!C5 -> 8025
B12: District | C12: 0
B13: Khelomore | C13: =Khelomore!C3 -> 7875
B14: Community | C14: =sum(C15:C18) -> 0
B15: Courtly | C15: 0
B16: Sportomic | C16: 0
B17: Misfits Community | C17: 0
B18: Rallygully Community games | C18: ='Offline & RG Community'!F13 -> 0
B19: Memberships | C19: 0
B20: Corporate Events | C20: 0
B21: Brand Activation | C21: 0
B22: Other Income | C22: 0
B23: Total Gross Revenue | C23: =sum(C4,C9,C19,C20,,C22) -> 40125
B24: Total Net Revenue (Post Commissions) | C24: ='Offline & RG Community'!H13 + Playo!F5 + Khelomore!E3 -> 38878.12
B25: Total Revenue post GST | C25: =C24/1.18 -> 32947.559
I999: Offline | J999: =SUM(J1000,J1001,J1002,J1003) -> 0 | K999: =SUM(K1000,K1001,K1002,K1003) -> 0 | L999: =SUM(L1000,L1001,L1002,L1003) -> 0 | M999: =SUM(M1000,M1001,M1002,M1003) -> 8715
I1000: Rentals | M1000: 5535
I1001: F&B | M1001: 0
I1002: Product Sales | J1002: 0 | K1002: 0 | M1002: 0
I1003: Bookings | J1003: 0 | M1003: 3180
I1004: Online: Third Party Platform | J1004: =sum(J1005:J1008) -> 0 | K1004: =sum(K1005:K1008) -> 0 | L1004: =sum(L1005:L1008) -> 0 | M1004: =sum(M1005:M1008) -> 31660
I1005: Hudle | M1005: 29780
I1006: Playo | M1006: 1280
I1007: District | J1007: 0 | K1007: 0 | L1007: 0 | M1007: 0
I1008: Khelomore | J1008: 0 | M1008: 600
I1009: Community | J1009: =SUM(J1010,J1011) -> 0 | K1009: =SUM(K1010,K1011) -> 0 | L1009: =SUM(L1010,L1011) -> 0 | M1009: =SUM(M1010,M1011) -> 11360
I1010: Rallygully | M1010: 8070
I1011: Misfits | J1011: 0 | K1011: 0 | M1011: 3290
I1012: Memberships | J1012: 0 | L1012: 0 | M1012: 0
I1013: Corporate Events | J1013: 0 | K1013: 0 | L1013: 0 | M1013: 0
...

Sheet Offline & RG Community
A1: Date | B1: Day | C1: Offline booking hours | D1: Discount Given | E1: Booking Revenue | F1: Community Revenue | G1: Paddle Rental | H1: Total Revenue
A2: 45981 | B2: Thursday | C2: 2 | D2: 0.2 | E2: 1000 | F2: 0 | G2: 0 | H2: =SUM(E2:G2) -> 1000
A3: 45982 | B3: Friday | C3: 1 | D3: 0.2 | E3: 500 | F3: 0 | G3: 0 | H3: =SUM(E3:G3) -> 500
A4: 45983 | B4: Saturday | C4: 4 | D4: 0.2 | E4: 3000 | F4: 0 | G4: 600 | H4: =SUM(E4:G4) -> 3600
A5: 45984 | B5: Sunday | C5: 0 | D5: 0.2 | E5: 0 | F5: 0 | G5: 625 | H5: =SUM(E5:G5) -> 625
A6: 45985 | B6: Monday | C6: 2 | D6: 0.2 | E6: 2100 | F6: 0 | G6: 350 | H6: =SUM(E6:G6) -> 2450
A7: 45986 | B7: Tuesday | C7: 1 | D7: 0.2 | E7: 600 | F7: 0 | G7: 150 | H7: =SUM(E7:G7) -> 750
A8: 45987 | B8: Wednesday | C8: 5 | D8: 0.2 | E8: 2900 | F8: 0 | G8: 1350 | H8: =SUM(E8:G8) -> 4250
A9: 45988 | B9: Thursday | C9: 3 | D9: 0.2 | E9: 2300 | F9: 0 | G9: 550 | H9: =SUM(E9:G9) -> 2850
A10: 45989 | B10: Friday | C10: 0 | D10: 0.2 | E10: 0 | F10: 0 | G10: 0 | H10: =SUM(E10:G10) -> 0
A11: 45990 | B11: Saturday | C11: 5.5 | D11: 0.2 | E11: 3100 | F11: 0 | G11: 1750 | H11: =SUM(E11:G11) -> 4850
A12: 45991 | B12: Sunday | C12: 4.5 | D12: 0.2 | E12: 2500 | F12: 0 | G12: 850 | H12: =SUM(E12:G12) -> 3350
A13: Total | C13: =SUM(C1:C12) -> 28 | E13: =SUM(E1:E12) -> 18000 | F13: =SUM(F1:F12) -> 0 | G13: =SUM(G1:G12) -> 6225 | H13: =SUM(E13:G13) -> 24225

Sheet Hudle
A1: Link | B1: Date | C1: Paid to Hudle | D1: Commisions (Including GST) | E1: Net Revenue | F1: TDS | G1: TCS | H1: Net Cash Received
B2: 1 - 30 Nov | C2: 0
C8: =SUM(C2:C7) -> 0 | E8: =SUM(E2:E7) -> 0 | H8: =SUM(H2:H7) -> 0

Sheet Playo
A1: Link | B1: Date | C1: Paid to Playo (₹) | D1: Commissions (₹) | E1: GST (₹) | F1: Net Revenue | G1: TDS (₹) | H1: TCS (₹) | I1: Net Cash Received
B2: 20 - 30 Nov | C2: 8025 | D2: 468.75 | E2: 84.38 | F2: =C2-D2-E2 -> 7471.87 | G2: 8.03 | H2: 0 | I2: 7463.84
C5: =SUM(C2:C3) -> 8025 | F5: =SUM(F2:F4) -> 7471.87 | I5: =SUM(I2:I3) -> 7463.84

Sheet Khelomore
A1: Link | B1: Date | C1: Paid to Khelomore (₹) | D1: Commissions (₹) | E1: Final Amount (₹)
B2: 20 - 30 Nov | C2: 7875 | D2: 393.75 | E2: 7181.25
C3: =SUM(C2) -> 7875 | E3: =SUM(E2) -> 7181.25
